Workbook

Sheet LEEME
A1: Base de conocimiento — Empleo y desempleo (España y Comunidad de Madrid)
A3: Descripción
A4: Datos públicos y gratuitos de empleo, actividad y desempleo, con series largas por año/trimestre, sexo, edad, comunidad autónoma y sector. El eje principal es la Encuesta de Población Activa (EPA, INE); se complementa con paro registrado y afiliación (SEPE / Seguridad Social) y con la EU-LFS regional (Eurostat, NUTS2).
A5: Fecha de consulta: 2026-10-21. Todas las cifras están transcritas de las API oficiales; los cálculos (medias anuales, tasas recalculadas, ratios) son fórmulas visibles en el libro.
A7: Índice de hojas
A8: Hoja | B8: Contenido | C8: Cobertura
A9: Resumen_Empleo | B9: Indicadores clave comparando España y Madrid, con enlaces a las hojas de detalle. | C9: Último dato
A10: EPA_Tasas_Trim | B10: Tasas de paro, empleo y actividad trimestrales (ambos sexos) por tramos de edad: total, <25, 25 y más, 16–19, 20–24. | C10: 2002T1–2026T2, España y Madrid
A11: EPA_Tasas_Anual_Calc | B11: Media anual de las tasas trimestrales (fórmula; solo si hay 4 trimestres). | C11: 2002–2025
A12: EPA_Paro_Anual_SexoEdad | B12: Tasa de paro, media anual publicada por el INE, por sexo y 6 tramos de edad. | C12: 2006–2025, España y Madrid
A13: EPA_Paro_Brecha_MAD_ESP | B13: Diferencia Madrid − España en puntos porcentuales (fórmulas). | C13: 2006–2025
A14: EPA_Paro_CCAA_2025 | B14: Tasa de paro media 2025 por comunidad autónoma y tramos de edad, con ranking. | C14: 2025, 17 CCAA + Ceuta y Melilla
A15: EPA_Absolutos_2026T2 | B15: Ocupados, parados y población por CCAA (miles) y tasa de paro recalculada. | C15: 2026T2
A16: EPA_Ocupados_4T | B16: Ocupados en los últimos 4 trimestres, España y Madrid. | C16: 2025T3–2026T2
A17: EPA_Madrid_Edad_2026T2 | B17: Madrid: ocupados, parados, población, tasas de actividad/empleo/paro por edad y por sexo (calculadas). | C17: 2026T2
A18: EPA_Sectores_2026T2 | B18: Ocupados por sector (CNAE-2025) × sexo × edad (datos largos). | C18: 2026T2, España y Madrid
A19: EPA_Sectores_Resumen | B19: Resumen por sector con pesos y % de mujeres (SUMIFS). | C19: 2026T2
... A21: Paro_Registrado_Afiliacion | B21: Paro registrado (SEPE), contratos, prestaciones y afiliados (Seguridad Social). | C21: 2026-06 a 2026-09 según fila
A22: FUENTES | B22: Origen de cada bloque: organismo, tabla, URL de la API y observaciones.
A24: Notas, límites y huecos conocidos
A25: • La EPA publica los datos de ambos sexos por tramos de edad; las series por sexo trimestrales y por tramos finos de edad no se descargaron (sí las medias anuales por sexo y edad, hoja EPA_Paro_Anual_SexoEdad).
A26: • El tramo 20–24 no existe antes de 2008T4/2009T1 en las series descargadas; las celdas vacías significan "sin dato".
A27: • La definición de EPA (INE) y la de Eurostat (EU-LFS) difieren en el tramo de edad (INE: 16 y más; Eurostat: 15–74 o 15–64) y las cifras no coinciden exactamente; úsese una misma fuente para comparar.
A28: • Los datos de sector de la EPA de 2026 usan CNAE-2025 (solo 4 grandes sectores en el cruce con sexo y edad). La serie histórica por sector en CNAE-2009 (tabla 66088) llega solo hasta 2008 y no se incluye.
A29: • Paro registrado: la cifra nacional es de septiembre de 2026 (Seguridad Social) y la de Madrid de junio de 2026 (boletín de la Comunidad de Madrid, cuyo encabezado indica julio pero el cuerpo junio). El boletín trae además una cifra nacional de paro (19.517) y de extranjeros en Madrid (1.345) que son erratas evidentes y se han excluido.
A30: • No incluido (huecos): serie histórica de paro registrado y afiliación por provincia/sector/edad, parados de larga duración, tipo de contrato y jornada en la EPA, población inactiva por motivo, NEET. Pendientes para una segunda fase.
A31: • Madrid por sexo y edad en cifras absolutas: solo se descargó hombres y ambos sexos (mujeres = ambos − hombres, cálculo propio).
A33: Convención de colores
A34: Azul: dato copiado de la fuente (valor fijo)
A35: Negro: fórmula de esta hoja
A36: Verde: fórmula que enlaza con otra hoja
... A38: Fondo amarillo claro: estimación no oficial (elaboración propia)

Sheet Resumen_Empleo
A1: Resumen de empleo y desempleo — España y Comunidad de Madrid
A2: Los valores enlazan con las hojas de detalle (verde). Último dato disponible a fecha de consulta: 2026-10-21
A4: Indicador | B4: Periodo | C4: España | D4: Madrid | E4: Madrid − España | F4: Hoja de origen / nota
A5: Tasa de paro EPA (%) | B5: 2026T2 | C5: =EPA_Tasas_Trim!CY7 -> 9.87 | D5: =EPA_Tasas_Trim!CY2 -> 7.58 | E5: =D5-C5 -> -2.29 | F5: EPA_Tasas_Trim
A6: Tasa de paro menores de 25 (%) | B6: 2026T2 | C6: =EPA_Tasas_Trim!CY8 -> 23.77 | D6: =EPA_Tasas_Trim!CY3 -> 19.81 | E6: =D6-C6 -> -3.96 | F6: EPA_Tasas_Trim
A7: Tasa de empleo (%) | B7: 2026T2 | C7: =EPA_Tasas_Trim!CY17 -> 53.44 | D7: =EPA_Tasas_Trim!CY12 -> 59.08 | E7: =D7-C7 -> 5.64 | F7: EPA_Tasas_Trim
A8: Tasa de actividad (%) | B8: 2026T2 | C8: =EPA_Tasas_Trim!CY27 -> 59.29 | D8: =EPA_Tasas_Trim!CY22 -> 63.92 | E8: =D8-C8 -> 4.63 | F8: EPA_Tasas_Trim
A9: Ocupados (miles) | B9: 2026T2 | C9: =EPA_Absolutos_2026T2!B2 -> 22779 | D9: =EPA_Absolutos_2026T2!B15 -> 3631.3 | F9: EPA_Absolutos_2026T2
A10: Parados (miles) | B10: 2026T2 | C10: =EPA_Absolutos_2026T2!C2 -> 2495.3 | D10: =EPA_Absolutos_2026T2!C15 -> 297.9 | F10: EPA_Absolutos_2026T2
A11: Activos (miles, calculado) | B11: 2026T2 | C11: =EPA_Absolutos_2026T2!E2 -> 25274.3 | D11: =EPA_Absolutos_2026T2!E15 -> 3929.2 | F11: ocupados + parados
A12: Tasa de paro recalculada (%) | B12: 2026T2 | C12: =EPA_Absolutos_2026T2!F2 -> 9.8728748 | D12: =EPA_Absolutos_2026T2!F15 -> 7.581696 | E12: =D12-C12 -> -2.2911788 | F12: Control: debe coincidir con la publicada (±0,05)
A13: Tasa de paro, media anual (%) | B13: 2025 | C13: =EPA_Paro_Anual_SexoEdad!X2 -> 10.5 | D13: =EPA_Paro_Anual_SexoEdad!X23 -> 7.97 | E13: =D13-C13 -> -2.53 | F13: EPA_Paro_Anual_SexoEdad (INE 74999)
A14: Máximo anual de la tasa de paro (%) 2006–2025 | B14: 2006–2025 | C14: =MAX(EPA_Paro_Anual_SexoEdad!E2:X2) -> 26.09 | D14: =MAX(EPA_Paro_Anual_SexoEdad!E23:X23) -> 19.76 | E14: =D14-C14 -> -6.33 | F14: EPA_Paro_Anual_SexoEdad
A15: Año del máximo | C15: =INDEX(EPA_Paro_Anual_SexoEdad!$E$1:$X$1,MATCH(MAX(EPA_Paro_Anual_SexoEdad!E2:X2),EPA_Paro_Anual_SexoEdad!E2:X2,0)) -> 2013 | D15: =INDEX(EPA_Paro_Anual_SexoEdad!$E$1:$X$1,MATCH(MAX(EPA_Paro_Anual_SexoEdad!E23:X23),EPA_Paro_Anual_SexoEdad!E23:X23,0)) -> 2013
A16: Paro registrado (personas) | B16: España 2026-09 / Madrid 2026-06 | C16: =Paro_Registrado_Afiliacion!E2 -> 2379505 | D16: =Paro_Registrado_Afiliacion!E7 -> 273631 | F16: Periodos distintos: la fuente de Madrid consultada llegaba a junio 2026
A17: Afiliados medios a la Seguridad Social (personas) | B17: 2026-08 | C17: =Paro_Registrado_Afiliacion!E29 -> 22345226 | D17: =Paro_Registrado_Afiliacion!E25 -> 3871993 | F17: Paro_Registrado_Afiliacion
A18: Tasa de paro 15–74 (Eurostat, %) | B18: 2025 | C18: =Eurostat_Paro_NUTS2!X34 -> 10.5 | D18: =Eurostat_Paro_NUTS2!X4 -> 8 | E18: =D18-C18 -> -2.5 | F18: Eurostat_Paro_NUTS2 (EU-LFS, definición ILO, 15–74 años)

Sheet EPA_Tasas_Trim
A1: indicador | B1: territorio | C1: sexo | D1: edad | E1: cod_INE | F1: 2002T1 | G1: 2002T2 | H1: 2002T3 | I1: 2002T4 | J1: 2003T1 | K1: 2003T2 | L1: 2003T3 | M1: 2003T4 | N1: 2004T1 | O1: 2004T2 | P1: 2004T3 | Q1: 2004T4 | R1: 2005T1 | S1: 2005T2 | T1: 2005T3 | U1: 2005T4 | V1: 2006T1 | W1: 2006T2 | X1: 2006T3 | Y1: 2006T4 | Z1: 2007T1 | AA1: 2007T2 | AB1: 2007T3 | AC1: 2007T4 | AD1: 2008T1 | AE1: 2008T2 | AF1: 2008T3 | AG1: 2008T4 | AH1: 2009T1 | AI1: 2009T2 | AJ1: 2009T3 | AK1: 2009T4 | AL1: 2010T1 | AM1: 2010T2 | AN1: 2010T3 | AO1: 2010T4 | AP1: 2011T1 | AQ1: 2011T2 | AR1: 2011T3 | AS1: 2011T4 | AT1: 2012T1 | AU1: 2012T2 | AV1: 2012T3 | AW1: 2012T4 | AX1: 2013T1 | AY1: 2013T2 | AZ1: 2013T3 | BA1: 2013T4 | BB1: 2014T1 | BC1: 2014T2 | BD1: 2014T3 | BE1: 2014T4 | BF1: 2015T1 | BG1: 2015T2 | BH1: 2015T3 | BI1: 2015T4 | BJ1: 2016T1 | BK1: 2016T2 | BL1: 2016T3 | BM1: 2016T4 | BN1: 2017T1 | BO1: 2017T2 | BP1: 2017T3 | BQ1: 2017T4 | BR1: 2018T1 | BS1: 2018T2 | BT1: 2018T3 | BU1: 2018T4 | BV1: 2019T1 | BW1: 2019T2 | BX1: 2019T3 | BY1: 2019T4 | BZ1: 2020T1 | CA1: 2020T2 | CB1: 2020T3 | CC1: 2020T4 | CD1: 2021T1 | CE1: 2021T2 | CF1: 2021T3 | CG1: 2021T4 | CH1: 2022T1 | CI1: 2022T2 | CJ1: 2022T3 | CK1: 2022T4 | CL1: 2023T1 | CM1: 2023T2 | CN1: 2023T3 | CO1: 2023T4 | CP1: 2024T1 | CQ1: 2024T2 | CR1: 2024T3 | CS1: 2024T4 | CT1: 2025T1 | CU1: 2025T2 | CV1: 2025T3 | CW1: 2025T4 | CX1: 2026T1 | CY1: 2026T2
A2: Tasa de paro | B2: Comunidad de Madrid | C2: Ambos sexos | D2: Total | E2: EPA452536 | F2: 7.49 | G2: 6.96 | H2: 7.75 | I2: 6.99 | J2: 7.77 | K2: 7.06 | L2: 7.48 | M2: 7.16 | N2: 6.65 | O2: 6.86 | P2: 6.49 | Q2: 6.95 | R2: 8.26 | S2: 6.96 | T2: 6.22 | U2: 5.9 | V2: 5.87 | W2: 6.91 | X2: 5.97 | Y2: 6.46 | Z2: 6.43 | AA2: 6.17 | AB2: 5.97 | AC2: 6.4 | AD2: 7.39 | AE2: 8.67 | AF2: 8.32 | AG2: 10.02 | AH2: 13.36 | AI2: 13.4 | AJ2: 14.18 | AK2: 14.48 | AL2: 15.89 | AM2: 16.18 | AN2: 15.76 | AO2: 15.54 | AP2: 15.18 | AQ2: 15.62 | AR2: 16.59 | AS2: 17.96 | AT2: 18.15 | AU2: 18.42 | AV2: 18.23 | AW2: 19.32 | AX2: 19.99 | AY2: 19.2 | AZ2: 19.41 | BA2: 20.45 | BB2: 20.43 | BC2: 19.03 | BD2: 17.53 | BE2: 18 | BF2: 17.79 | BG2: 17.66 | BH2: 16.27 | BI2: 16.51 | BJ2: 16.81 | BK2: 16.25 | BL2: 15.19 | BM2: 14.6 | BN2: 14.23 | BO2: 13.04 | BP2: 12.35 | BQ2: 13.75 | BR2: 13.4 | BS2: 12.08 | BT2: 11.86 | BU2: 11.54 | BV2: 11.7 | BW2: 10.54 | BX2: 10.26 | BY2: 9.99 | BZ2: 10.6 | CA2: 12.61 | CB2: 13.25 | CC2: 13.53 | CD2: 12.24 | CE2: 12.2 | CF2: 12.13 | CG2: 10.18 | CH2: 11.72 | CI2: 10.7 | CJ2: 11.11 | CK2: 11.33 | CL2: 10.83 | CM2: 9.11 | CN2: 10.24 | CO2: 9.64 | CP2: 9.19 | CQ2: 8.48 | CR2: 9.65 | CS2: 8.58 | CT2: 9.11 | CU2: 7.74 | CV2: 7.98 | CW2: 7.04 | CX2: 7.91 | CY2: 7.58
A3: Tasa de paro | B3: Comunidad de Madrid | C3: Ambos sexos | D3: Menores de 25 | E3: EPA452538 | F3: 14.49 | G3: 14.33 | H3: 15.54 | I3: 15.44 | J3: 14.18 | K3: 14.28 | L3: 18.85 | M3: 19.76 | N3: 15.61 | O3: 13.78 | P3: 17.32 | Q3: 16.12 | R3: 20.89 | S3: 17.02 | T3: 16.15 | U3: 12.73 | V3: 12.55 | W3: 15.53 | X3: 13.16 | Y3: 17.33 | Z3: 15.7 | AA3: 17.9 | AB3: 17.01 | AC3: 16.38 | AD3: 20.53 | AE3: 20.88 | AF3: 19.32 | AG3: 22.35 | AH3: 28.31 | AI3: 36.26 | AJ3: 39.02 | AK3: 33.21 | AL3: 33.93 | AM3: 37.05 | AN3: 37.81 | AO3: 39.67 | AP3: 36.58 | AQ3: 40.65 | AR3: 43.04 | AS3: 43.15 | AT3: 49.87 | AU3: 44.11 | AV3: 49.15 | AW3: 49.09 | AX3: 48.16 | AY3: 45.52 | AZ3: 50.38 | BA3: 51.18 | BB3: 54.09 | BC3: 47.93 | BD3: 47.57 | BE3: 46.37 | BF3: 47.98 | BG3: 42.67 | BH3: 44.32 | BI3: 41.68 | BJ3: 42.4 | BK3: 44.02 | BL3: 37.75 | BM3: 37.9 | BN3: 35.81 | BO3: 35.37 | BP3: 31.69 | BQ3: 35.89 | BR3: 25.11 | BS3: 26.6 | BT3: 27.7 | BU3: 30.42 | BV3: 33.16 | BW3: 29.24 | BX3: 29.69 | BY3: 24.27 | BZ3: 24.91 | CA3: 32.53 | CB3: 35.49 | CC3: 34.2 | CD3: 31.15 | CE3: 33.45 | CF3: 29.58 | CG3: 23.73 | CH3: 26.2 | CI3: 24.18 | CJ3: 32.77 | CK3: 27.92 | CL3: 28.46 | CM3: 24.83 | CN3: 30.76 | CO3: 25.34 | CP3: 18.68 | CQ3: 18.05 | CR3: 26.77 | CS3: 17.77 | CT3: 19.57 | CU3: 16.85 | CV3: 22.78 | CW3: 18.14 | CX3: 21.91 | CY3: 19.81
A4: Tasa de paro | B4: Comunidad de Madrid | C4: Ambos sexos | D4: 25 y más | E4: EPA452539 | F4: 6.6 | G4: 6.02 | H4: 6.74 | I4: 5.96 | J4: 7 | K4: 6.17 | L4: 6.07 | M4: 5.65 | N4: 5.63 | O4: 6.06 | P4: 5.28 | Q4: 5.94 | R4: 6.78 | S4: 5.68 | T4: 4.97 | U4: 5.08 | V4: 5.11 | W4: 5.9 | X4: 5.09 | Y4: 5.13 | Z4: 5.34 | AA4: 4.82 | AB4: 4.67 | AC4: 5.34 | AD4: 5.97 | AE4: 7.35 | AF4: 7.12 | AG4: 8.76 | AH4: 11.9 | AI4: 11.22 | AJ4: 11.75 | AK4: 12.78 | AL4: 14.31 | AM4: 14.35 | AN4: 13.8 | AO4: 13.54 | AP4: 13.5 | AQ4: 13.64 | AR4: 14.47 | AS4: 16.06 | AT4: 15.78 | AU4: 16.56 | AV4: 15.98 | AW4: 17.28 | AX4: 17.94 | AY4: 17.36 | AZ4: 17.28 | BA4: 18.25 | BB4: 18.08 | BC4: 17.07 | BD4: 15.49 | BE4: 16.03 | BF4: 15.72 | BG4: 15.9 | BH4: 14.24 | BI4: 14.84 | BJ4: 15.13 | BK4: 14.38 | BL4: 13.79 | BM4: 13.22 | BN4: 12.96 | BO4: 11.64 | BP4: 11.1 | BQ4: 12.31 | BR4: 12.64 | BS4: 11.11 | BT4: 10.79 | BU4: 10.28 | BV4: 10.37 | BW4: 9.35 | BX4: 8.97 | BY4: 9.07 | BZ4: 9.7 | CA4: 11.52 | CB4: 11.89 | CC4: 12.18 | CD4: 10.96 | CE4: 10.71 | CF4: 10.87 | CG4: 9.27 | CH4: 10.7 | CI4: 9.72 | CJ4: 9.46 | CK4: 10.18 | CL4: 9.51 | CM4: 8.04 | CN4: 8.73 | CO4: 8.56 | CP4: 8.48 | CQ4: 7.81 | CR4: 8.31 | CS4: 7.87 | CT4: 8.3 | CU4: 7.03 | CV4: 6.88 | CW4: 6.21 | CX4: 6.89 | CY4: 6.57
A5: Tasa de paro | B5: Comunidad de Madrid | C5: Ambos sexos | D5: 16 a 19 | E5: EPA452540 | F5: 19.28 | G5: 18.55 | H5: 24.96 | I5: 27.17 | J5: 23.25 | K5: 21.33 | L5: 26.64 | M5: 23.65 | N5: 26.45 | O5: 24.53 | P5: 25.66 | Q5: 27.15 | R5: 29.57 | S5: 24.19 | T5: 27.74 | U5: 20.76 | V5: 21.42 | W5: 30.84 | X5: 24.88 | Y5: 41.03 | Z5: 30.89 | AA5: 25.64 | AB5: 29.23 | AC5: 27.85 | AD5: 35.35 | AE5: 45.91 | AF5: 29.48 | AG5: 31.27 | AH5: 44.15 | AI5: 56.13 | AJ5: 60.51 | AK5: 48.93 | AL5: 48.3 | AM5: 66.83 | AN5: 58.71 | AO5: 60.86 | AP5: 61.12 | AQ5: 64.65 | AR5: 55.17 | AS5: 71.77 | AT5: 74.86 | AU5: 75.74 | AV5: 86.44 | AW5: 71.85 | AX5: 67.33 | AY5: 68.04 | AZ5: 79.87 | BA5: 78.58 | BB5: 74.25 | BC5: 67.47 | BD5: 64.17 | BE5: 68.93 | BF5: 60.93 | BG5: 72.56 | BH5: 69.25 | BI5: 70.27 | BJ5: 66.58 | BK5: 66.13 | BL5: 53.83 | BM5: 48.28 | BN5: 62.6 | BO5: 61.36 | BP5: 52.95 | BQ5: 64.87 | BR5: 56.71 | BS5: 50.88 | BT5: 52.22 | BU5: 47.85 | BV5: 45.24 | BW5: 45.29 | BX5: 48.02 | BY5: 46.66 | BZ5: 47.77 | CA5: 35.72 | CB5: 50.39 | CC5: 55.37 | CD5: 54.03 | CE5: 62.65 | CF5: 42.47 | CG5: 52.54 | CH5: 53.59 | CI5: 42.06 | CJ5: 46.21 | CK5: 52.24 | CL5: 45.86 | CM5: 39.13 | CN5: 53.53 | CO5: 32.77 | CP5: 27.94 | CQ5: 28.33 | CR5: 40.53 | CS5: 34.08 | CT5: 32.04 | CU5: 25.95 | CV5: 38.01 | CW5: 26.48 | CX5: 55.39 | CY5: 39.83
A6: Tasa de paro | B6: Comunidad de Madrid | C6: Ambos sexos | D6: 20 a 24 | E6: EPA452541 | AH6: 24.52 | AI6: 31.97 | AJ6: 33.96 | AK6: 29.91 | AL6: 31.06 | AM6: 31.17 | AN6: 33.77 | AO6: 35.44 | AP6: 31.85 | AQ6: 35.91 | AR6: 40.39 | AS6: 37.82 | AT6: 45.52 | AU6: 38.11 | AV6: 41.41 | AW6: 45.53 | AX6: 44.99 | AY6: 42.16 | AZ6: 44.96 | BA6: 46.47 | BB6: 50.5 | BC6: 44.4 | BD6: 44.74 | BE6: 42.18 | BF6: 46.19 | BG6: 37.89 | BH6: 39.77 | BI6: 36.21 | BJ6: 37.17 | BK6: 40.22 | BL6: 34.97 | BM6: 36.17 | BN6: 31.89 | BO6: 31.09 | BP6: 28.22 | BQ6: 31.23 | BR6: 21.08 | BS6: 23.92 | BT6: 22.92 | BU6: 26.6 | BV6: 30.89 | BW6: 26.2 | BX6: 26.66 | BY6: 20.1 | BZ6: 21.02 | CA6: 31.98 | CB6: 32.78 | CC6: 30.8 | CD6: 26.89 | CE6: 27.35 | CF6: 26.67 | CG6: 19.25 | CH6: 20.77 | CI6: 21.14 | CJ6: 30.25 | CK6: 23.93 | CL6: 25.34 | CM6: 23.07 | CN6: 26.76 | CO6: 24.47 | CP6: 17.41 | CQ6: 16.62 | CR6: 24.43 | CS6: 15.05 | CT6: 17.6 | CU6: 15.51 | CV6: 20.06 | CW6: 17.05 | CX6: 16.56 | CY6: 16.25
A7: Tasa de paro | B7: España | C7: Ambos sexos | D7: Total | E7: EPA452434 | F7: 11.55 | G7: 11.15 | H7: 11.49 | I7: 11.61 | J7: 11.99 | K7: 11.28 | L7: 11.3 | M7: 11.37 | N7: 11.5 | O7: 11.09 | P7: 10.74 | Q7: 10.53 | R7: 10.17 | S7: 9.32 | T7: 8.41 | U7: 8.71 | V7: 9.03 | W7: 8.44 | X7: 8.08 | Y7: 8.26 | Z7: 8.42 | AA7: 7.93 | AB7: 8.01 | AC7: 8.57 | AD7: 9.6 | AE7: 10.36 | AF7: 11.23 | AG7: 13.79 | AH7: 17.24 | AI7: 17.77 | AJ7: 17.75 | AK7: 18.66 | AL7: 19.84 | AM7: 19.89 | AN7: 19.59 | AO7: 20.11 | AP7: 21.08 | AQ7: 20.64 | AR7: 21.28 | AS7: 22.56 | AT7: 24.19 | AU7: 24.4 | AV7: 24.79 | AW7: 25.77 | AX7: 26.94 | AY7: 26.06 | AZ7: 25.65 | BA7: 25.73 | BB7: 25.93 | BC7: 24.47 | BD7: 23.67 | BE7: 23.7 | BF7: 23.78 | BG7: 22.37 | BH7: 21.18 | BI7: 20.9 | BJ7: 21 | BK7: 20 | BL7: 18.91 | BM7: 18.63 | BN7: 18.75 | BO7: 17.22 | BP7: 16.38 | BQ7: 16.55 | BR7: 16.74 | BS7: 15.28 | BT7: 14.55 | BU7: 14.45 | BV7: 14.7 | BW7: 14.02 | BX7: 13.92 | BY7: 13.78 | BZ7: 14.41 | CA7: 15.33 | CB7: 16.26 | CC7: 16.13 | CD7: 16.14 | CE7: 15.39 | CF7: 14.71 | CG7: 13.44 | CH7: 13.73 | CI7: 12.69 | CJ7: 12.73 | CK7: 12.99 | CL7: 13.38 | CM7: 11.67 | CN7: 11.89 | CO7: 11.8 | CP7: 12.29 | CQ7: 11.27 | CR7: 11.21 | CS7: 10.61 | CT7: 11.36 | CU7: 10.29 | CV7: 10.45 | CW7: 9.93 | CX7: 10.83 | CY7: 9.87
A8: Tasa de paro | B8: España | C8: Ambos sexos | D8: Menores de 25 | E8: EPA452436 | F8: 22.08 | G8: 21.5 | H8: 22.05 | I8: 23.16 | J8: 23.39 | K8: 22.28 | L8: 22.19 | M8: 22.94 | N8: 22.65 | O8: 22.46 | P8: 21.63 | Q8: 21.27 | R8: 21.69 | S8: 20.29 | T8: 18.01 | U8: 18.62 | V8: 18.71 | W8: 18.2 | X8: 16.9 | Y8: 17.81 | Z8: 17.72 | AA8: 18.12 | AB8: 17.87 | AC8: 18.66 | AD8: 21.08 | AE8: 23.62 | AF8: 24.18 | AG8: 28.97 | AH8: 35.54 | AI8: 38.06 | AJ8: 38.57 | AK8: 38.81 | AL8: 40.73 | AM8: 41.97 | AN8: 40.56 | AO8: 42.73 | AP8: 45.3 | AQ8: 45.87 | AR8: 45.58 | AS8: 48.14 | AT8: 51.67 | AU8: 53.04 | AV8: 52.01 | AW8: 54.83 | AX8: 56.92 | AY8: 55.98 | AZ8: 54.14 | BA8: 54.89 | BB8: 55.49 | BC8: 53.12 | BD8: 52.39 | BE8: 51.8 | BF8: 51.36 | BG8: 49.22 | BH8: 46.58 | BI8: 46.24 | BJ8: 46.5 | BK8: 46.48 | BL8: 41.94 | BM8: 42.92 | BN8: 41.66 | BO8: 39.53 | BP8: 35.97 | BQ8: 37.46 | BR8: 36.34 | BS8: 34.68 | BT8: 33 | BU8: 33.54 | BV8: 34.97 | BW8: 33.14 | BX8: 31.68 | BY8: 30.51 | BZ8: 32.99 | CA8: 39.61 | CB8: 40.45 | CC8: 40.13 | CD8: 39.44 | CE8: 38.47 | CF8: 31.66 | CG8: 30.98 | CH8: 30.04 | CI8: 29.23 | CJ8: 30.39 | CK8: 28.97 | CL8: 29.85 | CM8: 28.12 | CN8: 28.28 | CO8: 28.52 | CP8: 27.7 | CQ8: 26.58 | CR8: 26.89 | CS8: 24.9 | CT8: 26.53 | CU8: 24.54 | CV8: 25.42 | CW8: 23.01 | CX8: 24.54 | CY8: 23.77
A9: Tasa de paro | B9: España | C9: Ambos sexos | D9: 25 y más | E9: EPA452437 | F9: 9.96 | G9: 9.6 | H9: 9.87 | I9: 9.92 | J9: 10.37 | K9: 9.72 | L9: 9.71 | M9: 9.78 | N9: 10 | O9: 9.56 | P9: 9.22 | Q9: 9.13 | R9: 8.62 | S9: 7.83 | T9: 7.06 | U9: 7.41 | V9: 7.79 | W9: 7.18 | X9: 6.91 | Y9: 7.07 | Z9: 7.29 | AA9: 6.68 | AB9: 6.73 | AC9: 7.37 | AD9: 8.27 | AE9: 8.8 | AF9: 9.63 | AG9: 12.06 | AH9: 15.25 | AI9: 15.59 | AJ9: 15.45 | AK9: 16.65 | AL9: 17.81 | AM9: 17.72 | AN9: 17.49 | AO9: 18.02 | AP9: 18.9 | AQ9: 18.36 | AR9: 18.99 | AS9: 20.37 | AT9: 21.9 | AU9: 21.99 | AV9: 22.42 | AW9: 23.46 | AX9: 24.54 | AY9: 23.68 | AZ9: 23.28 | BA9: 23.48 | BB9: 23.72 | BC9: 22.35 | BD9: 21.43 | BE9: 21.64 | BF9: 21.81 | BG9: 20.42 | BH9: 19.22 | BI9: 19.13 | BJ9: 19.28 | BK9: 18.15 | BL9: 17.24 | BM9: 17 | BN9: 17.22 | BO9: 15.67 | BP9: 14.89 | BQ9: 15.08 | BR9: 15.44 | BS9: 13.91 | BT9: 13.16 | BU9: 13.11 | BV9: 13.31 | BW9: 12.67 | BX9: 12.55 | BY9: 12.61 | BZ9: 13.14 | CA9: 13.81 | CB9: 14.51 | CC9: 14.55 | CD9: 14.64 | CE9: 13.77 | CF9: 13.42 | CG9: 12.27 | CH9: 12.61 | CI9: 11.46 | CJ9: 11.34 | CK9: 11.85 | CL9: 12.21 | CM9: 10.44 | CN9: 10.54 | CO9: 10.55 | CP9: 11.14 | CQ9: 10.08 | CR9: 9.86 | CS9: 9.52 | CT9: 10.23 | CU9: 9.15 | CV9: 9.16 | CW9: 8.93 | CX9: 9.77 | CY9: 8.72
A10: Tasa de paro | B10: España | C10: Ambos sexos | D10: 16 a 19 | E10: EPA423476 | F10: 28.42 | G10: 29.48 | H10: 30.06 | I10: 31.55 | J10: 33.85 | K10: 34.13 | L10: 31.49 | M10: 32.07 | N10: 32.45 | O10: 32.16 | P10: 29.28 | Q10: 29.04 | R10: 31.21 | S10: 31.07 | T10: 26.88 | U10: 27.83 | V10: 29.68 | W10: 31.22 | X10: 24.87 | Y10: 31.23 | Z10: 27.59 | AA10: 29.19 | AB10: 27.21 | AC10: 31.08 | AD10: 32.82 | AE10: 40.96 | AF10: 38.34 | AG10: 45.83 | AH10: 54.25 | AI10: 56.18 | AJ10: 53.52 | AK10: 57.47 | AL10: 59.54 | AM10: 62.15 | AN10: 59.99 | AO10: 63.67 | AP10: 65.3 | AQ10: 62.53 | AR10: 60.38 | AS10: 69.15 | AT10: 71.44 | AU10: 73.19 | AV10: 71.89 | AW10: 73.88 | AX10: 75.63 | AY10: 73 | AZ10: 72.15 | BA10: 75.53 | BB10: 70.16 | BC10: 70.39 | BD10: 66.71 | BE10: 67.28 | BF10: 70.45 | BG10: 69.36 | BH10: 63.73 | BI10: 66.09 | BJ10: 64.12 | BK10: 63.52 | BL10: 54.69 | BM10: 58.67 | BN10: 58.74 | BO10: 55.98 | BP10: 50.41 | BQ10: 54.2 | BR10: 56.15 | BS10: 51.64 | BT10: 45.43 | BU10: 46.89 | BV10: 49.26 | BW10: 46.26 | BX10: 42.15 | BY10: 43.9 | BZ10: 47.29 | CA10: 54.5 | CB10: 55.93 | CC10: 60.14 | CD10: 58.42 | CE10: 55.15 | CF10: 43.25 | CG10: 50.23 | CH10: 45.73 | CI10: 48.78 | CJ10: 43.83 | CK10: 41.29 | CL10: 45.3 | CM10: 43.5 | CN10: 41.41 | CO10: 42.86 | CP10: 41.06 | CQ10: 44.52 | CR10: 38.43 | CS10: 38.79 | CT10: 40.22 | CU10: 39.88 | CV10: 37.36 | CW10: 30.43 | CX10: 39.13 | CY10: 41.12
A11: Tasa de paro | B11: España | C11: Ambos sexos | D11: 20 a 24 | E11: EPA423477 | AH11: 30.63 | AI11: 33.26 | AJ11: 34.54 | AK11: 34.67 | AL11: 36.31 | AM11: 36.96 | AN11: 35.95 | AO11: 38.33 | AP11: 41.14 | AQ11: 42.17 | AR11: 42 | AS11: 44.05 | AT11: 47.71 | AU11: 48.7 | AV11: 47.68 | AW11: 51.41 | AX11: 53.39 | AY11: 52.62 | AZ11: 50.14 | BA11: 50.93 | BB11: 52.86 | BC11: 49.99 | BD11: 49.54 | BE11: 48.88 | BF11: 47.74 | BG11: 45.26 | BH11: 42.89 | BI11: 42.52 | BJ11: 43.26 | BK11: 43.33 | BL11: 39.27 | BM11: 39.83 | BN11: 38.37 | BO11: 36.15 | BP11: 32.69 | BQ11: 33.95 | BR11: 32.37 | BS11: 30.97 | BT11: 30.1 | BU11: 30.78 | BV11: 32 | BW11: 30.22 | BX11: 29.28 | BY11: 27.72 | BZ11: 30.12 | CA11: 36.89 | CB11: 37.18 | CC11: 36.52 | CD11: 36.28 | CE11: 35.02 | CF11: 28.83 | CG11: 27.2 | CH11: 26.82 | CI11: 24.81 | CJ11: 27.25 | CK11: 26.47 | CL11: 26.86 | CM11: 24.94 | CN11: 25.14 | CO11: 25.72 | CP11: 24.98 | CQ11: 22.42 | CR11: 24.02 | CS11: 22.02 | CT11: 24.06 | CU11: 21.3 | CV11: 22.65 | CW11: 21.78 | CX11: 21.77 | CY11: 19.88
A12: Tasa de empleo | B12: Comunidad de Madrid | C12: Ambos sexos | D12: Total | E12: EPA440971 | F12: 54.03 | G12: 54.52 | H12: 54.58 | I12: 54.69 | J12: 54.56 | K12: 55.13 | L12: 55.11 | M12: 55.5 | N12: 56.25 | O12: 56.74 | P12: 56.75 | Q12: 57.36 | R12: 57.84 | S12: 59.53 | T12: 59.21 | U12: 59.37 | V12: 60.03 | W12: 59.88 | X12: 60 | Y12: 61 | Z12: 60.79 | AA12: 60.75 | AB12: 61.23 | AC12: 60.83 | AD12: 60.09 | AE12: 59.91 | AF12: 60.15 | AG12: 59.39 | AH12: 57.29 | AI12: 57.17 | AJ12: 56.09 | AK12: 56.1 | AL12: 55.43 | AM12: 55.51 | AN12: 55.48 | AO12: 56.02 | AP12: 55.38 | AQ12: 55.52 | AR12: 54.1 | AS12: 53.32 | AT12: 53.5 | AU12: 53.59 | AV12: 53.32 | AW12: 52.47 | AX12: 52.31 | AY12: 52.01 | AZ12: 51.61 | BA12: 50.95 | BB12: 50.5 | BC12: 51.42 | BD12: 52.5 | BE12: 53.15 | BF12: 53.08 | BG12: 53.56 | BH12: 53.53 | BI12: 54.06 | BJ12: 53.44 | BK12: 53.63 | BL12: 53.55 | BM12: 53.96 | BN12: 53.75 | BO12: 54.47 | BP12: 55.09 | BQ12: 54.62 | BR12: 54.79 | BS12: 55.25 | BT12: 55.11 | BU12: 55.68 | BV12: 55.37 | BW12: 56.23 | BX12: 55.97 | BY12: 57.06 | BZ12: 56.28 | CA12: 52.85 | CB12: 53.6 | CC12: 54.76 | CD12: 55.5 | CE12: 55.78 | CF12: 55.81 | CG12: 56.61 | CH12: 56.19 | CI12: 56.71 | CJ12: 55.91 | CK12: 55.99 | CL12: 56.41 | CM12: 57.65 | CN12: 56.65 | CO12: 57.1 | CP12: 57.46 | CQ12: 57.39 | CR12: 57.04 | CS12: 58.03 | CT12: 57.9 | CU12: 58.66 | CV12: 57.84 | CW12: 58.52 | CX12: 58.28 | CY12: 59.08
A13: Tasa de empleo | B13: Comunidad de Madrid | C13: Ambos sexos | D13: Menores de 25 | E13: EPA440973 | F13: 37.56 | G13: 38.03 | H13: 38.95 | I13: 37.09 | J13: 37.41 | K13: 38.99 | L13: 37.6 | M13: 36.65 | N13: 37.68 | O13: 39.65 | P13: 37.15 | Q13: 38.32 | R13: 39.5 | S13: 45.62 | T13: 45.31 | U13: 45.72 | V13: 45.08 | W13: 45.05 | X13: 48.11 | Y13: 47.01 | Z13: 46.81 | AA13: 44.51 | AB13: 46.61 | AC13: 43 | AD13: 41.71 | AE13: 42.22 | AF13: 43.87 | AG13: 40.37 | AH13: 36.26 | AI13: 31.69 | AJ13: 30.93 | AK13: 32.14 | AL13: 31.2 | AM13: 30.07 | AN13: 30.39 | AO13: 27.94 | AP13: 27.67 | AQ13: 26.49 | AR13: 25.53 | AS13: 24.33 | AT13: 21.47 | AU13: 23.53 | AV13: 21.52 | AW13: 20.28 | AX13: 22.16 | AY13: 22.27 | AZ13: 19.94 | BA13: 20.39 | BB13: 18.62 | BC13: 20.56 | BD13: 20.76 | BE13: 22.16 | BF13: 21.07 | BG13: 24.13 | BH13: 23.61 | BI13: 23.02 | BJ13: 22.4 | BK13: 22.09 | BL13: 22.51 | BM13: 21.37 | BN13: 21.92 | BO13: 23.11 | BP13: 25.22 | BQ13: 23.8 | BR13: 27.52 | BS13: 27.3 | BT13: 27.06 | BU13: 25.92 | BV13: 22.98 | BW13: 24.78 | BX13: 25.29 | BY13: 26.65 | BZ13: 25.31 | CA13: 19.29 | CB13: 20.8 | CC13: 23.05 | CD13: 25.29 | CE13: 25.29 | CF13: 27.69 | CG13: 27.76 | CH13: 28.13 | CI13: 29.34 | CJ13: 26.48 | CK13: 25.86 | CL13: 27.77 | CM13: 26.52 | CN13: 26.23 | CO13: 26.57 | CP13: 30.75 | CQ13: 28.43 | CR13: 28.46 | CS13: 31.26 | CT13: 30.69 | CU13: 31.97 | CV13: 28.45 | CW13: 30.04 | CX13: 28.11 | CY13: 32.59
A14: Tasa de empleo | B14: Comunidad de Madrid | C14: Ambos sexos | D14: 25 y más | E14: EPA440974 | F14: 56.95 | G14: 57.41 | H14: 57.29 | I14: 57.7 | J14: 57.47 | K14: 57.83 | L14: 58 | M14: 58.57 | N14: 59.23 | O14: 59.44 | P14: 59.81 | Q14: 60.3 | R14: 60.64 | S14: 61.63 | T14: 61.28 | U14: 61.39 | V14: 62.21 | W14: 62.02 | X14: 61.7 | Y14: 62.98 | Z14: 62.77 | AA14: 63.03 | AB14: 63.27 | AC14: 63.3 | AD14: 62.62 | AE14: 62.32 | AF14: 62.35 | AG14: 61.94 | AH14: 60.08 | AI14: 60.51 | AJ14: 59.35 | AK14: 59.17 | AL14: 58.5 | AM14: 58.7 | AN14: 58.6 | AO14: 59.48 | AP14: 58.77 | AQ14: 59.03 | AR14: 57.53 | AS14: 56.78 | AT14: 57.3 | AU14: 57.13 | AV14: 57.04 | AW14: 56.22 | AX14: 55.8 | AY14: 55.44 | AZ14: 55.24 | BA14: 54.45 | BB14: 54.13 | BC14: 54.92 | BD14: 56.1 | BE14: 56.67 | BF14: 56.71 | BG14: 56.9 | BH14: 56.92 | BI14: 57.58 | BJ14: 56.97 | BK14: 57.22 | BL14: 57.09 | BM14: 57.68 | BN14: 57.4 | BO14: 58.07 | BP14: 58.53 | BQ14: 58.19 | BR14: 57.97 | BS14: 58.54 | BT14: 58.42 | BU14: 59.21 | BV14: 59.24 | BW14: 60.01 | BX14: 59.68 | BY14: 60.77 | BZ14: 60.09 | CA14: 57 | CB14: 57.67 | CC14: 58.71 | CD14: 59.21 | CE14: 59.53 | CF14: 59.24 | CG14: 60.14 | CH14: 59.68 | CI14: 60.13 | CJ14: 59.68 | CK14: 59.9 | CL14: 60.08 | CM14: 61.64 | CN14: 60.57 | CO14: 61.04 | CP14: 60.97 | CQ14: 61.31 | CR14: 60.86 | CS14: 61.64 | CT14: 61.6 | CU14: 62.32 | CV14: 61.77 | CW14: 62.37 | CX14: 62.38 | CY14: 62.7
A15: Tasa de empleo | B15: Comunidad de Madrid | C15: Ambos sexos | D15: 16 a 19 | E15: EPA440975 | F15: 16.42 | G15: 16.06 | H15: 17.68 | I15: 15.28 | J15: 12.17 | K15: 13.03 | L15: 11.95 | M15: 13.67 | N15: 12.36 | O15: 13.04 | P15: 14.67 | Q15: 16.13 | R15: 16.49 | S15: 24.29 | T15: 22.87 | U15: 24.1 | V15: 22.59 | W15: 21.16 | X15: 23.48 | Y15: 17.76 | Z15: 20.43 | AA15: 20.92 | AB15: 20.91 | AC15: 20.35 | AD15: 17.95 | AE15: 16.35 | AF15: 21.7 | AG15: 18.23 | AH15: 13.99 | AI15: 9.88 | AJ15: 9.67 | AK15: 10.75 | AL15: 10.2 | AM15: 6.51 | AN15: 8.1 | AO15: 7.44 | AP15: 6.75 | AQ15: 6.38 | AR15: 8.8 | AS15: 4.62 | AT15: 3.89 | AU15: 3.96 | AV15: 2.39 | AW15: 3.67 | AX15: 4.79 | AY15: 4.08 | AZ15: 3 | BA15: 3.13 | BB15: 3.75 | BC15: 4.65 | BD15: 4.88 | BE15: 4.74 | BF15: 4.5 | BG15: 3.73 | BH15: 4.69 | BI15: 4.37 | BJ15: 5.34 | BK15: 4.5 | BL15: 5.64 | BM15: 5.79 | BN15: 3.71 | BO15: 4.44 | BP15: 5.51 | BQ15: 4.08 | BR15: 4.06 | BS15: 4.08 | BT15: 6.55 | BU15: 7.83 | BV15: 6.67 | BW15: 6.82 | BX15: 5.94 | BY15: 6.6 | BZ15: 5.74 | CA15: 6.05 | CB15: 5.52 | CC15: 4.83 | CD15: 5.97 | CE15: 5.52 | CF15: 9.48 | CG15: 5.32 | CH15: 6.65 | CI15: 7.46 | CJ15: 7.52 | CK15: 5.42 | CL15: 7.4 | CM15: 5.51 | CN15: 6.15 | CO15: 5.98 | CP15: 7.72 | CQ15: 6.88 | CR15: 7.76 | CS15: 8.33 | CT15: 8.13 | CU15: 8.39 | CV15: 8.16 | CW15: 7.29 | CX15: 5.2 | CY15: 8.61
A16: Tasa de empleo | B16: Comunidad de Madrid | C16: Ambos sexos | D16: 20 a 24 | E16: EPA440976 | AG16: 54.41 | AH16: 50.51 | AI16: 45.75 | AJ16: 44.8 | AK16: 46.23 | AL16: 45.15 | AM16: 45.85 | AN16: 45.46 | AO16: 41.9 | AP16: 42.01 | AQ16: 40.33 | AR16: 37.12 | AS16: 38.04 | AT16: 33.73 | AU16: 37.22 | AV16: 34.99 | AW16: 31.96 | AX16: 34.47 | AY16: 35.26 | AZ16: 32.14 | BA16: 32.85 | BB16: 29.44 | BC16: 32.18 | BD16: 32.44 | BE16: 34.98 | BF16: 33.32 | BG16: 39.37 | BH16: 37.86 | BI16: 37.17 | BJ16: 35.43 | BK16: 35.63 | BL16: 35.59 | BM16: 33.53 | BN16: 36.22 | BO16: 37.84 | BP16: 40.84 | BQ16: 39.5 | BR16: 46.23 | BS16: 45.85 | BT16: 43.5 | BU16: 40.49 | BV16: 36.15 | BW16: 39.31 | BX16: 40.94 | BY16: 42.83 | BZ16: 41.05 | CA16: 29.94 | CB16: 33.13 | CC16: 37.78 | CD16: 40.72 | CE16: 41.11 | CF16: 41.93 | CG16: 45.14 | CH16: 45.02 | CI16: 46.33 | CJ16: 41.68 | CK16: 42.23 | CL16: 43.21 | CM16: 42.19 | CN16: 41.2 | CO16: 41.64 | CP16: 47.9 | CQ16: 45.4 | CR16: 44.26 | CS16: 48.61 | CT16: 47.98 | CU16: 50.17 | CV16: 43.4 | CW16: 46.99 | CX16: 45.12 | CY16: 50.58
A17: Tasa de empleo | B17: España | C17: Ambos sexos | D17: Total | E17: EPA441060 | F17: 47.82 | G17: 48.4 | H17: 48.61 | I17: 48.57 | J17: 48.65 | K17: 49.37 | L17: 49.8 | M17: 49.86 | N17: 49.77 | O17: 50.28 | P17: 50.82 | Q17: 51.1 | R17: 51.54 | S17: 52.47 | T17: 52.99 | U17: 53.02 | V17: 53.03 | W17: 53.68 | X17: 53.99 | Y17: 54.01 | Z17: 53.94 | AA17: 54.53 | AB17: 54.73 | AC17: 54.38 | AD17: 53.94 | AE17: 53.85 | AF17: 53.47 | AG17: 52.03 | AH17: 49.97 | AI17: 49.58 | AJ17: 49.39 | AK17: 48.8 | AL17: 48.17 | AM17: 48.4 | AN17: 48.54 | AO17: 48.13 | AP17: 47.48 | AQ17: 47.96 | AR17: 47.58 | AS17: 46.69 | AT17: 45.72 | AU17: 45.74 | AV17: 45.54 | AW17: 44.71 | AX17: 43.97 | AY17: 44.36 | AZ17: 44.64 | BA17: 44.46 | BB17: 44.05 | BC17: 45.04 | BD17: 45.44 | BE17: 45.61 | BF17: 45.32 | BG17: 46.41 | BH17: 46.9 | BI17: 47.01 | BJ17: 46.84 | BK17: 47.53 | BL17: 48.07 | BM17: 47.97 | BN17: 47.76 | BO17: 48.7 | BP17: 49.27 | BQ17: 49.07 | BR17: 48.67 | BS17: 49.81 | BT17: 50.18 | BU17: 50.14 | BV17: 49.78 | BW17: 50.51 | BX17: 50.54 | BY17: 50.64 | BZ17: 49.8 | CA17: 47.03 | CB17: 48.43 | CC17: 48.81 | CD17: 48.27 | CE17: 49.43 | CF17: 50.33 | CG17: 50.67 | CH17: 50.34 | CI17: 51.16 | CJ17: 51.28 | CK17: 50.82 | CL17: 50.62 | CM17: 51.99 | CN17: 52.24 | CO17: 51.89 | CP17: 51.42 | CQ17: 52.26 | CR17: 52.42 | CS17: 52.28 | CT17: 51.92 | CU17: 52.96 | CV17: 53.1 | CW17: 53.09 | CX17: 52.48 | CY17: 53.44
A18: Tasa de empleo | B18: España | C18: Ambos sexos | D18: Menores de 25 | E18: EPA441062 | F18: 36.85 | G18: 37.26 | H18: 38.57 | I18: 36.9 | J18: 36.5 | K18: 37.64 | L18: 39.37 | M18: 37.59 | N18: 37.43 | O18: 37.98 | P18: 40.15 | Q18: 38.64 | R18: 39.86 | S18: 41.69 | T18: 44.7 | U18: 42.2 | V18: 41.77 | W18: 43.08 | X18: 45.44 | Y18: 42.82 | Z18: 41.86 | AA18: 42.88 | AB18: 45.38 | AC18: 41.9 | AD18: 40.16 | AE18: 39.87 | AF18: 41.83 | AG18: 36.59 | AH18: 32.2 | AI18: 30.76 | AJ18: 31.42 | AK18: 28.79 | AL18: 27.44 | AM18: 27.45 | AN18: 28.85 | AO18: 25.96 | AP18: 24.27 | AQ18: 24.39 | AR18: 25.7 | AS18: 22.37 | AT18: 20.47 | AU18: 20.29 | AV18: 21.58 | AW18: 18.65 | AX18: 17.89 | AY18: 18.2 | AZ18: 19.89 | BA18: 18.29 | BB18: 17.44 | BC18: 18.33 | BD18: 19.55 | BE18: 18.81 | BF18: 18.44 | BG18: 19.74 | BH18: 21.96 | BI18: 19.99 | BJ18: 19.3 | BK18: 19.96 | BL18: 22.43 | BM18: 20.42 | BN18: 20.69 | BO18: 22.25 | BP18: 25.64 | BQ18: 23.11 | BR18: 22.29 | BS18: 24.19 | BT18: 26.27 | BU18: 24.26 | BV18: 22.88 | BW18: 24.55 | BX18: 27.03 | BY18: 24.97 | BZ18: 23.22 | CA18: 18.2 | CB18: 21.37 | CC18: 19.84 | CD18: 19.74 | CE18: 22 | CF18: 26.47 | CG18: 23.41 | CH18: 24.12 | CI18: 26.35 | CJ18: 27.11 | CK18: 24.87 | CL18: 24.35 | CM18: 26.53 | CN18: 29.09 | CO18: 25.94 | CP18: 25.99 | CQ18: 27.41 | CR18: 29.86 | CS18: 27.24 | CT18: 25.88 | CU18: 28.56 | CV18: 30.57 | CW18: 28.04 | CX18: 27.57 | CY18: 29.78
A19: Tasa de empleo | B19: España | C19: Ambos sexos | D19: 25 y más | E19: EPA441063 | F19: 49.76 | G19: 50.35 | H19: 50.35 | I19: 50.57 | J19: 50.7 | K19: 51.33 | L19: 51.52 | M19: 51.85 | N19: 51.75 | O19: 52.23 | P19: 52.49 | Q19: 53.04 | R19: 53.34 | S19: 54.11 | T19: 54.24 | U19: 54.63 | V19: 54.69 | W19: 55.23 | X19: 55.23 | Y19: 55.62 | Z19: 55.67 | AA19: 56.18 | AB19: 56.05 | AC19: 56.12 | AD19: 55.86 | AE19: 55.78 | AF19: 55.06 | AG19: 54.13 | AH19: 52.37 | AI19: 52.1 | AJ19: 51.77 | AK19: 51.42 | AL19: 50.86 | AM19: 51.1 | AN19: 51.06 | AO19: 50.94 | AP19: 50.4 | AQ19: 50.91 | AR19: 50.29 | AS19: 49.69 | AT19: 48.82 | AU19: 48.85 | AV19: 48.44 | AW19: 47.85 | AX19: 47.1 | AY19: 47.49 | AZ19: 47.58 | BA19: 47.55 | BB19: 47.18 | BC19: 48.17 | BD19: 48.47 | BE19: 48.73 | BF19: 48.45 | BG19: 49.51 | BH19: 49.79 | BI19: 50.14 | BJ19: 50.03 | BK19: 50.72 | BL19: 51.03 | BM19: 51.15 | BN19: 50.89 | BO19: 51.77 | BP19: 52.01 | BQ19: 52.09 | BR19: 51.75 | BS19: 52.81 | BT19: 52.99 | BU19: 53.19 | BV19: 52.96 | BW19: 53.59 | BX19: 53.35 | BY19: 53.72 | BZ19: 53 | CA19: 50.52 | CB19: 51.72 | CC19: 52.33 | CD19: 51.69 | CE19: 52.73 | CF19: 53.21 | CG19: 53.97 | CH19: 53.54 | CI19: 54.21 | CJ19: 54.26 | CK19: 54.04 | CL19: 53.9 | CM19: 55.16 | CN19: 55.14 | CO19: 55.19 | CP19: 54.66 | CQ19: 55.46 | CR19: 55.34 | CS19: 55.53 | CT19: 55.31 | CU19: 56.14 | CV19: 56.02 | CW19: 56.34 | CX19: 55.74 | CY19: 56.55
A20: Tasa de empleo | B20: España | C20: Ambos sexos | D20: 16 a 19 | E20: EPA441064 | F20: 18.18 | G20: 17.49 | H20: 19.12 | I20: 17.34 | J20: 16.09 | K20: 16.84 | L20: 18.69 | M20: 17.11 | N20: 16.34 | O20: 16.74 | P20: 19.75 | Q20: 18.03 | R20: 18.56 | S20: 20.31 | T20: 23.23 | U20: 20.08 | V20: 18.99 | W20: 20.16 | X20: 24.35 | Y20: 19.58 | Z20: 19.94 | AA20: 21.57 | AB20: 24.22 | AC20: 19.48 | AD20: 18.87 | AE20: 17.34 | AF20: 19.92 | AG20: 14.47 | AH20: 11.74 | AI20: 11.22 | AJ20: 12.37 | AK20: 8.88 | AL20: 8.68 | AM20: 8.66 | AN20: 9.04 | AO20: 6.93 | AP20: 6.4 | AQ20: 7.38 | AR20: 8.76 | AS20: 5.22 | AT20: 4.85 | AU20: 4.92 | AV20: 5.42 | AW20: 3.95 | AX20: 3.85 | AY20: 4.39 | AZ20: 5.23 | BA20: 3.8 | BB20: 4.22 | BC20: 4.21 | BD20: 5.36 | BE20: 4.78 | BF20: 4.18 | BG20: 4.56 | BH20: 6.15 | BI20: 4.61 | BJ20: 4.63 | BK20: 4.87 | BL20: 6.93 | BM20: 5.51 | BN20: 5.35 | BO20: 6.25 | BP20: 8.29 | BQ20: 6.61 | BR20: 5.75 | BS20: 7.21 | BT20: 9.05 | BU20: 7.39 | BV20: 6.85 | BW20: 8.01 | BX20: 9.49 | BY20: 7.73 | BZ20: 6.81 | CA20: 4.71 | CB20: 6.15 | CC20: 4.5 | CD20: 4.35 | CE20: 6.14 | CF20: 9.62 | CG20: 6.18 | CH20: 7.14 | CI20: 7.85 | CJ20: 9.21 | CK20: 7.71 | CL20: 6.9 | CM20: 8.09 | CN20: 10.38 | CO20: 7.59 | CP20: 8.05 | CQ20: 8.7 | CR20: 11.2 | CS20: 8.54 | CT20: 7.22 | CU20: 8.91 | CV20: 10.96 | CW20: 8.22 | CX20: 8.07 | CY20: 9.6
A21: Tasa de empleo | B21: España | C21: Ambos sexos | D21: 20 a 24 | E21: EPA441065 | AG21: 51.58 | AH21: 46.15 | AI21: 44.16 | AJ21: 44.56 | AK21: 42.59 | AL21: 40.52 | AM21: 40.59 | AN21: 42.77 | AO21: 39.37 | AP21: 36.89 | AQ21: 36.45 | AR21: 37.76 | AS21: 34.59 | AT21: 31.61 | AU21: 31.27 | AV21: 33.13 | AW21: 29.16 | AX21: 27.93 | AY21: 28.13 | AZ21: 30.47 | BA21: 28.78 | BB21: 27.07 | BC21: 28.65 | BD21: 29.99 | BE21: 29.19 | BF21: 29.05 | BG21: 31.11 | BH21: 33.88 | BI21: 31.7 | BJ21: 30.55 | BK21: 31.62 | BL21: 34.49 | BM21: 32.09 | BN21: 32.79 | BO21: 34.95 | BP21: 39.48 | BQ21: 36.32 | BR21: 35.59 | BS21: 37.87 | BT21: 40.2 | BU21: 37.97 | BV21: 35.94 | BW21: 38.02 | BX21: 41.33 | BY21: 39.04 | BZ21: 36.6 | CA21: 29.18 | CB21: 33.75 | CC21: 32.33 | CD21: 32.07 | CE21: 34.87 | CF21: 40.17 | CG21: 37.39 | CH21: 37.86 | CI21: 41.34 | CJ21: 41.7 | CK21: 38.89 | CL21: 38.46 | CM21: 41.14 | CN21: 43.97 | CO21: 40.74 | CP21: 40.35 | CQ21: 42.62 | CR21: 44.99 | CS21: 42.37 | CT21: 40.85 | CU21: 44.28 | CV21: 45.97 | CW21: 43.51 | CX21: 42.84 | CY21: 45.56
A22: Tasa de actividad | B22: Comunidad de Madrid | C22: Ambos sexos | D22: Total | E22: EPA436440 | F22: 58.4 | G22: 58.6 | H22: 59.16 | I22: 58.8 | J22: 59.16 | K22: 59.32 | L22: 59.56 | M22: 59.78 | N22: 60.25 | O22: 60.92 | P22: 60.69 | Q22: 61.64 | R22: 63.05 | S22: 63.98 | T22: 63.13 | U22: 63.09 | V22: 63.77 | W22: 64.32 | X22: 63.81 | Y22: 65.2 | Z22: 64.97 | AA22: 64.74 | AB22: 65.12 | AC22: 64.99 | AD22: 64.89 | AE22: 65.59 | AF22: 65.61 | AG22: 66.01 | AH22: 66.13 | AI22: 66.02 | AJ22: 65.35 | AK22: 65.6 | AL22: 65.9 | AM22: 66.22 | AN22: 65.86 | AO22: 66.33 | AP22: 65.3 | AQ22: 65.79 | AR22: 64.86 | AS22: 65 | AT22: 65.37 | AU22: 65.69 | AV22: 65.21 | AW22: 65.03 | AX22: 65.38 | AY22: 64.38 | AZ22: 64.04 | BA22: 64.05 | BB22: 63.47 | BC22: 63.5 | BD22: 63.65 | BE22: 64.82 | BF22: 64.56 | BG22: 65.06 | BH22: 63.93 | BI22: 64.75 | BJ22: 64.24 | BK22: 64.03 | BL22: 63.15 | BM22: 63.18 | BN22: 62.67 | BO22: 62.64 | BP22: 62.85 | BQ22: 63.32 | BR22: 63.27 | BS22: 62.84 | BT22: 62.53 | BU22: 62.94 | BV22: 62.71 | BW22: 62.86 | BX22: 62.37 | BY22: 63.4 | BZ22: 62.96 | CA22: 60.48 | CB22: 61.79 | CC22: 63.33 | CD22: 63.24 | CE22: 63.53 | CF22: 63.52 | CG22: 63.02 | CH22: 63.65 | CI22: 63.5 | CJ22: 62.91 | CK22: 63.15 | CL22: 63.26 | CM22: 63.42 | CN22: 63.11 | CO22: 63.19 | CP22: 63.27 | CQ22: 62.71 | CR22: 63.13 | CS22: 63.48 | CT22: 63.7 | CU22: 63.59 | CV22: 62.85 | CW22: 62.95 | CX22: 63.29 | CY22: 63.92
A23: Tasa de actividad | B23: Comunidad de Madrid | C23: Ambos sexos | D23: Menores de 25 | E23: EPA436442 | F23: 43.92 | G23: 44.4 | H23: 46.12 | I23: 43.87 | J23: 43.59 | K23: 45.49 | L23: 46.34 | M23: 45.68 | N23: 44.65 | O23: 45.99 | P23: 44.94 | Q23: 45.68 | R23: 49.93 | S23: 54.97 | T23: 54.04 | U23: 52.39 | V23: 51.54 | W23: 53.34 | X23: 55.4 | Y23: 56.87 | Z23: 55.53 | AA23: 54.22 | AB23: 56.16 | AC23: 51.42 | AD23: 52.48 | AE23: 53.37 | AF23: 54.37 | AG23: 51.99 | AH23: 50.59 | AI23: 49.71 | AJ23: 50.72 | AK23: 48.13 | AL23: 47.23 | AM23: 47.77 | AN23: 48.86 | AO23: 46.31 | AP23: 43.64 | AQ23: 44.63 | AR23: 44.82 | AS23: 42.8 | AT23: 42.83 | AU23: 42.09 | AV23: 42.32 | AW23: 39.83 | AX23: 42.76 | AY23: 40.89 | AZ23: 40.19 | BA23: 41.76 | BB23: 40.56 | BC23: 39.48 | BD23: 39.6 | BE23: 41.32 | BF23: 40.5 | BG23: 42.09 | BH23: 42.41 | BI23: 39.47 | BJ23: 38.88 | BK23: 39.47 | BL23: 36.16 | BM23: 34.41 | BN23: 34.14 | BO23: 35.76 | BP23: 36.92 | BQ23: 37.12 | BR23: 36.74 | BS23: 37.2 | BT23: 37.42 | BU23: 37.25 | BV23: 34.38 | BW23: 35.02 | BX23: 35.97 | BY23: 35.19 | BZ23: 33.7 | CA23: 28.59 | CB23: 32.25 | CC23: 35.02 | CD23: 36.73 | CE23: 38 | CF23: 39.32 | CG23: 36.4 | CH23: 38.12 | CI23: 38.7 | CJ23: 39.39 | CK23: 35.87 | CL23: 38.81 | CM23: 35.28 | CN23: 37.88 | CO23: 35.59 | CP23: 37.81 | CQ23: 34.69 | CR23: 38.86 | CS23: 38.01 | CT23: 38.16 | CU23: 38.45 | CV23: 36.84 | CW23: 36.69 | CX23: 36 | CY23: 40.64
A24: Tasa de actividad | B24: Comunidad de Madrid | C24: Ambos sexos | D24: 25 y más | E24: EPA436443 | F24: 60.97 | G24: 61.09 | H24: 61.42 | I24: 61.35 | J24: 61.79 | K24: 61.64 | L24: 61.75 | M24: 62.08 | N24: 62.76 | O24: 63.28 | P24: 63.15 | Q24: 64.11 | R24: 65.06 | S24: 65.34 | T24: 64.49 | U24: 64.67 | V24: 65.56 | W24: 65.91 | X24: 65.01 | Y24: 66.39 | Z24: 66.31 | AA24: 66.22 | AB24: 66.36 | AC24: 66.87 | AD24: 66.59 | AE24: 67.26 | AF24: 67.13 | AG24: 67.88 | AH24: 68.19 | AI24: 68.15 | AJ24: 67.25 | AK24: 67.84 | AL24: 68.27 | AM24: 68.54 | AN24: 67.98 | AO24: 68.8 | AP24: 67.94 | AQ24: 68.35 | AR24: 67.26 | AS24: 67.64 | AT24: 68.04 | AU24: 68.47 | AV24: 67.89 | AW24: 67.97 | AX24: 68 | AY24: 67.08 | AZ24: 66.78 | BA24: 66.6 | BB24: 66.08 | BC24: 66.23 | BD24: 66.38 | BE24: 67.48 | BF24: 67.29 | BG24: 67.66 | BH24: 66.37 | BI24: 67.62 | BJ24: 67.13 | BK24: 66.83 | BL24: 66.22 | BM24: 66.47 | BN24: 65.94 | BO24: 65.73 | BP24: 65.84 | BQ24: 66.36 | BR24: 66.36 | BS24: 65.85 | BT24: 65.49 | BU24: 65.99 | BV24: 66.1 | BW24: 66.2 | BX24: 65.56 | BY24: 66.83 | BZ24: 66.55 | CA24: 64.42 | CB24: 65.45 | CC24: 66.86 | CD24: 66.5 | CE24: 66.67 | CF24: 66.47 | CG24: 66.28 | CH24: 66.83 | CI24: 66.6 | CJ24: 65.92 | CK24: 66.68 | CL24: 66.39 | CM24: 67.03 | CN24: 66.37 | CO24: 66.76 | CP24: 66.62 | CQ24: 66.51 | CR24: 66.38 | CS24: 66.91 | CT24: 67.17 | CU24: 67.03 | CV24: 66.33 | CW24: 66.5 | CX24: 66.99 | CY24: 67.11
A25: Tasa de actividad | B25: Comunidad de Madrid | C25: Ambos sexos | D25: 16 a 19 | E25: EPA436444 | F25: 20.34 | G25: 19.72 | H25: 23.56 | I25: 20.98 | J25: 15.86 | K25: 16.56 | L25: 16.29 | M25: 17.91 | N25: 16.8 | O25: 17.28 | P25: 19.74 | Q25: 22.14 | R25: 23.41 | S25: 32.04 | T25: 31.65 | U25: 30.41 | V25: 28.75 | W25: 30.59 | X25: 31.26 | Y25: 30.12 | Z25: 29.56 | AA25: 28.13 | AB25: 29.55 | AC25: 28.2 | AD25: 27.77 | AE25: 30.22 | AF25: 30.77 | AG25: 26.53 | AH25: 25.05 | AI25: 22.53 | AJ25: 24.49 | AK25: 21.05 | AL25: 19.73 | AM25: 19.64 | AN25: 19.62 | AO25: 19.01 | AP25: 17.35 | AQ25: 18.04 | AR25: 19.64 | AS25: 16.37 | AT25: 15.47 | AU25: 16.31 | AV25: 17.62 | AW25: 13.05 | AX25: 14.65 | AY25: 12.77 | AZ25: 14.92 | BA25: 14.6 | BB25: 14.56 | BC25: 14.3 | BD25: 13.62 | BE25: 15.27 | BF25: 11.53 | BG25: 13.58 | BH25: 15.24 | BI25: 14.68 | BJ25: 15.97 | BK25: 13.29 | BL25: 12.21 | BM25: 11.2 | BN25: 9.91 | BO25: 11.49 | BP25: 11.71 | BQ25: 11.61 | BR25: 9.37 | BS25: 8.31 | BT25: 13.72 | BU25: 15.01 | BV25: 12.18 | BW25: 12.46 | BX25: 11.43 | BY25: 12.38 | BZ25: 10.99 | CA25: 9.41 | CB25: 11.12 | CC25: 10.83 | CD25: 12.98 | CE25: 14.78 | CF25: 16.49 | CG25: 11.21 | CH25: 14.33 | CI25: 12.87 | CJ25: 13.98 | CK25: 11.35 | CL25: 13.68 | CM25: 9.06 | CN25: 13.24 | CO25: 8.89 | CP25: 10.71 | CQ25: 9.6 | CR25: 13.04 | CS25: 12.64 | CT25: 11.96 | CU25: 11.34 | CV25: 13.17 | CW25: 9.92 | CX25: 11.66 | CY25: 14.3
A26: Tasa de actividad | B26: Comunidad de Madrid | C26: Ambos sexos | D26: 20 a 24 | E26: EPA436445 | AG26: 68.13 | AH26: 66.92 | AI26: 67.25 | AJ26: 67.84 | AK26: 65.96 | AL26: 65.49 | AM26: 66.61 | AN26: 68.64 | AO26: 64.9 | AP26: 61.65 | AQ26: 62.94 | AR26: 62.27 | AS26: 61.18 | AT26: 61.9 | AU26: 60.14 | AV26: 59.71 | AW26: 58.68 | AX26: 62.66 | AY26: 60.96 | AZ26: 58.39 | BA26: 61.38 | BB26: 59.47 | BC26: 57.88 | BD26: 58.71 | BE26: 60.49 | BF26: 61.93 | BG26: 63.39 | BH26: 62.86 | BI26: 58.27 | BJ26: 56.39 | BK26: 59.61 | BL26: 54.73 | BM26: 52.53 | BN26: 53.17 | BO26: 54.91 | BP26: 56.89 | BQ26: 57.43 | BR26: 58.58 | BS26: 60.27 | BT26: 56.44 | BU26: 55.17 | BV26: 52.31 | BW26: 53.27 | BX26: 55.82 | BY26: 53.61 | BZ26: 51.98 | CA26: 44.02 | CB26: 49.3 | CC26: 54.6 | CD26: 55.69 | CE26: 56.58 | CF26: 57.18 | CG26: 55.9 | CH26: 56.82 | CI26: 58.75 | CJ26: 59.76 | CK26: 55.52 | CL26: 57.88 | CM26: 54.85 | CN26: 56.25 | CO26: 55.13 | CP26: 58 | CQ26: 54.45 | CR26: 58.57 | CS26: 57.22 | CT26: 58.23 | CU26: 59.38 | CV26: 54.29 | CW26: 56.65 | CX26: 54.07 | CY26: 60.39
A27: Tasa de actividad | B27: España | C27: Ambos sexos | D27: Total | E27: EPA388079 | F27: 54.06 | G27: 54.48 | H27: 54.92 | I27: 54.95 | J27: 55.28 | K27: 55.65 | L27: 56.15 | M27: 56.25 | N27: 56.24 | O27: 56.55 | P27: 56.93 | Q27: 57.12 | R27: 57.38 | S27: 57.86 | T27: 57.86 | U27: 58.08 | V27: 58.3 | W27: 58.63 | X27: 58.74 | Y27: 58.88 | Z27: 58.9 | AA27: 59.23 | AB27: 59.5 | AC27: 59.47 | AD27: 59.67 | AE27: 60.07 | AF27: 60.23 | AG27: 60.35 | AH27: 60.39 | AI27: 60.3 | AJ27: 60.05 | AK27: 59.99 | AL27: 60.09 | AM27: 60.41 | AN27: 60.37 | AO27: 60.25 | AP27: 60.16 | AQ27: 60.44 | AR27: 60.44 | AS27: 60.29 | AT27: 60.31 | AU27: 60.5 | AV27: 60.55 | AW27: 60.23 | AX27: 60.18 | AY27: 60 | AZ27: 60.04 | BA27: 59.86 | BB27: 59.46 | BC27: 59.63 | BD27: 59.53 | BE27: 59.77 | BF27: 59.45 | BG27: 59.79 | BH27: 59.5 | BI27: 59.43 | BJ27: 59.29 | BK27: 59.41 | BL27: 59.28 | BM27: 58.95 | BN27: 58.78 | BO27: 58.84 | BP27: 58.92 | BQ27: 58.8 | BR27: 58.46 | BS27: 58.8 | BT27: 58.73 | BU27: 58.61 | BV27: 58.35 | BW27: 58.74 | BX27: 58.72 | BY27: 58.74 | BZ27: 58.18 | CA27: 55.54 | CB27: 57.83 | CC27: 58.19 | CD27: 57.56 | CE27: 58.42 | CF27: 59.01 | CG27: 58.53 | CH27: 58.36 | CI27: 58.6 | CJ27: 58.76 | CK27: 58.4 | CL27: 58.44 | CM27: 58.85 | CN27: 59.29 | CO27: 58.83 | CP27: 58.63 | CQ27: 58.9 | CR27: 59.04 | CS27: 58.49 | CT27: 58.57 | CU27: 59.03 | CV27: 59.3 | CW27: 58.94 | CX27: 58.86 | CY27: 59.29
A28: Tasa de actividad | B28: España | C28: Ambos sexos | D28: Menores de 25 | E28: EPA436340 | F28: 47.29 | G28: 47.46 | H28: 49.48 | I28: 48.02 | J28: 47.64 | K28: 48.43 | L28: 50.6 | M28: 48.77 | N28: 48.38 | O28: 48.98 | P28: 51.23 | Q28: 49.07 | R28: 50.91 | S28: 52.3 | T28: 54.52 | U28: 51.86 | V28: 51.38 | W28: 52.67 | X28: 54.68 | Y28: 52.11 | Z28: 50.87 | AA28: 52.37 | AB28: 55.25 | AC28: 51.52 | AD28: 50.89 | AE28: 52.2 | AF28: 55.17 | AG28: 51.51 | AH28: 49.95 | AI28: 49.67 | AJ28: 51.15 | AK28: 47.05 | AL28: 46.3 | AM28: 47.3 | AN28: 48.54 | AO28: 45.34 | AP28: 44.37 | AQ28: 45.06 | AR28: 47.23 | AS28: 43.14 | AT28: 42.36 | AU28: 43.2 | AV28: 44.96 | AW28: 41.3 | AX28: 41.52 | AY28: 41.35 | AZ28: 43.36 | BA28: 40.55 | BB28: 39.18 | BC28: 39.11 | BD28: 41.06 | BE28: 39.02 | BF28: 37.9 | BG28: 38.86 | BH28: 41.1 | BI28: 37.19 | BJ28: 36.07 | BK28: 37.3 | BL28: 38.64 | BM28: 35.77 | BN28: 35.47 | BO28: 36.8 | BP28: 40.04 | BQ28: 36.95 | BR28: 35.02 | BS28: 37.04 | BT28: 39.21 | BU28: 36.51 | BV28: 35.19 | BW28: 36.72 | BX28: 39.56 | BY28: 35.94 | BZ28: 34.66 | CA28: 30.14 | CB28: 35.88 | CC28: 33.14 | CD28: 32.59 | CE28: 35.76 | CF28: 38.73 | CG28: 33.92 | CH28: 34.49 | CI28: 37.23 | CJ28: 38.94 | CK28: 35.02 | CL28: 34.72 | CM28: 36.91 | CN28: 40.57 | CO28: 36.29 | CP28: 35.95 | CQ28: 37.34 | CR28: 40.85 | CS28: 36.28 | CT28: 35.23 | CU28: 37.84 | CV28: 40.99 | CW28: 36.42 | CX28: 36.54 | CY28: 39.07
A29: Tasa de actividad | B29: España | C29: Ambos sexos | D29: 25 y más | E29: EPA436341 | F29: 55.26 | G29: 55.7 | H29: 55.86 | I29: 56.14 | J29: 56.57 | K29: 56.86 | L29: 57.06 | M29: 57.47 | N29: 57.5 | O29: 57.75 | P29: 57.83 | Q29: 58.37 | R29: 58.37 | S29: 58.71 | T29: 58.36 | U29: 59 | V29: 59.32 | W29: 59.5 | X29: 59.33 | Y29: 59.85 | Z29: 60.05 | AA29: 60.2 | AB29: 60.1 | AC29: 60.58 | AD29: 60.89 | AE29: 61.16 | AF29: 60.92 | AG29: 61.55 | AH29: 61.79 | AI29: 61.72 | AJ29: 61.22 | AK29: 61.69 | AL29: 61.89 | AM29: 62.1 | AN29: 61.88 | AO29: 62.14 | AP29: 62.15 | AQ29: 62.36 | AR29: 62.08 | AS29: 62.4 | AT29: 62.51 | AU29: 62.62 | AV29: 62.44 | AW29: 62.52 | AX29: 62.42 | AY29: 62.23 | AZ29: 62.02 | BA29: 62.14 | BB29: 61.85 | BC29: 62.04 | BD29: 61.69 | BE29: 62.2 | BF29: 61.96 | BG29: 62.22 | BH29: 61.64 | BI29: 62.01 | BJ29: 61.98 | BK29: 61.97 | BL29: 61.67 | BM29: 61.63 | BN29: 61.48 | BO29: 61.39 | BP29: 61.11 | BQ29: 61.34 | BR29: 61.19 | BS29: 61.34 | BT29: 61.02 | BU29: 61.21 | BV29: 61.09 | BW29: 61.36 | BX29: 61 | BY29: 61.47 | BZ29: 61.02 | CA29: 58.62 | CB29: 60.5 | CC29: 61.24 | CD29: 60.55 | CE29: 61.15 | CF29: 61.46 | CG29: 61.52 | CH29: 61.26 | CI29: 61.22 | CJ29: 61.21 | CK29: 61.31 | CL29: 61.4 | CM29: 61.59 | CN29: 61.63 | CO29: 61.7 | CP29: 61.51 | CQ29: 61.68 | CR29: 61.39 | CS29: 61.37 | CT29: 61.61 | CU29: 61.8 | CV29: 61.67 | CW29: 61.87 | CX29: 61.78 | CY29: 61.95
A30: Tasa de actividad | B30: España | C30: Ambos sexos | D30: 16 a 19 | E30: EPA388081 | F30: 25.4 | G30: 24.81 | H30: 27.34 | I30: 25.33 | J30: 24.32 | K30: 25.57 | L30: 27.28 | M30: 25.19 | N30: 24.2 | O30: 24.67 | P30: 27.93 | Q30: 25.4 | R30: 26.99 | S30: 29.46 | T30: 31.76 | U30: 27.82 | V30: 27.01 | W30: 29.31 | X30: 32.4 | Y30: 28.47 | Z30: 27.53 | AA30: 30.45 | AB30: 33.27 | AC30: 28.27 | AD30: 28.1 | AE30: 29.37 | AF30: 32.3 | AG30: 26.71 | AH30: 25.65 | AI30: 25.61 | AJ30: 26.62 | AK30: 20.89 | AL30: 21.45 | AM30: 22.88 | AN30: 22.59 | AO30: 19.06 | AP30: 18.44 | AQ30: 19.71 | AR30: 22.1 | AS30: 16.92 | AT30: 16.99 | AU30: 18.36 | AV30: 19.28 | AW30: 15.11 | AX30: 15.8 | AY30: 16.27 | AZ30: 18.79 | BA30: 15.55 | BB30: 14.14 | BC30: 14.23 | BD30: 16.09 | BE30: 14.6 | BF30: 14.14 | BG30: 14.88 | BH30: 16.94 | BI30: 13.58 | BJ30: 12.91 | BK30: 13.36 | BL30: 15.3 | BM30: 13.34 | BN30: 12.97 | BO30: 14.2 | BP30: 16.72 | BQ30: 14.42 | BR30: 13.11 | BS30: 14.9 | BT30: 16.59 | BU30: 13.91 | BV30: 13.5 | BW30: 14.91 | BX30: 16.4 | BY30: 13.78 | BZ30: 12.91 | CA30: 10.36 | CB30: 13.96 | CC30: 11.29 | CD30: 10.45 | CE30: 13.69 | CF30: 16.95 | CG30: 12.42 | CH30: 13.16 | CI30: 15.33 | CJ30: 16.4 | CK30: 13.14 | CL30: 12.62 | CM30: 14.31 | CN30: 17.72 | CO30: 13.28 | CP30: 13.65 | CQ30: 15.68 | CR30: 18.19 | CS30: 13.95 | CT30: 12.08 | CU30: 14.83 | CV30: 17.5 | CW30: 11.81 | CX30: 13.26 | CY30: 16.3
A31: Tasa de actividad | B31: España | C31: Ambos sexos | D31: 20 a 24 | E31: EPA388082 | AG31: 68.32 | AH31: 66.53 | AI31: 66.17 | AJ31: 68.08 | AK31: 65.2 | AL31: 63.62 | AM31: 64.38 | AN31: 66.78 | AO31: 63.84 | AP31: 62.67 | AQ31: 63.03 | AR31: 65.1 | AS31: 61.82 | AT31: 60.45 | AU31: 60.95 | AV31: 63.32 | AW31: 60 | AX31: 59.92 | AY31: 59.38 | AZ31: 61.11 | BA31: 58.65 | BB31: 57.42 | BC31: 57.29 | BD31: 59.44 | BE31: 57.09 | BF31: 55.58 | BG31: 56.84 | BH31: 59.32 | BI31: 55.15 | BJ31: 53.83 | BK31: 55.8 | BL31: 56.79 | BM31: 53.34 | BN31: 53.21 | BO31: 54.74 | BP31: 58.65 | BQ31: 54.98 | BR31: 52.63 | BS31: 54.87 | BT31: 57.5 | BU31: 54.86 | BV31: 52.85 | BW31: 54.48 | BX31: 58.44 | BY31: 54.01 | BZ31: 52.37 | CA31: 46.25 | CB31: 53.72 | CC31: 50.94 | CD31: 50.34 | CE31: 53.66 | CF31: 56.44 | CG31: 51.35 | CH31: 51.74 | CI31: 54.98 | CJ31: 57.33 | CK31: 52.9 | CL31: 52.58 | CM31: 54.81 | CN31: 58.73 | CO31: 54.85 | CP31: 53.78 | CQ31: 54.94 | CR31: 59.22 | CS31: 54.34 | CT31: 53.79 | CU31: 56.27 | CV31: 59.44 | CW31: 55.62 | CX31: 54.76 | CY31: 56.87

Sheet EPA_Tasas_Anual_Calc
A1: indicador | B1: territorio | C1: sexo | D1: edad | E1: cod_INE | F1: 2002 | G1: 2003 | H1: 2004 | I1: 2005 | J1: 2006 | K1: 2007 | L1: 2008 | M1: 2009 | N1: 2010 | O1: 2011 | P1: 2012 | Q1: 2013 | R1: 2014 | S1: 2015 | T1: 2016 | U1: 2017 | V1: 2018 | W1: 2019 | X1: 2020 | Y1: 2021 | Z1: 2022 | AA1: 2023 | AB1: 2024 | AC1: 2025
A2: Tasa de paro | B2: Comunidad de Madrid | C2: Ambos sexos | D2: Total | E2: EPA452536 | F2: =IF(COUNT(EPA_Tasas_Trim!F2:I2)=4,AVERAGE(EPA_Tasas_Trim!F2:I2),"") -> 7.2975 | G2: =IF(COUNT(EPA_Tasas_Trim!J2:M2)=4,AVERAGE(EPA_Tasas_Trim!J2:M2),"") -> 7.3675 | H2: =IF(COUNT(EPA_Tasas_Trim!N2:Q2)=4,AVERAGE(EPA_Tasas_Trim!N2:Q2),"") -> 6.7375 | I2: =IF(COUNT(EPA_Tasas_Trim!R2:U2)=4,AVERAGE(EPA_Tasas_Trim!R2:U2),"") -> 6.835 | J2: =IF(COUNT(EPA_Tasas_Trim!V2:Y2)=4,AVERAGE(EPA_Tasas_Trim!V2:Y2),"") -> 6.3025 | K2: =IF(COUNT(EPA_Tasas_Trim!Z2:AC2)=4,AVERAGE(EPA_Tasas_Trim!Z2:AC2),"") -> 6.2425 | L2: =IF(COUNT(EPA_Tasas_Trim!AD2:AG2)=4,AVERAGE(EPA_Tasas_Trim!AD2:AG2),"") -> 8.6 | M2: =IF(COUNT(EPA_Tasas_Trim!AH2:AK2)=4,AVERAGE(EPA_Tasas_Trim!AH2:AK2),"") -> 13.855 | N2: =IF(COUNT(EPA_Tasas_Trim!AL2:AO2)=4,AVERAGE(EPA_Tasas_Trim!AL2:AO2),"") -> 15.8425 | O2: =IF(COUNT(EPA_Tasas_Trim!AP2:AS2)=4,AVERAGE(EPA_Tasas_Trim!AP2:AS2),"") -> 16.3375 | P2: =IF(COUNT(EPA_Tasas_Trim!AT2:AW2)=4,AVERAGE(EPA_Tasas_Trim!AT2:AW2),"") -> 18.53 | Q2: =IF(COUNT(EPA_Tasas_Trim!AX2:BA2)=4,AVERAGE(EPA_Tasas_Trim!AX2:BA2),"") -> 19.7625 | R2: =IF(COUNT(EPA_Tasas_Trim!BB2:BE2)=4,AVERAGE(EPA_Tasas_Trim!BB2:BE2),"") -> 18.7475 | S2: =IF(COUNT(EPA_Tasas_Trim!BF2:BI2)=4,AVERAGE(EPA_Tasas_Trim!BF2:BI2),"") -> 17.0575 | T2: =IF(COUNT(EPA_Tasas_Trim!BJ2:BM2)=4,AVERAGE(EPA_Tasas_Trim!BJ2:BM2),"") -> 15.7125 | U2: =IF(COUNT(EPA_Tasas_Trim!BN2:BQ2)=4,AVERAGE(EPA_Tasas_Trim!BN2:BQ2),"") -> 13.3425 | V2: =IF(COUNT(EPA_Tasas_Trim!BR2:BU2)=4,AVERAGE(EPA_Tasas_Trim!BR2:BU2),"") -> 12.22 | W2: =IF(COUNT(EPA_Tasas_Trim!BV2:BY2)=4,AVERAGE(EPA_Tasas_Trim!BV2:BY2),"") -> 10.6225 | X2: =IF(COUNT(EPA_Tasas_Trim!BZ2:CC2)=4,AVERAGE(EPA_Tasas_Trim!BZ2:CC2),"") -> 12.4975 | Y2: =IF(COUNT(EPA_Tasas_Trim!CD2:CG2)=4,AVERAGE(EPA_Tasas_Trim!CD2:CG2),"") -> 11.6875 | Z2: =IF(COUNT(EPA_Tasas_Trim!CH2:CK2)=4,AVERAGE(EPA_Tasas_Trim!CH2:CK2),"") -> 11.215 | AA2: =IF(COUNT(EPA_Tasas_Trim!CL2:CO2)=4,AVERAGE(EPA_Tasas_Trim!CL2:CO2),"") -> 9.955 | AB2: =IF(COUNT(EPA_Tasas_Trim!CP2:CS2)=4,AVERAGE(EPA_Tasas_Trim!CP2:CS2),"") -> 8.975 | AC2: =IF(COUNT(EPA_Tasas_Trim!CT2:CW2)=4,AVERAGE(EPA_Tasas_Trim!CT2:CW2),"") -> 7.9675
A3: Tasa de paro | B3: Comunidad de Madrid | C3: Ambos sexos | D3: Menores de 25 | E3: EPA452538 | F3: =IF(COUNT(EPA_Tasas_Trim!F3:I3)=4,AVERAGE(EPA_Tasas_Trim!F3:I3),"") -> 14.95 | G3: =IF(COUNT(EPA_Tasas_Trim!J3:M3)=4,AVERAGE(EPA_Tasas_Trim!J3:M3),"") -> 16.7675 | H3: =IF(COUNT(EPA_Tasas_Trim!N3:Q3)=4,AVERAGE(EPA_Tasas_Trim!N3:Q3),"") -> 15.7075 | I3: =IF(COUNT(EPA_Tasas_Trim!R3:U3)=4,AVERAGE(EPA_Tasas_Trim!R3:U3),"") -> 16.6975 | J3: =IF(COUNT(EPA_Tasas_Trim!V3:Y3)=4,AVERAGE(EPA_Tasas_Trim!V3:Y3),"") -> 14.6425 | K3: =IF(COUNT(EPA_Tasas_Trim!Z3:AC3)=4,AVERAGE(EPA_Tasas_Trim!Z3:AC3),"") -> 16.7475 | L3: =IF(COUNT(EPA_Tasas_Trim!AD3:AG3)=4,AVERAGE(EPA_Tasas_Trim!AD3:AG3),"") -> 20.77 | M3: =IF(COUNT(EPA_Tasas_Trim!AH3:AK3)=4,AVERAGE(EPA_Tasas_Trim!AH3:AK3),"") -> 34.2 | N3: =IF(COUNT(EPA_Tasas_Trim!AL3:AO3)=4,AVERAGE(EPA_Tasas_Trim!AL3:AO3),"") -> 37.115 | O3: =IF(COUNT(EPA_Tasas_Trim!AP3:AS3)=4,AVERAGE(EPA_Tasas_Trim!AP3:AS3),"") -> 40.855 | P3: =IF(COUNT(EPA_Tasas_Trim!AT3:AW3)=4,AVERAGE(EPA_Tasas_Trim!AT3:AW3),"") -> 48.055 | Q3: =IF(COUNT(EPA_Tasas_Trim!AX3:BA3)=4,AVERAGE(EPA_Tasas_Trim!AX3:BA3),"") -> 48.81 | R3: =IF(COUNT(EPA_Tasas_Trim!BB3:BE3)=4,AVERAGE(EPA_Tasas_Trim!BB3:BE3),"") -> 48.99 | S3: =IF(COUNT(EPA_Tasas_Trim!BF3:BI3)=4,AVERAGE(EPA_Tasas_Trim!BF3:BI3),"") -> 44.1625 | T3: =IF(COUNT(EPA_Tasas_Trim!BJ3:BM3)=4,AVERAGE(EPA_Tasas_Trim!BJ3:BM3),"") -> 40.5175 | U3: =IF(COUNT(EPA_Tasas_Trim!BN3:BQ3)=4,AVERAGE(EPA_Tasas_Trim!BN3:BQ3),"") -> 34.69 | V3: =IF(COUNT(EPA_Tasas_Trim!BR3:BU3)=4,AVERAGE(EPA_Tasas_Trim!BR3:BU3),"") -> 27.4575 | W3: =IF(COUNT(EPA_Tasas_Trim!BV3:BY3)=4,AVERAGE(EPA_Tasas_Trim!BV3:BY3),"") -> 29.09 | X3: =IF(COUNT(EPA_Tasas_Trim!BZ3:CC3)=4,AVERAGE(EPA_Tasas_Trim!BZ3:CC3),"") -> 31.7825 | Y3: =IF(COUNT(EPA_Tasas_Trim!CD3:CG3)=4,AVERAGE(EPA_Tasas_Trim!CD3:CG3),"") -> 29.4775 | Z3: =IF(COUNT(EPA_Tasas_Trim!CH3:CK3)=4,AVERAGE(EPA_Tasas_Trim!CH3:CK3),"") -> 27.7675 | AA3: =IF(COUNT(EPA_Tasas_Trim!CL3:CO3)=4,AVERAGE(EPA_Tasas_Trim!CL3:CO3),"") -> 27.3475 | AB3: =IF(COUNT(EPA_Tasas_Trim!CP3:CS3)=4,AVERAGE(EPA_Tasas_Trim!CP3:CS3),"") -> 20.3175 | AC3: =IF(COUNT(EPA_Tasas_Trim!CT3:CW3)=4,AVERAGE(EPA_Tasas_Trim!CT3:CW3),"") -> 19.335
A4: Tasa de paro | B4: Comunidad de Madrid | C4: Ambos sexos | D4: 25 y más | E4: EPA452539 | F4: =IF(COUNT(EPA_Tasas_Trim!F4:I4)=4,AVERAGE(EPA_Tasas_Trim!F4:I4),"") -> 6.33 | G4: =IF(COUNT(EPA_Tasas_Trim!J4:M4)=4,AVERAGE(EPA_Tasas_Trim!J4:M4),"") -> 6.2225 | H4: =IF(COUNT(EPA_Tasas_Trim!N4:Q4)=4,AVERAGE(EPA_Tasas_Trim!N4:Q4),"") -> 5.7275 | I4: =IF(COUNT(EPA_Tasas_Trim!R4:U4)=4,AVERAGE(EPA_Tasas_Trim!R4:U4),"") -> 5.6275 | J4: =IF(COUNT(EPA_Tasas_Trim!V4:Y4)=4,AVERAGE(EPA_Tasas_Trim!V4:Y4),"") -> 5.3075 | K4: =IF(COUNT(EPA_Tasas_Trim!Z4:AC4)=4,AVERAGE(EPA_Tasas_Trim!Z4:AC4),"") -> 5.0425 | L4: =IF(COUNT(EPA_Tasas_Trim!AD4:AG4)=4,AVERAGE(EPA_Tasas_Trim!AD4:AG4),"") -> 7.3 | M4: =IF(COUNT(EPA_Tasas_Trim!AH4:AK4)=4,AVERAGE(EPA_Tasas_Trim!AH4:AK4),"") -> 11.9125 | N4: =IF(COUNT(EPA_Tasas_Trim!AL4:AO4)=4,AVERAGE(EPA_Tasas_Trim!AL4:AO4),"") -> 14 | O4: =IF(COUNT(EPA_Tasas_Trim!AP4:AS4)=4,AVERAGE(EPA_Tasas_Trim!AP4:AS4),"") -> 14.4175 | P4: =IF(COUNT(EPA_Tasas_Trim!AT4:AW4)=4,AVERAGE(EPA_Tasas_Trim!AT4:AW4),"") -> 16.4 | Q4: =IF(COUNT(EPA_Tasas_Trim!AX4:BA4)=4,AVERAGE(EPA_Tasas_Trim!AX4:BA4),"") -> 17.7075 | R4: =IF(COUNT(EPA_Tasas_Trim!BB4:BE4)=4,AVERAGE(EPA_Tasas_Trim!BB4:BE4),"") -> 16.6675 | S4: =IF(COUNT(EPA_Tasas_Trim!BF4:BI4)=4,AVERAGE(EPA_Tasas_Trim!BF4:BI4),"") -> 15.175 | T4: =IF(COUNT(EPA_Tasas_Trim!BJ4:BM4)=4,AVERAGE(EPA_Tasas_Trim!BJ4:BM4),"") -> 14.13 | U4: =IF(COUNT(EPA_Tasas_Trim!BN4:BQ4)=4,AVERAGE(EPA_Tasas_Trim!BN4:BQ4),"") -> 12.0025 | V4: =IF(COUNT(EPA_Tasas_Trim!BR4:BU4)=4,AVERAGE(EPA_Tasas_Trim!BR4:BU4),"") -> 11.205 | W4: =IF(COUNT(EPA_Tasas_Trim!BV4:BY4)=4,AVERAGE(EPA_Tasas_Trim!BV4:BY4),"") -> 9.44 | X4: =IF(COUNT(EPA_Tasas_Trim!BZ4:CC4)=4,AVERAGE(EPA_Tasas_Trim!BZ4:CC4),"") -> 11.3225 | Y4: =IF(COUNT(EPA_Tasas_Trim!CD4:CG4)=4,AVERAGE(EPA_Tasas_Trim!CD4:CG4),"") -> 10.4525 | Z4: =IF(COUNT(EPA_Tasas_Trim!CH4:CK4)=4,AVERAGE(EPA_Tasas_Trim!CH4:CK4),"") -> 10.015 | AA4: =IF(COUNT(EPA_Tasas_Trim!CL4:CO4)=4,AVERAGE(EPA_Tasas_Trim!CL4:CO4),"") -> 8.71 | AB4: =IF(COUNT(EPA_Tasas_Trim!CP4:CS4)=4,AVERAGE(EPA_Tasas_Trim!CP4:CS4),"") -> 8.1175 | AC4: =IF(COUNT(EPA_Tasas_Trim!CT4:CW4)=4,AVERAGE(EPA_Tasas_Trim!CT4:CW4),"") -> 7.105
A5: Tasa de paro | B5: Comunidad de Madrid | C5: Ambos sexos | D5: 16 a 19 | E5: EPA452540 | F5: =IF(COUNT(EPA_Tasas_Trim!F5:I5)=4,AVERAGE(EPA_Tasas_Trim!F5:I5),"") -> 22.49 | G5: =IF(COUNT(EPA_Tasas_Trim!J5:M5)=4,AVERAGE(EPA_Tasas_Trim!J5:M5),"") -> 23.7175 | H5: =IF(COUNT(EPA_Tasas_Trim!N5:Q5)=4,AVERAGE(EPA_Tasas_Trim!N5:Q5),"") -> 25.9475 | I5: =IF(COUNT(EPA_Tasas_Trim!R5:U5)=4,AVERAGE(EPA_Tasas_Trim!R5:U5),"") -> 25.565 | J5: =IF(COUNT(EPA_Tasas_Trim!V5:Y5)=4,AVERAGE(EPA_Tasas_Trim!V5:Y5),"") -> 29.5425 | K5: =IF(COUNT(EPA_Tasas_Trim!Z5:AC5)=4,AVERAGE(EPA_Tasas_Trim!Z5:AC5),"") -> 28.4025 | L5: =IF(COUNT(EPA_Tasas_Trim!AD5:AG5)=4,AVERAGE(EPA_Tasas_Trim!AD5:AG5),"") -> 35.5025 | M5: =IF(COUNT(EPA_Tasas_Trim!AH5:AK5)=4,AVERAGE(EPA_Tasas_Trim!AH5:AK5),"") -> 52.43 | N5: =IF(COUNT(EPA_Tasas_Trim!AL5:AO5)=4,AVERAGE(EPA_Tasas_Trim!AL5:AO5),"") -> 58.675 | O5: =IF(COUNT(EPA_Tasas_Trim!AP5:AS5)=4,AVERAGE(EPA_Tasas_Trim!AP5:AS5),"") -> 63.1775 | P5: =IF(COUNT(EPA_Tasas_Trim!AT5:AW5)=4,AVERAGE(EPA_Tasas_Trim!AT5:AW5),"") -> 77.2225 | Q5: =IF(COUNT(EPA_Tasas_Trim!AX5:BA5)=4,AVERAGE(EPA_Tasas_Trim!AX5:BA5),"") -> 73.455 | R5: =IF(COUNT(EPA_Tasas_Trim!BB5:BE5)=4,AVERAGE(EPA_Tasas_Trim!BB5:BE5),"") -> 68.705 | S5: =IF(COUNT(EPA_Tasas_Trim!BF5:BI5)=4,AVERAGE(EPA_Tasas_Trim!BF5:BI5),"") -> 68.2525 | T5: =IF(COUNT(EPA_Tasas_Trim!BJ5:BM5)=4,AVERAGE(EPA_Tasas_Trim!BJ5:BM5),"") -> 58.705 | U5: =IF(COUNT(EPA_Tasas_Trim!BN5:BQ5)=4,AVERAGE(EPA_Tasas_Trim!BN5:BQ5),"") -> 60.445 | V5: =IF(COUNT(EPA_Tasas_Trim!BR5:BU5)=4,AVERAGE(EPA_Tasas_Trim!BR5:BU5),"") -> 51.915 | W5: =IF(COUNT(EPA_Tasas_Trim!BV5:BY5)=4,AVERAGE(EPA_Tasas_Trim!BV5:BY5),"") -> 46.3025 | X5: =IF(COUNT(EPA_Tasas_Trim!BZ5:CC5)=4,AVERAGE(EPA_Tasas_Trim!BZ5:CC5),"") -> 47.3125 | Y5: =IF(COUNT(EPA_Tasas_Trim!CD5:CG5)=4,AVERAGE(EPA_Tasas_Trim!CD5:CG5),"") -> 52.9225 | Z5: =IF(COUNT(EPA_Tasas_Trim!CH5:CK5)=4,AVERAGE(EPA_Tasas_Trim!CH5:CK5),"") -> 48.525 | AA5: =IF(COUNT(EPA_Tasas_Trim!CL5:CO5)=4,AVERAGE(EPA_Tasas_Trim!CL5:CO5),"") -> 42.8225 | AB5: =IF(COUNT(EPA_Tasas_Trim!CP5:CS5)=4,AVERAGE(EPA_Tasas_Trim!CP5:CS5),"") -> 32.72 | AC5: =IF(COUNT(EPA_Tasas_Trim!CT5:CW5)=4,AVERAGE(EPA_Tasas_Trim!CT5:CW5),"") -> 30.62
A6: Tasa de paro | B6: Comunidad de Madrid | C6: Ambos sexos | D6: 20 a 24 | E6: EPA452541 | F6: =IF(COUNT(EPA_Tasas_Trim!F6:I6)=4,AVERAGE(EPA_Tasas_Trim!F6:I6),"") | G6: =IF(COUNT(EPA_Tasas_Trim!J6:M6)=4,AVERAGE(EPA_Tasas_Trim!J6:M6),"") | H6: =IF(COUNT(EPA_Tasas_Trim!N6:Q6)=4,AVERAGE(EPA_Tasas_Trim!N6:Q6),"") | I6: =IF(COUNT(EPA_Tasas_Trim!R6:U6)=4,AVERAGE(EPA_Tasas_Trim!R6:U6),"") | J6: =IF(COUNT(EPA_Tasas_Trim!V6:Y6)=4,AVERAGE(EPA_Tasas_Trim!V6:Y6),"") | K6: =IF(COUNT(EPA_Tasas_Trim!Z6:AC6)=4,AVERAGE(EPA_Tasas_Trim!Z6:AC6),"") | L6: =IF(COUNT(EPA_Tasas_Trim!AD6:AG6)=4,AVERAGE(EPA_Tasas_Trim!AD6:AG6),"") | M6: =IF(COUNT(EPA_Tasas_Trim!AH6:AK6)=4,AVERAGE(EPA_Tasas_Trim!AH6:AK6),"") -> 30.09 | N6: =IF(COUNT(EPA_Tasas_Trim!AL6:AO6)=4,AVERAGE(EPA_Tasas_Trim!AL6:AO6),"") -> 32.86 | O6: =IF(COUNT(EPA_Tasas_Trim!AP6:AS6)=4,AVERAGE(EPA_Tasas_Trim!AP6:AS6),"") -> 36.4925 | P6: =IF(COUNT(EPA_Tasas_Trim!AT6:AW6)=4,AVERAGE(EPA_Tasas_Trim!AT6:AW6),"") -> 42.6425 | Q6: =IF(COUNT(EPA_Tasas_Trim!AX6:BA6)=4,AVERAGE(EPA_Tasas_Trim!AX6:BA6),"") -> 44.645 | R6: =IF(COUNT(EPA_Tasas_Trim!BB6:BE6)=4,AVERAGE(EPA_Tasas_Trim!BB6:BE6),"") -> 45.455 | S6: =IF(COUNT(EPA_Tasas_Trim!BF6:BI6)=4,AVERAGE(EPA_Tasas_Trim!BF6:BI6),"") -> 40.015 | T6: =IF(COUNT(EPA_Tasas_Trim!BJ6:BM6)=4,AVERAGE(EPA_Tasas_Trim!BJ6:BM6),"") -> 37.1325 | U6: =IF(COUNT(EPA_Tasas_Trim!BN6:BQ6)=4,AVERAGE(EPA_Tasas_Trim!BN6:BQ6),"") -> 30.6075 | V6: =IF(COUNT(EPA_Tasas_Trim!BR6:BU6)=4,AVERAGE(EPA_Tasas_Trim!BR6:BU6),"") -> 23.63 | W6: =IF(COUNT(EPA_Tasas_Trim!BV6:BY6)=4,AVERAGE(EPA_Tasas_Trim!BV6:BY6),"") -> 25.9625 | X6: =IF(COUNT(EPA_Tasas_Trim!BZ6:CC6)=4,AVERAGE(EPA_Tasas_Trim!BZ6:CC6),"") -> 29.145 | Y6: =IF(COUNT(EPA_Tasas_Trim!CD6:CG6)=4,AVERAGE(EPA_Tasas_Trim!CD6:CG6),"") -> 25.04 | Z6: =IF(COUNT(EPA_Tasas_Trim!CH6:CK6)=4,AVERAGE(EPA_Tasas_Trim!CH6:CK6),"") -> 24.0225 | AA6: =IF(COUNT(EPA_Tasas_Trim!CL6:CO6)=4,AVERAGE(EPA_Tasas_Trim!CL6:CO6),"") -> 24.91 | AB6: =IF(COUNT(EPA_Tasas_Trim!CP6:CS6)=4,AVERAGE(EPA_Tasas_Trim!CP6:CS6),"") -> 18.3775 | AC6: =IF(COUNT(EPA_Tasas_Trim!CT6:CW6)=4,AVERAGE(EPA_Tasas_Trim!CT6:CW6),"") -> 17.555
