Workbook

Sheet LEEME
A1: Base de conocimiento — Salarios (España y Comunidad de Madrid)
A3: Descripción
A4: Salarios brutos anuales con la distribución más completa que ofrecen las fuentes públicas gratuitas: media, mediana, percentiles 10 y 90, cuartiles, moda (2022–2024), desigualdad (Gini, razones entre deciles), edad, sexo, comunidad autónoma, sector, ocupación, tipo de contrato y proporción de trabajadores por múltiplos del SMI. Se añade la distribución por centiles de la Agencia Tributaria (número de personas por tramo y salario medio por sexo) y el histórico del SMI.
A5: Fecha de consulta: 2026-10-21. La desviación típica NO la publica ningún organismo (solo con microdatos): la hoja Estimacion_DesvTipica ofrece una aproximación lognormal marcada en amarillo.
A7: Índice de hojas
A8: Hoja | B8: Contenido | C8: Cobertura
A9: Resumen_Salarios | B9: Cuadro 2024: media, mediana, percentiles, moda, ratios, brecha de género, DT estimada, SMI. | C9: 2024
A10: EES_Distribucion | B10: Media, P10, cuartiles, mediana, P90 por sexo, España y Madrid. | C10: 2008–2024
A11: EES_Moda | B11: Salario modal y detalle (nota de prensa INE). | C11: 2022–2024, España
A12: Estimacion_DesvTipica | B12: Desviación típica aproximada por tres métodos lognormales, serie anual. | C12: 2008–2024, España y Madrid
A13: EES_Edad | B13: Salario medio por tramo de edad y sexo (España 11 tramos; Madrid 5 tramos). | C13: 2008–2024
A14: EES_CCAA_2024 | B14: Distribución del salario por CCAA con ratios y ranking (fórmulas). | C14: 2024
A15: EES_Sector_Ocup_Contrato | B15: Salario medio por sector CNAE-09, ocupación CNO-11 y tipo de contrato (España). | C15: 2008–2024
A16: EES_Desigualdad_SMI | B16: Gini, tasa de salario bajo, razones de deciles y % de trabajadores por múltiplos del SMI. | C16: 2008–2024, España
A17: AEAT_Centiles_2024 | B17: Número de asalariados y salario medio por centil/decil y sexo (Agencia Tributaria). | C17: 2024, España
A18: SMI_Historico | B18: Salario mínimo interprofesional y su relación con el salario mediano. | C18: 2004–2026
A19: FUENTES | B19: Origen de cada bloque.
A21: Notas, límites y huecos conocidos
A22: • La EES mide el salario bruto anual por trabajador asalariado (incluye pagas extra y pagos irregulares), sin la sección A (agricultura) del CNAE. No equivale a ganancia por hora ni a coste laboral.
A23: • Fiabilidad: en las tablas del INE los valores negativos indican muestra de 100 a 500 observaciones (alta variabilidad) y las celdas vacías menos de 100. En este libro los negativos se guardan en positivo con fondo naranja.
A24: • Percentiles disponibles en la EES: P10, cuartiles, mediana y P90. Percentiles más extremos (P1, P5, P95, P99) solo existen en la hoja AEAT_Centiles_2024, que cubre otra población (asalariados con año completo y ≥ SMI) y no es directamente comparable con la EES.
A25: • Moda: el INE solo la menciona en las notas de prensa; se han recogido 2022, 2023 y 2024 (España). No hay moda para Madrid ni series anteriores.
A26: • Ruptura metodológica en los tramos de SMI (hoja EES_Desigualdad_SMI) entre 2018 y 2019: no comparar tasas de ambos periodos sin cautela.
A27: • Madrid solo tiene detalle completo en EES_Distribucion (por sexo) y EES_Edad (5 tramos). Sin sector/ocupación/contrato para Madrid ni percentiles AEAT de Madrid (hueco pendiente).
A28: • Huecos pendientes: coste laboral trimestral (ETCL, tabla 6061), salarios pactados en convenio, salarios por hora, decilas de salario de la EPA por CCAA (tabla 66241), tablas AEAT por edad/CCAA/provincia/sector, años anteriores a 2008.
A29: • SMI: 2018–2026 verificado contra dos fuentes en esta sesión; 2004–2017 son cifras históricas recordadas del BOE que deben contrastarse antes de citarlas.
A31: Convención de colores
A32: Azul: dato copiado de la fuente (valor fijo)
A33: Negro: fórmula de esta hoja
... A36: Fondo amarillo claro: estimación no oficial (elaboración propia)

Sheet Resumen_Salarios
A1: Resumen de salarios — España y Comunidad de Madrid (salario bruto anual, euros)
A2: Último año disponible: 2024 (INE, Encuesta Anual de Estructura Salarial). Los valores enlazan con las hojas de detalle (verde).
A4: Medida 2024 (€/año) | B4: España ambos | C4: España mujeres | D4: España hombres | E4: Madrid ambos | F4: Madrid mujeres | G4: Madrid hombres
A5: Media | B5: =EES_Distribucion!U2 -> 29540.26 | C5: =EES_Distribucion!U8 -> 26904.9 | D5: =EES_Distribucion!U14 -> 32057.55 | E5: =EES_Distribucion!U20 -> 34410.01 | F5: =EES_Distribucion!U26 -> 31048.41 | G5: =EES_Distribucion!U32 -> 37634.49
A6: Mediana | B6: =EES_Distribucion!U5 -> 24497.17 | C6: =EES_Distribucion!U11 -> 22087.71 | D6: =EES_Distribucion!U17 -> 26376.88 | E6: =EES_Distribucion!U23 -> 28037.75 | F6: =EES_Distribucion!U29 -> 25362.11 | G6: =EES_Distribucion!U35 -> 30680.09
A7: Percentil 10 | B7: =EES_Distribucion!U3 -> 12018.46 | C7: =EES_Distribucion!U9 -> 9717.33 | D7: =EES_Distribucion!U15 -> 15327.38 | E7: =EES_Distribucion!U21 -> 13728.43 | F7: =EES_Distribucion!U27 -> 11444.52 | G7: =EES_Distribucion!U33 -> 15876
A8: Cuartil inferior | B8: =EES_Distribucion!U4 -> 17457.47 | C8: =EES_Distribucion!U10 -> 15744.72 | D8: =EES_Distribucion!U16 -> 19776 | E8: =EES_Distribucion!U22 -> 18872.44 | F8: =EES_Distribucion!U28 -> 17071.26 | G8: =EES_Distribucion!U34 -> 21409.25
A9: Cuartil superior | B9: =EES_Distribucion!U6 -> 36969.61 | C9: =EES_Distribucion!U12 -> 34439.17 | D9: =EES_Distribucion!U18 -> 39239.7 | E9: =EES_Distribucion!U24 -> 43598 | F9: =EES_Distribucion!U30 -> 39230.44 | G9: =EES_Distribucion!U36 -> 47685.13
A10: Percentil 90 | B10: =EES_Distribucion!U7 -> 52515.27 | C10: =EES_Distribucion!U13 -> 48730.36 | D10: =EES_Distribucion!U19 -> 56153.65 | E10: =EES_Distribucion!U25 -> 63685.49 | F10: =EES_Distribucion!U31 -> 57968.53 | G10: =EES_Distribucion!U37 -> 68784.2
A11: Moda (salario más frecuente) | B11: =EES_Moda!D4 -> 16520.18 | C11: n.d. | E11: n.d.
A13: Indicadores derivados (fórmulas)
A14: Media / mediana | B14: =B5/B6 -> 1.2058642 | C14: =C5/C6 -> 1.2180937 | D14: =D5/D6 -> 1.2153655 | E14: =E5/E6 -> 1.2272743 | F14: =F5/F6 -> 1.2242045 | G14: =G5/G6 -> 1.2266747
A15: P90 / P10 | B15: =B10/B7 -> 4.3695507 | C15: =C10/C7 -> 5.014789 | D15: =D10/D7 -> 3.663617 | E15: =E10/E7 -> 4.6389492 | F15: =F10/F7 -> 5.0651779 | G15: =G10/G7 -> 4.3325901
A16: Rango intercuartílico (€) | B16: =B9-B8 -> 19512.14 | C16: =C9-C8 -> 18694.45 | D16: =D9-D8 -> 19463.7 | E16: =E9-E8 -> 24725.56 | F16: =F9-F8 -> 22159.18 | G16: =G9-G8 -> 26275.88
A17: Brecha de género en la media (1 − mujeres/hombres, %) [col. ambos sexos] | B17: =(1-C5/D5)*100 -> 16.073125 | E17: =(1-F5/G5)*100 -> 17.500118
A18: Brecha de género en la mediana (1 − mujeres/hombres, %) [col. ambos sexos] | B18: =(1-C6/D6)*100 -> 16.261097 | E18: =(1-F6/G6)*100 -> 17.333652
A19: Madrid vs España (ambos sexos): media / mediana (%) | B19: =(E5/B5-1)*100 -> 16.485129 | C19: =(E6/B6-1)*100 -> 14.453016 | D19: ← diferencia % de la media (B) y de la mediana (C) de Madrid sobre la de España
A21: Desviación típica estimada 2024 (NO oficial, lognormal)
A22: Territorio | B22: DT (P90/P10) | C22: DT (cuartiles) | D22: DT (media/mediana) | E22: Coef. variación (P90/P10, %)
A23: Total Nacional | B23: =Estimacion_DesvTipica!K22 -> 18504.208 | C23: =Estimacion_DesvTipica!L22 -> 17787.557 | D23: =Estimacion_DesvTipica!M22 -> 19906.463 | E23: =Estimacion_DesvTipica!N22 -> 62.640642
A24: Comunidad de Madrid | B24: =Estimacion_DesvTipica!K43 -> 22592.197 | C24: =Estimacion_DesvTipica!L43 -> 23590.439 | D24: =Estimacion_DesvTipica!M43 -> 24481.996 | E24: =Estimacion_DesvTipica!N43 -> 65.655886
A26: SMI y evolución
A27: SMI 2026, mensual en 14 pagas (€) | B27: =SMI_Historico!B24 -> 1221
A28: SMI 2026, anual (€) | B28: =SMI_Historico!C24 -> 17094
A29: SMI 2024 anual / salario mediano España 2024 (%) | B29: =SMI_Historico!E22 -> 64.807486
A30: Crecimiento nominal de la media 2008–2024, España (%) | B30: =(EES_Distribucion!U2/EES_Distribucion!E2-1)*100 -> 34.989229
A31: Crecimiento nominal de la media 2008–2024, Madrid (%) | B31: =(EES_Distribucion!U20/EES_Distribucion!E20-1)*100 -> 36.171512
A32: Crecimiento nominal de la mediana 2008–2024, España (%) | B32: =(EES_Distribucion!U5/EES_Distribucion!E5-1)*100 -> 34.27227
A33: Crecimiento nominal de la mediana 2008–2024, Madrid (%) | B33: =(EES_Distribucion!U23/EES_Distribucion!E23-1)*100 -> 38.324209

Sheet EES_Distribucion
A1: cod_INE | B1: sexo | C1: territorio | D1: medida | E1: 2008 | F1: 2009 | G1: 2010 | H1: 2011 | I1: 2012 | J1: 2013 | K1: 2014 | L1: 2015 | M1: 2016 | N1: 2017 | O1: 2018 | P1: 2019 | Q1: 2020 | R1: 2021 | S1: 2022 | T1: 2023 | U1: 2024
A2: EAES741 | B2: Ambos sexos | C2: Total Nacional | D2: Media | E2: 21883.42 | F2: 22511.47 | G2: 22790.2 | H2: 22899.35 | I2: 22726.44 | J2: 22697.86 | K2: 22858.17 | L2: 23106.3 | M2: 23156.34 | N2: 23646.5 | O2: 24009.12 | P2: 24395.98 | Q2: 25165.51 | R2: 25896.82 | S2: 26948.87 | T2: 28049.94 | U2: 29540.26
A3: EAES740 | B3: Ambos sexos | C3: Total Nacional | D3: Percentil 10 | E3: 8903.52 | F3: 8723.15 | G3: 8643.66 | H3: 8402.15 | I3: 7979.4 | J3: 7692.3 | K3: 7626.2 | L3: 7962.45 | M3: 8095.44 | N3: 8583.81 | O3: 8457.36 | P3: 8943.26 | Q3: 9586.51 | R3: 10192.38 | S3: 10657.37 | T3: 11466.88 | U3: 12018.46
A4: EAES739 | B4: Ambos sexos | C4: Total Nacional | D4: Cuartil inferior | E4: 13342.53 | F4: 13587.26 | G4: 13602.53 | H4: 13553.97 | I4: 13369.45 | J4: 13039.36 | K4: 13217.84 | L4: 13414.92 | M4: 13369.74 | N4: 13897.22 | O4: 13998.29 | P4: 14271.06 | Q4: 14641.96 | R4: 15215.03 | S4: 15913.52 | T4: 16632.97 | U4: 17457.47
A5: EAES738 | B5: Ambos sexos | C5: Total Nacional | D5: Mediana | E5: 18244.4 | F5: 18803.28 | G5: 19017.09 | H5: 19303.51 | I5: 19040.98 | J5: 19029.66 | K5: 19263.78 | L5: 19466.49 | M5: 19432.62 | N5: 19830.12 | O5: 20078.44 | P5: 20351.02 | Q5: 20920.12 | R5: 21638.69 | S5: 22383.11 | T5: 23349 | U5: 24497.17
A6: EAES737 | B6: Ambos sexos | C6: Total Nacional | D6: Cuartil superior | E6: 26874.02 | F6: 28024.86 | G6: 28255.45 | H6: 28658.66 | I6: 28395.5 | J6: 28563.69 | K6: 28782.7 | L6: 29163.66 | M6: 29191.56 | N6: 29628.64 | O6: 30057.33 | P6: 30558.45 | Q6: 31550.01 | R6: 32385.45 | S6: 33561.62 | T6: 34991.64 | U6: 36969.61
A7: EAES736 | B7: Ambos sexos | C7: Total Nacional | D7: Percentil 90 | E7: 38558.29 | F7: 40123.94 | G7: 40811.42 | H7: 40680.54 | I7: 40807.99 | J7: 41108.4 | K7: 41350.36 | L7: 41648.67 | M7: 41855.38 | N7: 42454.21 | O7: 43382.16 | P7: 44127.12 | Q7: 45359.96 | R7: 46430.36 | S7: 48217.21 | T7: 49836 | U7: 52515.27
A8: EAES633 | B8: Mujeres | C8: Total Nacional | D8: Media | E8: 18910.62 | F8: 19502.02 | G8: 19735.22 | H8: 19767.59 | I8: 19537.33 | J8: 19514.58 | K8: 19744.82 | L8: 20051.58 | M8: 20131.41 | N8: 20607.85 | O8: 21011.89 | P8: 21682.02 | Q8: 22467.48 | R8: 23175.95 | S8: 24359.82 | T8: 25591.31 | U8: 26904.9
A9: EAES632 | B9: Mujeres | C9: Total Nacional | D9: Percentil 10 | E9: 7088.36 | F9: 7027.1 | G9: 7001.27 | H9: 6996.22 | I9: 6750.12 | J9: 6457.78 | K9: 6205.32 | L9: 6630.92 | M9: 6808.88 | N9: 7161.93 | O9: 6958.16 | P9: 7416.44 | Q9: 7837.68 | R9: 8329.95 | S9: 8732.51 | T9: 9421.49 | U9: 9717.33
A10: EAES631 | B10: Mujeres | C10: Total Nacional | D10: Cuartil inferior | E10: 11038.28 | F10: 11324.09 | G10: 11462.43 | H10: 11376.86 | I10: 11153.94 | J10: 10801.94 | K10: 10900.7 | L10: 10993.54 | M10: 11129.97 | N10: 11567.75 | O10: 11617.31 | P10: 12403.36 | Q10: 12781.59 | R10: 13369.98 | S10: 14094.78 | T10: 14977.44 | U10: 15744.72
A11: EAES630 | B11: Mujeres | C11: Total Nacional | D11: Mediana | E11: 15886.02 | F11: 16433.14 | G11: 16536.1 | H11: 16796.41 | I11: 16524.51 | J11: 16452.43 | K11: 16771.32 | L11: 16825.11 | M11: 16831.58 | N11: 17214.6 | O11: 17467.43 | P11: 17961.93 | Q11: 18556.68 | R11: 19162.47 | S11: 20045.68 | T11: 21177.99 | U11: 22087.71
A12: EAES629 | B12: Mujeres | C12: Total Nacional | D12: Cuartil superior | E12: 23446.18 | F12: 24556.88 | G12: 24751.72 | H12: 25038.56 | I12: 24505.75 | J12: 24568.84 | K12: 25134.57 | L12: 25562.92 | M12: 25711.14 | N12: 26174.19 | O12: 26743.16 | P12: 27661.43 | Q12: 28747.87 | R12: 29694.42 | S12: 30984.32 | T12: 32648.05 | U12: 34439.17
A13: EAES628 | B13: Mujeres | C13: Total Nacional | D13: Percentil 90 | E13: 34397.13 | F13: 36009.1 | G13: 36249.13 | H13: 35871.36 | I13: 35506.25 | J13: 36068.77 | K13: 36627.29 | L13: 37098.89 | M13: 37167.95 | N13: 37896.51 | O13: 39104.6 | P13: 40005.75 | Q13: 41380.88 | R13: 42182.44 | S13: 44481.68 | T13: 46370.71 | U13: 48730.36
... A37: EAES442 | B37: Hombres | C37: Comunidad de Madrid | D37: Percentil 90 | E37: 52686.37 | F37: 54461.91 | G37: 52372.28 | H37: 53382.21 | I37: 53378.31 | J37: 54635.59 | K37: 54979.32 | L37: 53873.09 | M37: 54266.69 | N37: 54674.86 | O37: 55442.81 | P37: 55884.81 | Q37: 57983.28 | R37: 58491.16 | S37: 62205.71 | T37: 64430.8 | U37: 68784.2

Sheet EES_Moda
A1: anio | B1: salario_medio | C1: salario_mediano | D1: salario_modal | E1: media/mediana | F1: media/moda | G1: detalle | H1: fuente
A2: 2022 | B2: 26948.87 | C2: 22383.11 | D2: 14586.44 | E2: =B2/C2 -> 1.2039824 | F2: =B2/D2 -> 1.8475289 | G2: Moda en torno a 14.586,44 € (4,2% de asalariados); picos similares en 16.495,84 € (4,2%) y 18.494,32 € (4,1%); intervalo más frecuente 14.000-15.000 € | H2: INE nota de prensa EES 2022
A3: 2023 | B3: 28049.94 | C3: 23349 | D3: 15574.85 | E3: =B3/C3 -> 1.2013337 | F3: =B3/D3 -> 1.8009766 | G3: Moda en torno a 15.574,85 € (4,6% de asalariados); intervalo más frecuente 15.000-16.000 € | H3: INE nota de prensa EAES 2023
A4: 2024 | B4: 29540.26 | C4: 24497.17 | D4: 16520.18 | E4: =B4/C4 -> 1.2058642 | F4: =B4/D4 -> 1.7881318 | G4: Intervalo más frecuente 16.000-17.000 € (3,8% de asalariados); 16.000-23.000 € concentra el 29,5% | H4: INE nota de prensa EAES 2024 (28 mayo 2026)
A6: Salario bruto anual en euros, ambos sexos, España. El INE solo da la moda en la nota de prensa, no en las tablas de la API; Madrid no la publica. Se recogen únicamente los tres años consultados.

Sheet Estimacion_DesvTipica
A1: ESTIMACIÓN NO OFICIAL de la desviación típica del salario bruto anual (ambos sexos)
A2: El INE no publica la desviación típica (solo microdatos). Aquí se aproxima suponiendo una distribución lognormal ajustada con (a) P90/P10, (b) cuartiles y (c) media/mediana. Orden de magnitud, no dato oficial.
A4: Total Nacional
A5: Año | B5: Media | C5: P10 | D5: Cuartil inf. | E5: Mediana | F5: Cuartil sup. | G5: P90 | H5: σ (P90/P10) | I5: σ (cuartiles) | J5: σ (media/mediana) | K5: DT est. (P90/P10) | L5: DT est. (cuartiles) | M5: DT est. (media/mediana) | N5: Coef. variación est. (%) (P90/P10)
A6: 2008 | B6: =EES_Distribucion!E2 -> 21883.42 | C6: =EES_Distribucion!E3 -> 8903.52 | D6: =EES_Distribucion!E4 -> 13342.53 | E6: =EES_Distribucion!E5 -> 18244.4 | F6: =EES_Distribucion!E6 -> 26874.02 | G6: =EES_Distribucion!E7 -> 38558.29 | H6: =LN(G6/C6)/(2*NORMSINV(0.9)) -> 0.57185542 | I6: =LN(F6/D6)/(2*NORMSINV(0.75)) -> 0.51906151 | J6: =SQRT(2*LN(B6/E6)) -> 0.60311042 | K6: =B6*SQRT(EXP(H6^2)-1) -> 13610.49 | L6: =B6*SQRT(EXP(I6^2)-1) -> 12168.662 | M6: =B6*SQRT(EXP(J6^2)-1) -> 14494.412 | N6: =K6/B6*100 -> 62.195442
A7: 2009 | B7: =EES_Distribucion!F2 -> 22511.47 | C7: =EES_Distribucion!F3 -> 8723.15 | D7: =EES_Distribucion!F4 -> 13587.26 | E7: =EES_Distribucion!F5 -> 18803.28 | F7: =EES_Distribucion!F6 -> 28024.86 | G7: =EES_Distribucion!F7 -> 40123.94 | H7: =LN(G7/C7)/(2*NORMSINV(0.9)) -> 0.59536924 | I7: =LN(F7/D7)/(2*NORMSINV(0.75)) -> 0.53667189 | J7: =SQRT(2*LN(B7/E7)) -> 0.59998939 | K7: =B7*SQRT(EXP(H7^2)-1) -> 14682.884 | L7: =B7*SQRT(EXP(I7^2)-1) -> 13005.701 | M7: =B7*SQRT(EXP(J7^2)-1) -> 14818.485 | N7: =K7/B7*100 -> 65.224012
A8: 2010 | B8: =EES_Distribucion!G2 -> 22790.2 | C8: =EES_Distribucion!G3 -> 8643.66 | D8: =EES_Distribucion!G4 -> 13602.53 | E8: =EES_Distribucion!G5 -> 19017.09 | F8: =EES_Distribucion!G6 -> 28255.45 | G8: =EES_Distribucion!G7 -> 40811.42 | H8: =LN(G8/C8)/(2*NORMSINV(0.9)) -> 0.60556902 | I8: =LN(F8/D8)/(2*NORMSINV(0.75)) -> 0.54191376 | J8: =SQRT(2*LN(B8/E8)) -> 0.60165201 | K8: =B8*SQRT(EXP(H8^2)-1) -> 15168.499 | L8: =B8*SQRT(EXP(I8^2)-1) -> 13315.054 | M8: =B8*SQRT(EXP(J8^2)-1) -> 15051.501 | N8: =K8/B8*100 -> 66.557113
A9: 2011 | B9: =EES_Distribucion!H2 -> 22899.35 | C9: =EES_Distribucion!H3 -> 8402.15 | D9: =EES_Distribucion!H4 -> 13553.97 | E9: =EES_Distribucion!H5 -> 19303.51 | F9: =EES_Distribucion!H6 -> 28658.66 | G9: =EES_Distribucion!H7 -> 40680.54 | H9: =LN(G9/C9)/(2*NORMSINV(0.9)) -> 0.61537212 | I9: =LN(F9/D9)/(2*NORMSINV(0.75)) -> 0.55506861 | J9: =SQRT(2*LN(B9/E9)) -> 0.58450249 | K9: =B9*SQRT(EXP(H9^2)-1) -> 15537.168 | L9: =B9*SQRT(EXP(I9^2)-1) -> 13755.604 | M9: =B9*SQRT(EXP(J9^2)-1) -> 14613.626 | N9: =K9/B9*100 -> 67.84982
A10: 2012 | B10: =EES_Distribucion!I2 -> 22726.44 | C10: =EES_Distribucion!I3 -> 7979.4 | D10: =EES_Distribucion!I4 -> 13369.45 | E10: =EES_Distribucion!I5 -> 19040.98 | F10: =EES_Distribucion!I6 -> 28395.5 | G10: =EES_Distribucion!I7 -> 40807.99 | H10: =LN(G10/C10)/(2*NORMSINV(0.9)) -> 0.63673391 | I10: =LN(F10/D10)/(2*NORMSINV(0.75)) -> 0.55839131 | J10: =SQRT(2*LN(B10/E10)) -> 0.59487058 | K10: =B10*SQRT(EXP(H10^2)-1) -> 16069.175 | L10: =B10*SQRT(EXP(I10^2)-1) -> 13746.822 | M10: =B10*SQRT(EXP(J10^2)-1) -> 14808.354 | N10: =K10/B10*100 -> 70.706962
A11: 2013 | B11: =EES_Distribucion!J2 -> 22697.86 | C11: =EES_Distribucion!J3 -> 7692.3 | D11: =EES_Distribucion!J4 -> 13039.36 | E11: =EES_Distribucion!J5 -> 19029.66 | F11: =EES_Distribucion!J6 -> 28563.69 | G11: =EES_Distribucion!J7 -> 41108.4 | H11: =LN(G11/C11)/(2*NORMSINV(0.9)) -> 0.65389201 | I11: =LN(F11/D11)/(2*NORMSINV(0.75)) -> 0.58130154 | J11: =SQRT(2*LN(B11/E11)) -> 0.59375388 | K11: =B11*SQRT(EXP(H11^2)-1) -> 16579.289 | L11: =B11*SQRT(EXP(I11^2)-1) -> 14391.524 | M11: =B11*SQRT(EXP(J11^2)-1) -> 14756.782 | N11: =K11/B11*100 -> 73.043399
A12: 2014 | B12: =EES_Distribucion!K2 -> 22858.17 | C12: =EES_Distribucion!K3 -> 7626.2 | D12: =EES_Distribucion!K4 -> 13217.84 | E12: =EES_Distribucion!K5 -> 19263.78 | F12: =EES_Distribucion!K6 -> 28782.7 | G12: =EES_Distribucion!K7 -> 41350.36 | H12: =LN(G12/C12)/(2*NORMSINV(0.9)) -> 0.65954874 | I12: =LN(F12/D12)/(2*NORMSINV(0.75)) -> 0.57688577 | J12: =SQRT(2*LN(B12/E12)) -> 0.58494778 | K12: =B12*SQRT(EXP(H12^2)-1) -> 16874.378 | L12: =B12*SQRT(EXP(I12^2)-1) -> 14363.671 | M12: =B12*SQRT(EXP(J12^2)-1) -> 14600.468 | N12: =K12/B12*100 -> 73.822088
A13: 2015 | B13: =EES_Distribucion!L2 -> 23106.3 | C13: =EES_Distribucion!L3 -> 7962.45 | D13: =EES_Distribucion!L4 -> 13414.92 | E13: =EES_Distribucion!L5 -> 19466.49 | F13: =EES_Distribucion!L6 -> 29163.66 | G13: =EES_Distribucion!L7 -> 41648.67 | H13: =LN(G13/C13)/(2*NORMSINV(0.9)) -> 0.64551936 | I13: =LN(F13/D13)/(2*NORMSINV(0.75)) -> 0.57566175 | J13: =SQRT(2*LN(B13/E13)) -> 0.58550966 | K13: =B13*SQRT(EXP(H13^2)-1) -> 16613.095 | L13: =B13*SQRT(EXP(I13^2)-1) -> 14483.392 | M13: =B13*SQRT(EXP(J13^2)-1) -> 14775.704 | N13: =K13/B13*100 -> 71.89855
A14: 2016 | B14: =EES_Distribucion!M2 -> 23156.34 | C14: =EES_Distribucion!M3 -> 8095.44 | D14: =EES_Distribucion!M4 -> 13369.74 | E14: =EES_Distribucion!M5 -> 19432.62 | F14: =EES_Distribucion!M6 -> 29191.56 | G14: =EES_Distribucion!M7 -> 41855.38 | H14: =LN(G14/C14)/(2*NORMSINV(0.9)) -> 0.64098841 | I14: =LN(F14/D14)/(2*NORMSINV(0.75)) -> 0.57887142 | J14: =SQRT(2*LN(B14/E14)) -> 0.59214105 | K14: =B14*SQRT(EXP(H14^2)-1) -> 16506.483 | L14: =B14*SQRT(EXP(I14^2)-1) -> 14609.966 | M14: =B14*SQRT(EXP(J14^2)-1) -> 15006.368 | N14: =K14/B14*100 -> 71.28278
A15: 2017 | B15: =EES_Distribucion!N2 -> 23646.5 | C15: =EES_Distribucion!N3 -> 8583.81 | D15: =EES_Distribucion!N4 -> 13897.22 | E15: =EES_Distribucion!N5 -> 19830.12 | F15: =EES_Distribucion!N6 -> 29628.64 | G15: =EES_Distribucion!N7 -> 42454.21 | H15: =LN(G15/C15)/(2*NORMSINV(0.9)) -> 0.6236769 | I15: =LN(F15/D15)/(2*NORMSINV(0.75)) -> 0.56120396 | J15: =SQRT(2*LN(B15/E15)) -> 0.59331799 | K15: =B15*SQRT(EXP(H15^2)-1) -> 16305.192 | L15: =B15*SQRT(EXP(I15^2)-1) -> 14387.31 | M15: =B15*SQRT(EXP(J15^2)-1) -> 15360.142 | N15: =K15/B15*100 -> 68.953936
A16: 2018 | B16: =EES_Distribucion!O2 -> 24009.12 | C16: =EES_Distribucion!O3 -> 8457.36 | D16: =EES_Distribucion!O4 -> 13998.29 | E16: =EES_Distribucion!O5 -> 20078.44 | F16: =EES_Distribucion!O6 -> 30057.33 | G16: =EES_Distribucion!O7 -> 43382.16 | H16: =LN(G16/C16)/(2*NORMSINV(0.9)) -> 0.63790302 | I16: =LN(F16/D16)/(2*NORMSINV(0.75)) -> 0.56648109 | J16: =SQRT(2*LN(B16/E16)) -> 0.59797518 | K16: =B16*SQRT(EXP(H16^2)-1) -> 17014.054 | L16: =B16*SQRT(EXP(I16^2)-1) -> 14768.417 | M16: =B16*SQRT(EXP(J16^2)-1) -> 15741.211 | N16: =K16/B16*100 -> 70.864965
A17: 2019 | B17: =EES_Distribucion!P2 -> 24395.98 | C17: =EES_Distribucion!P3 -> 8943.26 | D17: =EES_Distribucion!P4 -> 14271.06 | E17: =EES_Distribucion!P5 -> 20351.02 | F17: =EES_Distribucion!P6 -> 30558.45 | G17: =EES_Distribucion!P7 -> 44127.12 | H17: =LN(G17/C17)/(2*NORMSINV(0.9)) -> 0.62275074 | I17: =LN(F17/D17)/(2*NORMSINV(0.75)) -> 0.56443225 | J17: =SQRT(2*LN(B17/E17)) -> 0.60214173 | K17: =B17*SQRT(EXP(H17^2)-1) -> 16791.848 | L17: =B17*SQRT(EXP(I17^2)-1) -> 14942.987 | M17: =B17*SQRT(EXP(J17^2)-1) -> 16127.653 | N17: =K17/B17*100 -> 68.83039
A18: 2020 | B18: =EES_Distribucion!Q2 -> 25165.51 | C18: =EES_Distribucion!Q3 -> 9586.51 | D18: =EES_Distribucion!Q4 -> 14641.96 | E18: =EES_Distribucion!Q5 -> 20920.12 | F18: =EES_Distribucion!Q6 -> 31550.01 | G18: =EES_Distribucion!Q7 -> 45359.96 | H18: =LN(G18/C18)/(2*NORMSINV(0.9)) -> 0.60640278 | I18: =LN(F18/D18)/(2*NORMSINV(0.75)) -> 0.56908391 | J18: =SQRT(2*LN(B18/E18)) -> 0.60788655 | K18: =B18*SQRT(EXP(H18^2)-1) -> 16776.995 | L18: =B18*SQRT(EXP(I18^2)-1) -> 15562.969 | M18: =B18*SQRT(EXP(J18^2)-1) -> 16826.087 | N18: =K18/B18*100 -> 66.666619
A19: 2021 | B19: =EES_Distribucion!R2 -> 25896.82 | C19: =EES_Distribucion!R3 -> 10192.38 | D19: =EES_Distribucion!R4 -> 15215.03 | E19: =EES_Distribucion!R5 -> 21638.69 | F19: =EES_Distribucion!R6 -> 32385.45 | G19: =EES_Distribucion!R7 -> 46430.36 | H19: =LN(G19/C19)/(2*NORMSINV(0.9)) -> 0.59159273 | I19: =LN(F19/D19)/(2*NORMSINV(0.75)) -> 0.55999776 | J19: =SQRT(2*LN(B19/E19)) -> 0.59939514 | K19: =B19*SQRT(EXP(H19^2)-1) -> 16763.905 | L19: =B19*SQRT(EXP(I19^2)-1) -> 15717.02 | M19: =B19*SQRT(EXP(J19^2)-1) -> 17026.838 | N19: =K19/B19*100 -> 64.733449
A20: 2022 | B20: =EES_Distribucion!S2 -> 26948.87 | C20: =EES_Distribucion!S3 -> 10657.37 | D20: =EES_Distribucion!S4 -> 15913.52 | E20: =EES_Distribucion!S5 -> 22383.11 | F20: =EES_Distribucion!S6 -> 33561.62 | G20: =EES_Distribucion!S7 -> 48217.21 | H20: =LN(G20/C20)/(2*NORMSINV(0.9)) -> 0.58892064 | I20: =LN(F20/D20)/(2*NORMSINV(0.75)) -> 0.55316933 | J20: =SQRT(2*LN(B20/E20)) -> 0.60931882 | K20: =B20*SQRT(EXP(H20^2)-1) -> 17351.656 | L20: =B20*SQRT(EXP(I20^2)-1) -> 16123.833 | M20: =B20*SQRT(EXP(J20^2)-1) -> 18069.284 | N20: =K20/B20*100 -> 64.387322
A21: 2023 | B21: =EES_Distribucion!T2 -> 28049.94 | C21: =EES_Distribucion!T3 -> 11466.88 | D21: =EES_Distribucion!T4 -> 16632.97 | E21: =EES_Distribucion!T5 -> 23349 | F21: =EES_Distribucion!T6 -> 34991.64 | G21: =EES_Distribucion!T7 -> 49836 | H21: =LN(G21/C21)/(2*NORMSINV(0.9)) -> 0.57324058 | I21: =LN(F21/D21)/(2*NORMSINV(0.75)) -> 0.55132217 | J21: =SQRT(2*LN(B21/E21)) -> 0.60569355 | K21: =B21*SQRT(EXP(H21^2)-1) -> 17495.356 | L21: =B21*SQRT(EXP(I21^2)-1) -> 16717.614 | M21: =B21*SQRT(EXP(J21^2)-1) -> 18673.816 | N21: =K21/B21*100 -> 62.37217
A22: 2024 | B22: =EES_Distribucion!U2 -> 29540.26 | C22: =EES_Distribucion!U3 -> 12018.46 | D22: =EES_Distribucion!U4 -> 17457.47 | E22: =EES_Distribucion!U5 -> 24497.17 | F22: =EES_Distribucion!U6 -> 36969.61 | G22: =EES_Distribucion!U7 -> 52515.27 | H22: =LN(G22/C22)/(2*NORMSINV(0.9)) -> 0.57534173 | I22: =LN(F22/D22)/(2*NORMSINV(0.75)) -> 0.55621941 | J22: =SQRT(2*LN(B22/E22)) -> 0.61187659 | K22: =B22*SQRT(EXP(H22^2)-1) -> 18504.208 | L22: =B22*SQRT(EXP(I22^2)-1) -> 17787.557 | M22: =B22*SQRT(EXP(J22^2)-1) -> 19906.463 | N22: =K22/B22*100 -> 62.640642
A25: Comunidad de Madrid
A26: Año | B26: Media | C26: P10 | D26: Cuartil inf. | E26: Mediana | F26: Cuartil sup. | G26: P90 | H26: σ (P90/P10) | I26: σ (cuartiles) | J26: σ (media/mediana) | K26: DT est. (P90/P10) | L26: DT est. (cuartiles) | M26: DT est. (media/mediana) | N26: Coef. variación est. (%) (P90/P10)
A27: 2008 | B27: =EES_Distribucion!E20 -> 25269.61 | C27: =EES_Distribucion!E21 -> 9715.01 | D27: =EES_Distribucion!E22 -> 13915.75 | E27: =EES_Distribucion!E23 -> 20269.59 | F27: =EES_Distribucion!E24 -> 32008.66 | G27: =EES_Distribucion!E25 -> 46748.62 | H27: =LN(G27/C27)/(2*NORMSINV(0.9)) -> 0.61297285 | I27: =LN(F27/D27)/(2*NORMSINV(0.75)) -> 0.61749285 | J27: =SQRT(2*LN(B27/E27)) -> 0.66404933 | K27: =B27*SQRT(EXP(H27^2)-1) -> 17065.17 | L27: =B27*SQRT(EXP(I27^2)-1) -> 17216.433 | M27: =B27*SQRT(EXP(J27^2)-1) -> 18811.878 | N27: =K27/B27*100 -> 67.532382
A28: 2009 | B28: =EES_Distribucion!F20 -> 25860.65 | C28: =EES_Distribucion!F21 -> 9773.58 | D28: =EES_Distribucion!F22 -> 14205.96 | E28: =EES_Distribucion!F23 -> 20712.42 | F28: =EES_Distribucion!F24 -> 33000 | G28: =EES_Distribucion!F25 -> 48338.55 | H28: =LN(G28/C28)/(2*NORMSINV(0.9)) -> 0.62367625 | I28: =LN(F28/D28)/(2*NORMSINV(0.75)) -> 0.62480265 | J28: =SQRT(2*LN(B28/E28)) -> 0.66631672 | K28: =B28*SQRT(EXP(H28^2)-1) -> 17831.914 | L28: =B28*SQRT(EXP(I28^2)-1) -> 17870.808 | M28: =B28*SQRT(EXP(J28^2)-1) -> 19333.256 | N28: =K28/B28*100 -> 68.953849
A29: 2010 | B29: =EES_Distribucion!G20 -> 25988.95 | C29: =EES_Distribucion!G21 -> 10101.07 | D29: =EES_Distribucion!G22 -> 14604.68 | E29: =EES_Distribucion!G23 -> 21319.25 | F29: =EES_Distribucion!G24 -> 32678.77 | G29: =EES_Distribucion!G25 -> 47391.3 | H29: =LN(G29/C29)/(2*NORMSINV(0.9)) -> 0.60309602 | I29: =LN(F29/D29)/(2*NORMSINV(0.75)) -> 0.59703176 | J29: =SQRT(2*LN(B29/E29)) -> 0.62938228 | K29: =B29*SQRT(EXP(H29^2)-1) -> 17213.207 | L29: =B29*SQRT(EXP(I29^2)-1) -> 17007.295 | M29: =B29*SQRT(EXP(J29^2)-1) -> 18118.803 | N29: =K29/B29*100 -> 66.232791
A30: 2011 | B30: =EES_Distribucion!H20 -> 25845.2 | C30: =EES_Distribucion!H21 -> 9307.05 | D30: =EES_Distribucion!H22 -> 14192.74 | E30: =EES_Distribucion!H23 -> 21045.69 | F30: =EES_Distribucion!H24 -> 33026.05 | G30: =EES_Distribucion!H25 -> 48212.49 | H30: =LN(G30/C30)/(2*NORMSINV(0.9)) -> 0.64174005 | I30: =LN(F30/D30)/(2*NORMSINV(0.75)) -> 0.62607777 | J30: =SQRT(2*LN(B30/E30)) -> 0.64098223 | K30: =B30*SQRT(EXP(H30^2)-1) -> 18449.531 | L30: =B30*SQRT(EXP(I30^2)-1) -> 17904.183 | M30: =B30*SQRT(EXP(J30^2)-1) -> 18422.96 | N30: =K30/B30*100 -> 71.384749
A31: 2012 | B31: =EES_Distribucion!I20 -> 26044.39 | C31: =EES_Distribucion!I21 -> 9154.8 | D31: =EES_Distribucion!I22 -> 14323.48 | E31: =EES_Distribucion!I23 -> 21418.48 | F31: =EES_Distribucion!I24 -> 33429.03 | G31: =EES_Distribucion!I25 -> 48734.74 | H31: =LN(G31/C31)/(2*NORMSINV(0.9)) -> 0.65237866 | I31: =LN(F31/D31)/(2*NORMSINV(0.75)) -> 0.62827088 | J31: =SQRT(2*LN(B31/E31)) -> 0.62537715 | K31: =B31*SQRT(EXP(H31^2)-1) -> 18969.638 | L31: =B31*SQRT(EXP(I31^2)-1) -> 18118.642 | M31: =B31*SQRT(EXP(J31^2)-1) -> 18017.774 | N31: =K31/B31*100 -> 72.835792
A32: 2013 | B32: =EES_Distribucion!J20 -> 26215.36 | C32: =EES_Distribucion!J21 -> 8884.58 | D32: =EES_Distribucion!J22 -> 14117.55 | E32: =EES_Distribucion!J23 -> 21273.89 | F32: =EES_Distribucion!J24 -> 33557.52 | G32: =EES_Distribucion!J25 -> 49370.05 | H32: =LN(G32/C32)/(2*NORMSINV(0.9)) -> 0.66912125 | I32: =LN(F32/D32)/(2*NORMSINV(0.75)) -> 0.64184984 | J32: =SQRT(2*LN(B32/E32)) -> 0.64632035 | K32: =B32*SQRT(EXP(H32^2)-1) -> 19700.727 | L32: =B32*SQRT(EXP(I32^2)-1) -> 18717.675 | M32: =B32*SQRT(EXP(J32^2)-1) -> 18877.073 | N32: =K32/B32*100 -> 75.149557
A33: 2014 | B33: =EES_Distribucion!K20 -> 26570.35 | C33: =EES_Distribucion!K21 -> 8862.52 | D33: =EES_Distribucion!K22 -> 14275.72 | E33: =EES_Distribucion!K23 -> 21579.38 | F33: =EES_Distribucion!K24 -> 33791.93 | G33: =EES_Distribucion!K25 -> 49985.99 | H33: =LN(G33/C33)/(2*NORMSINV(0.9)) -> 0.6749286 | I33: =LN(F33/D33)/(2*NORMSINV(0.75)) -> 0.63875087 | J33: =SQRT(2*LN(B33/E33)) -> 0.64507008 | K33: =B33*SQRT(EXP(H33^2)-1) -> 20183.094 | L33: =B33*SQRT(EXP(I33^2)-1) -> 18859.543 | M33: =B33*SQRT(EXP(J33^2)-1) -> 19087.442 | N33: =K33/B33*100 -> 75.960964
A34: 2015 | B34: =EES_Distribucion!L20 -> 26448.04 | C34: =EES_Distribucion!L21 -> 9165.01 | D34: =EES_Distribucion!L22 -> 14359.3 | E34: =EES_Distribucion!L23 -> 21307.78 | F34: =EES_Distribucion!L24 -> 33382.74 | G34: =EES_Distribucion!L25 -> 49079.02 | H34: =LN(G34/C34)/(2*NORMSINV(0.9)) -> 0.65469027 | I34: =LN(F34/D34)/(2*NORMSINV(0.75)) -> 0.62539215 | J34: =SQRT(2*LN(B34/E34)) -> 0.65743409 | K34: =B34*SQRT(EXP(H34^2)-1) -> 19347.542 | L34: =B34*SQRT(EXP(I34^2)-1) -> 18297.553 | M34: =B34*SQRT(EXP(J34^2)-1) -> 19447.375 | N34: =K34/B34*100 -> 73.153029
A35: 2016 | B35: =EES_Distribucion!M20 -> 26330.14 | C35: =EES_Distribucion!M21 -> 9619.78 | D35: =EES_Distribucion!M22 -> 14263.26 | E35: =EES_Distribucion!M23 -> 21165 | F35: =EES_Distribucion!M24 -> 33321.02 | G35: =EES_Distribucion!M25 -> 49427.2 | H35: =LN(G35/C35)/(2*NORMSINV(0.9)) -> 0.63855389 | I35: =LN(F35/D35)/(2*NORMSINV(0.75)) -> 0.62899505 | J35: =SQRT(2*LN(B35/E35)) -> 0.66085614 | K35: =B35*SQRT(EXP(H35^2)-1) -> 18682.025 | L35: =B35*SQRT(EXP(I35^2)-1) -> 18342.996 | M35: =B35*SQRT(EXP(J35^2)-1) -> 19485.005 | N35: =K35/B35*100 -> 70.953004
A36: 2017 | B36: =EES_Distribucion!N20 -> 27089.12 | C36: =EES_Distribucion!N21 -> 9920.36 | D36: =EES_Distribucion!N22 -> 14697.3 | E36: =EES_Distribucion!N23 -> 21608.08 | F36: =EES_Distribucion!N24 -> 34094.32 | G36: =EES_Distribucion!N25 -> 50280.72 | H36: =LN(G36/C36)/(2*NORMSINV(0.9)) -> 0.63322949 | I36: =LN(F36/D36)/(2*NORMSINV(0.75)) -> 0.62378042 | J36: =SQRT(2*LN(B36/E36)) -> 0.67240591 | K36: =B36*SQRT(EXP(H36^2)-1) -> 19025.875 | L36: =B36*SQRT(EXP(I36^2)-1) -> 18682.757 | M36: =B36*SQRT(EXP(J36^2)-1) -> 20481.521 | N36: =K36/B36*100 -> 70.234378
A37: 2018 | B37: =EES_Distribucion!O20 -> 27010.93 | C37: =EES_Distribucion!O21 -> 9396.89 | D37: =EES_Distribucion!O22 -> 14732.73 | E37: =EES_Distribucion!O23 -> 21477.88 | F37: =EES_Distribucion!O24 -> 34273.57 | G37: =EES_Distribucion!O25 -> 51234.14 | H37: =LN(G37/C37)/(2*NORMSINV(0.9)) -> 0.66170858 | I37: =LN(F37/D37)/(2*NORMSINV(0.75)) -> 0.62588272 | J37: =SQRT(2*LN(B37/E37)) -> 0.67707907 | K37: =B37*SQRT(EXP(H37^2)-1) -> 20020.644 | L37: =B37*SQRT(EXP(I37^2)-1) -> 18704.693 | M37: =B37*SQRT(EXP(J37^2)-1) -> 20599.239 | N37: =K37/B37*100 -> 74.120527
A38: 2019 | B38: =EES_Distribucion!P20 -> 27817.76 | C38: =EES_Distribucion!P21 -> 10063.68 | D38: =EES_Distribucion!P22 -> 15070.7 | E38: =EES_Distribucion!P23 -> 22262.74 | F38: =EES_Distribucion!P24 -> 35519.71 | G38: =EES_Distribucion!P25 -> 51938.58 | H38: =LN(G38/C38)/(2*NORMSINV(0.9)) -> 0.64028987 | I38: =LN(F38/D38)/(2*NORMSINV(0.75)) -> 0.6355436 | J38: =SQRT(2*LN(B38/E38)) -> 0.6674732 | K38: =B38*SQRT(EXP(H38^2)-1) -> 19802.929 | L38: =B38*SQRT(EXP(I38^2)-1) -> 19624.393 | M38: =B38*SQRT(EXP(J38^2)-1) -> 20841.102 | N38: =K38/B38*100 -> 71.188079
A39: 2020 | B39: =EES_Distribucion!Q20 -> 28829.06 | C39: =EES_Distribucion!Q21 -> 11402.18 | D39: =EES_Distribucion!Q22 -> 15709.73 | E39: =EES_Distribucion!Q23 -> 23231.04 | F39: =EES_Distribucion!Q24 -> 36697.27 | G39: =EES_Distribucion!Q25 -> 53499.96 | H39: =LN(G39/C39)/(2*NORMSINV(0.9)) -> 0.60312686 | I39: =LN(F39/D39)/(2*NORMSINV(0.75)) -> 0.62893624 | J39: =SQRT(2*LN(B39/E39)) -> 0.65710667 | K39: =B39*SQRT(EXP(H39^2)-1) -> 19095.456 | L39: =B39*SQRT(EXP(I39^2)-1) -> 20081.605 | M39: =B39*SQRT(EXP(J39^2)-1) -> 21185.15 | N39: =K39/B39*100 -> 66.23683
A40: 2021 | B40: =EES_Distribucion!R20 -> 29512.58 | C40: =EES_Distribucion!R21 -> 11769.4 | D40: =EES_Distribucion!R22 -> 16463.53 | E40: =EES_Distribucion!R23 -> 24090.61 | F40: =EES_Distribucion!R24 -> 37441.93 | G40: =EES_Distribucion!R25 -> 54074.15 | H40: =LN(G40/C40)/(2*NORMSINV(0.9)) -> 0.59492468 | I40: =LN(F40/D40)/(2*NORMSINV(0.75)) -> 0.60908529 | J40: =SQRT(2*LN(B40/E40)) -> 0.63717262 | K40: =B40*SQRT(EXP(H40^2)-1) -> 19232.221 | L40: =B40*SQRT(EXP(I40^2)-1) -> 19779.18 | M40: =B40*SQRT(EXP(J40^2)-1) -> 20884.941 | N40: =K40/B40*100 -> 65.166181
A41: 2022 | B41: =EES_Distribucion!S20 -> 31230.73 | C41: =EES_Distribucion!S21 -> 12432.75 | D41: =EES_Distribucion!S22 -> 17085.48 | E41: =EES_Distribucion!S23 -> 25203.47 | F41: =EES_Distribucion!S24 -> 39260.5 | G41: =EES_Distribucion!S25 -> 57854.73 | H41: =LN(G41/C41)/(2*NORMSINV(0.9)) -> 0.59989825 | I41: =LN(F41/D41)/(2*NORMSINV(0.75)) -> 0.61675507 | J41: =SQRT(2*LN(B41/E41)) -> 0.65486008 | K41: =B41*SQRT(EXP(H41^2)-1) -> 20554.339 | L41: =B41*SQRT(EXP(I41^2)-1) -> 21247.235 | M41: =B41*SQRT(EXP(J41^2)-1) -> 22853.512 | N41: =K41/B41*100 -> 65.814469
A42: 2023 | B42: =EES_Distribucion!T20 -> 32219.6 | C42: =EES_Distribucion!T21 -> 13160 | D42: =EES_Distribucion!T22 -> 17938.54 | E42: =EES_Distribucion!T23 -> 26100.08 | F42: =EES_Distribucion!T24 -> 40977.46 | G42: =EES_Distribucion!T25 -> 59648.4 | H42: =LN(G42/C42)/(2*NORMSINV(0.9)) -> 0.58963113 | I42: =LN(F42/D42)/(2*NORMSINV(0.75)) -> 0.61236712 | J42: =SQRT(2*LN(B42/E42)) -> 0.6490556 | K42: =B42*SQRT(EXP(H42^2)-1) -> 20774.965 | L42: =B42*SQRT(EXP(I42^2)-1) -> 21732.877 | M42: =B42*SQRT(EXP(J42^2)-1) -> 23320.859 | N42: =K42/B42*100 -> 64.479276
A43: 2024 | B43: =EES_Distribucion!U20 -> 34410.01 | C43: =EES_Distribucion!U21 -> 13728.43 | D43: =EES_Distribucion!U22 -> 18872.44 | E43: =EES_Distribucion!U23 -> 28037.75 | F43: =EES_Distribucion!U24 -> 43598 | G43: =EES_Distribucion!U25 -> 63685.49 | H43: =LN(G43/C43)/(2*NORMSINV(0.9)) -> 0.59868363 | I43: =LN(F43/D43)/(2*NORMSINV(0.75)) -> 0.62069781 | J43: =SQRT(2*LN(B43/E43)) -> 0.63999327 | K43: =B43*SQRT(EXP(H43^2)-1) -> 22592.197 | L43: =B43*SQRT(EXP(I43^2)-1) -> 23590.439 | M43: =B43*SQRT(EXP(J43^2)-1) -> 24481.996 | N43: =K43/B43*100 -> 65.655886
...

Sheet EES_Edad
A1: tabla_INE | B1: cod_INE | C1: sexo | D1: edad | E1: territorio | F1: 2008 | G1: 2009 | H1: 2010 | I1: 2011 | J1: 2012 | K1: 2013 | L1: 2014 | M1: 2015 | N1: 2016 | O1: 2017 | P1: 2018 | Q1: 2019 | R1: 2020 | S1: 2021 | T1: 2022 | U1: 2023 | V1: 2024
A2: 28189 | B2: EAES399 | C2: Ambos sexos | D2: Todas las edades | E2: Total Nacional | F2: 21883.42 | G2: 22511.47 | H2: 22790.2 | I2: 22899.35 | J2: 22726.44 | K2: 22697.86 | L2: 22858.17 | M2: 23106.3 | N2: 23156.34 | O2: 23646.5 | P2: 24009.12 | Q2: 24395.98 | R2: 25165.51 | S2: 25896.82 | T2: 26948.87 | U2: 28049.94 | V2: 29540.26
A3: 28189 | B3: EAES398 | C3: Ambos sexos | D3: Menos de 20 | E3: Total Nacional | F3: 9960.26 | G3: 9624.47 | H3: 10208.7 | I3: 8148.49 | J3: 7427.72 | K3: 7456.6 | L3: 7732.36 | M3: 7526.91 | N3: 7182.53 | O3: 7868.32 | P3: 8423.42 | Q3: 9101.3 | R3: 9394.06 | S3: 9180.17 | T3: 10597.24 | U3: 11313.36 | V3: 10693.93
A4: 28189 | B4: EAES396 | C4: Ambos sexos | D4: 20 a 24 | E4: Total Nacional | F4: 13293.39 | G4: 12784.44 | H4: 13349.15 | I4: 12210.47 | J4: 11296.43 | K4: 10668.3 | L4: 11835.07 | M4: 11228.51 | N4: 11316.3 | O4: 11775.39 | P4: 12914.18 | Q4: 12640.65 | R4: 12925.08 | S4: 13224.95 | T4: 15181.24 | U4: 15364.17 | V4: 15636.05
A5: 28189 | B5: EAES395 | C5: Ambos sexos | D5: 25 a 29 | E5: Total Nacional | F5: 17434 | G5: 17530.28 | H5: 17637.97 | I5: 16938.06 | J5: 16244.38 | K5: 15587.21 | L5: 16305.61 | M5: 16046.47 | N5: 15876.26 | O5: 16440.55 | P5: 17525.91 | Q5: 17772.31 | R5: 18372.47 | S5: 19089.06 | T5: 20459.6 | U5: 21039.12 | V5: 22723.25
A6: 28189 | B6: EAES394 | C6: Ambos sexos | D6: 30 a 34 | E6: Total Nacional | F6: 20528.28 | G6: 20818.91 | H6: 21274.68 | I6: 20782.77 | J6: 20201.98 | K6: 19452.11 | L6: 20208.67 | M6: 19597.57 | N6: 19339.25 | O6: 19847.27 | P6: 20763.51 | Q6: 20969.47 | R6: 21321.13 | S6: 22123.5 | T6: 24114.17 | U6: 25222.51 | V6: 26944.39
A7: 28189 | B7: EAES393 | C7: Ambos sexos | D7: 35 a 39 | E7: Total Nacional | F7: 22429.72 | G7: 22824.94 | H7: 23219.24 | I7: 23136.49 | J7: 22927.66 | K7: 22522.09 | L7: 22920.46 | M7: 22397.04 | N7: 22216.15 | O7: 22616.45 | P7: 23431.41 | Q7: 23283.02 | R7: 23671.27 | S7: 24134.3 | T7: 25745.84 | U7: 26928.36 | V7: 28704.89
A8: 28189 | B8: EAES392 | C8: Ambos sexos | D8: 40 a 44 | E8: Total Nacional | F8: 23585.09 | G8: 23822.65 | H8: 24336.99 | I8: 24598.45 | J8: 24157.21 | K8: 23973.45 | L8: 24132.53 | M8: 24238.98 | N8: 24305.16 | O8: 24631.01 | P8: 25193.03 | Q8: 25734.87 | R8: 26125.41 | S8: 26770.18 | T8: 27713.56 | U8: 28638.39 | V8: 30215.05
A9: 28189 | B9: EAES391 | C9: Ambos sexos | D9: 45 a 49 | E9: Total Nacional | F9: 24326.53 | G9: 24846.62 | H9: 25156.71 | I9: 25265.23 | J9: 24689.67 | K9: 24781.25 | L9: 25078.78 | M9: 25063.81 | N9: 25127.54 | O9: 25674.74 | P9: 26014.46 | Q9: 26627.9 | R9: 27279.93 | S9: 28077.21 | T9: 29293.69 | U9: 30514.62 | V9: 32051.12
A10: 28189 | B10: EAES390 | C10: Ambos sexos | D10: 50 a 54 | E10: Total Nacional | F10: 25881.4 | G10: 26182.26 | H10: 26604.42 | I10: 26522.82 | J10: 25930.82 | K10: 25748.79 | L10: 25819.99 | M10: 25928.89 | N10: 25917.68 | O10: 26256.18 | P10: 26871.12 | Q10: 27183.07 | R10: 27754.07 | S10: 28380.64 | T10: 29381.29 | U10: 30887.92 | V10: 32357.6
A11: 28189 | B11: EAES389 | C11: Ambos sexos | D11: 55 a 59 | E11: Total Nacional | F11: 26981.89 | G11: 27208.98 | H11: 28234.6 | I11: 27846 | J11: 27166.96 | K11: 27406.12 | L11: 27360.02 | M11: 27457.14 | N11: 27282.41 | O11: 27631.35 | P11: 27948.41 | Q11: 28240.07 | R11: 28713.98 | S11: 29149.8 | T11: 30196.33 | U11: 31231.39 | V11: 32247.58
A12: 28189 | B12: EAES388 | C12: Ambos sexos | D12: 60 a 64 | E12: Total Nacional | F12: 22230.81 | G12: 22332.16 | H12: 22624.93 | I12: 22877.58 | J12: 22290.64 | K12: 22626.56 | L12: 24091.36 | M12: 24716.04 | N12: 24624.48 | O12: 25334.93 | P12: 26073.06 | Q12: 26735.18 | R12: 27390.57 | S12: 28220.73 | T12: 29646.98 | U12: 30968.18 | V12: 31814.39
A13: 28189 | B13: EAES397 | C13: Ambos sexos | D13: 65 y más | E13: Total Nacional | F13: 27116.41 | G13: 24748.59 | H13: 27700.12 | I13: 28058.32 | J13: 25723.51 | K13: 24538.14 | L13: 23854.21 | M13: 22280.44 | N13: 22661.04 | O13: 23190.74 | P13: 24584.63 | Q13: 24857.33 | R13: 26833.25 | S13: 26837.66 | T13: 30496.85 | U13: 30930.83 | V13: 31576.81
A14: 28189 | B14: EAES387 | C14: Mujeres | D14: Todas las edades | E14: Total Nacional | F14: 18910.62 | G14: 19502.02 | H14: 19735.22 | I14: 19767.59 | J14: 19537.33 | K14: 19514.58 | L14: 19744.82 | M14: 20051.58 | N14: 20131.41 | O14: 20607.85 | P14: 21011.89 | Q14: 21682.02 | R14: 22467.48 | S14: 23175.95 | T14: 24359.82 | U14: 25591.31 | V14: 26904.9
A15: 28189 | B15: EAES386 | C15: Mujeres | D15: Menos de 20 | E15: Total Nacional | F15: 8130.68 | G15: 8499.86 | H15: 8637.1 | I15: 6952.69 | L15: 6577.38 | N15: 5733.6 | O15: 6066.79 | P15: 7277.64 | Q15: 7855.04 | R15: 7825.26 | S15: 8067.08 | T15: 8875.09 | U15: 9558.96 | V15: 9280.82
A16: 28189 | B16: EAES384 | C16: Mujeres | D16: 20 a 24 | E16: Total Nacional | F16: 11663.96 | G16: 11424.08 | H16: 11906.62 | I16: 10913.35 | J16: 10099.75 | K16: 9410.99 | L16: 10603.52 | M16: 9690.75 | N16: 9746.34 | O16: 10171.93 | P16: 11100.84 | Q16: 11427.77 | R16: 11548.97 | S16: 11747.25 | T16: 13789.84 | U16: 13891.62 | V16: 14016.31
A17: 28189 | B17: EAES383 | C17: Mujeres | D17: 25 a 29 | E17: Total Nacional | F17: 16005.3 | G17: 16308.84 | H17: 16241.61 | I17: 15552.41 | J17: 15042.6 | K17: 14462.27 | L17: 15019.71 | M17: 14853.58 | N17: 14793.84 | O17: 15129.41 | P17: 16045.85 | Q17: 16650.63 | R17: 17208.34 | S17: 17718.66 | T17: 19343.03 | U17: 20244.83 | V17: 21464.3
A18: 28189 | B18: EAES382 | C18: Mujeres | D18: 30 a 34 | E18: Total Nacional | F18: 18371.69 | G18: 18637.84 | H18: 19261.16 | I18: 18645.05 | J18: 17995.4 | K18: 17443.94 | L18: 18435.4 | M18: 17679.61 | N18: 17398.35 | O18: 17882.67 | P18: 18689.23 | Q18: 19042.73 | R18: 19283.67 | S18: 20089.61 | T18: 22361.32 | U18: 23572.59 | V18: 25340.39
A19: 28189 | B19: EAES381 | C19: Mujeres | D19: 35 a 39 | E19: Total Nacional | F19: 19526.68 | G19: 20072.16 | H19: 20710.98 | I19: 20373.05 | J19: 20031.92 | K19: 19659.26 | L19: 20324.74 | M19: 19924.75 | N19: 19667.87 | O19: 19946.55 | P19: 20757.25 | Q19: 20682.9 | R19: 21322.66 | S19: 21832.52 | T19: 23237.09 | U19: 24799.41 | V19: 26277.95
A20: 28189 | B20: EAES380 | C20: Mujeres | D20: 40 a 44 | E20: Total Nacional | F20: 20268.85 | G20: 20446.34 | H20: 20966.53 | I20: 21290.6 | J20: 20941.8 | K20: 20713.21 | L20: 20953.82 | M20: 21246.22 | N20: 21421.72 | O20: 21792.7 | P20: 22206.71 | Q20: 22826.24 | R20: 23223.46 | S20: 23962.41 | T20: 24734.92 | U20: 25955.04 | V20: 27327.48
A21: 28189 | B21: EAES379 | C21: Mujeres | D21: 45 a 49 | E21: Total Nacional | F21: 20842.75 | G21: 21277.21 | H21: 21305.78 | I21: 21545.65 | J21: 20821.54 | K21: 20987.98 | L21: 21101.2 | M21: 21453.15 | N21: 21614.93 | O21: 22156.46 | P21: 22826.82 | Q21: 23569.51 | R21: 24323.96 | S21: 25071.06 | T21: 26507.49 | U21: 27501.67 | V21: 28750.57
A22: 28189 | B22: EAES378 | C22: Mujeres | D22: 50 a 54 | E22: Total Nacional | F22: 22010.7 | G22: 21899.18 | H22: 22129.13 | I22: 22177.94 | J22: 21744.69 | K22: 21483.87 | L22: 21786.77 | M22: 22115.5 | N22: 22067.03 | O22: 22367.7 | P22: 22832.87 | Q22: 23490.58 | R22: 24228.35 | S22: 24815.41 | T22: 25939.04 | U22: 27862.87 | V22: 29375.17
A23: 28189 | B23: EAES377 | C23: Mujeres | D23: 55 a 59 | E23: Total Nacional | F23: 22666.51 | G23: 22744.5 | H23: 23013.28 | I23: 22999.83 | J23: 22396.23 | K23: 22563.92 | L23: 22482.92 | M23: 22822.24 | N23: 22821.99 | O23: 23360.75 | P23: 23580.95 | Q23: 24648.49 | R23: 25111.64 | S23: 25674.78 | T23: 26928.34 | U23: 27756.04 | V23: 28758.22
A24: 28189 | B24: EAES376 | C24: Mujeres | D24: 60 a 64 | E24: Total Nacional | F24: 19003.09 | G24: 19634.05 | H24: 20035.11 | I24: 20604.14 | J24: 19963.66 | K24: 20520.08 | L24: 20460.53 | M24: 21218.54 | N24: 21246.54 | O24: 22241.99 | P24: 23029.65 | Q24: 24211.54 | R24: 24957.11 | S24: 25412.38 | T24: 27217.22 | U24: 28406.47 | V24: 29319.19
A25: 28189 | B25: EAES385 | C25: Mujeres | D25: 65 y más | E25: Total Nacional | F25: 20430.39 | G25: 18447.25 | H25: 20182.45 | I25: 18443.64 | J25: 16757.7 | K25: 17821.32 | L25: 15756.77 | M25: 15196.83 | N25: 15097.24 | O25: 15166.79 | P25: 19472.58 | Q25: 20126.4 | R25: 21784.18 | S25: 22638.42 | T25: 25437.34 | U25: 26713.37 | V25: 26521.52
A26: 28189 | B26: EAES375 | C26: Hombres | D26: Todas las edades | E26: Total Nacional | F26: 24203.33 | G26: 25001.05 | H26: 25479.74 | I26: 25667.89 | J26: 25682.05 | K26: 25675.17 | L26: 25727.24 | M26: 25992.76 | N26: 25924.43 | O26: 26391.84 | P26: 26738.19 | Q26: 26934.38 | R26: 27642.52 | S26: 28388.69 | T26: 29381.84 | U26: 30372.49 | V26: 32057.55
A27: 28189 | B27: EAES374 | C27: Hombres | D27: Menos de 20 | E27: Total Nacional | F27: 11039.25 | G27: 10305.82 | H27: 11614.73 | I27: 8861.57 | J27: 8045.64 | L27: 9060.68 | M27: 8585.6 | N27: 8369.57 | O27: 8821.3 | P27: 9118.47 | Q27: 9902.54 | R27: 10411.69 | S27: 9946.44 | T27: 12436.56 | U27: 12943.66 | V27: 11752.16
A28: 28189 | B28: EAES372 | C28: Hombres | D28: 20 a 24 | E28: Total Nacional | F28: 14711.9 | G28: 13974.59 | H28: 14804.88 | I28: 13491.76 | J28: 12438.6 | K28: 11856.76 | L28: 13072.04 | M28: 12706.37 | N28: 12641.01 | O28: 13199.81 | P28: 14364.46 | Q28: 13663.22 | R28: 14043.56 | S28: 14399.62 | T28: 16337.24 | U28: 16541.79 | V28: 17066.66
A29: 28189 | B29: EAES371 | C29: Hombres | D29: 25 a 29 | E29: Total Nacional | F29: 18739.58 | G29: 18683.19 | H29: 19099.29 | I29: 18429.65 | J29: 17629.2 | K29: 16853.47 | L29: 17634.95 | M29: 17275.91 | N29: 16906.88 | O29: 17615.64 | P29: 18930.97 | Q29: 18807.51 | R29: 19469.16 | S29: 20368.81 | T29: 21445.91 | U29: 21747.87 | V29: 23857.01
A30: 28189 | B30: EAES370 | C30: Hombres | D30: 30 a 34 | E30: Total Nacional | F30: 22488.18 | G30: 22884.93 | H30: 23175.67 | I30: 22912.41 | J30: 22525.75 | K30: 21468.59 | L30: 21924.81 | M30: 21479 | N30: 21175.45 | O30: 21669.71 | P30: 22818.88 | Q30: 22789.9 | R30: 23129.35 | S30: 23867.16 | T30: 25682.23 | U30: 26764.55 | V30: 28417.52
A31: 28189 | B31: EAES369 | C31: Hombres | D31: 35 a 39 | E31: Total Nacional | F31: 24758.37 | G31: 25280.29 | H31: 25423.2 | I31: 25664.6 | J31: 25652.49 | K31: 25217.67 | L31: 25392.1 | M31: 24769.6 | N31: 24568.19 | O31: 25051.45 | P31: 25901.92 | Q31: 25760.79 | R31: 25833.56 | S31: 26198.45 | T31: 28111.8 | U31: 28919.4 | V31: 31087.1
A32: 28189 | B32: EAES368 | C32: Hombres | D32: 40 a 44 | E32: Total Nacional | F32: 26242.01 | G32: 26593.26 | H32: 27282.66 | I32: 27351.22 | J32: 26995.84 | K32: 26968.77 | L32: 27068.98 | M32: 27033.74 | N32: 26957.7 | O32: 27259.18 | P32: 27940.2 | Q32: 28489.96 | R32: 28823.06 | S32: 29340.39 | T32: 30671.43 | U32: 31199.25 | V32: 32987.94
A33: 28189 | B33: EAES367 | C33: Hombres | D33: 45 a 49 | E33: Total Nacional | F33: 27015.59 | G33: 27779.85 | H33: 28540.81 | I33: 28449.08 | J33: 28253.68 | K33: 28371.35 | L33: 28787.48 | M33: 28391.07 | N33: 28286.16 | O33: 28912.87 | P33: 28978.69 | Q33: 29537.85 | R33: 30024.43 | S33: 30928.97 | T33: 31900.79 | U33: 33470.13 | V33: 35301.5
A34: 28189 | B34: EAES366 | C34: Hombres | D34: 50 a 54 | E34: Total Nacional | F34: 28531.8 | G34: 29503.96 | H34: 30288.16 | I34: 30134.37 | J34: 29562.85 | K34: 29561.34 | L34: 29302.92 | M34: 29600.11 | N34: 29435.74 | O34: 29711.02 | P34: 30312.15 | Q34: 30586.89 | R34: 30899.77 | S34: 31656.92 | T34: 32660.09 | U34: 33776.94 | V34: 35185.97
A35: 28189 | B35: EAES365 | C35: Hombres | D35: 55 a 59 | E35: Total Nacional | F35: 29393.28 | G35: 30181.38 | H35: 32069.41 | I35: 31615.79 | J35: 31349.16 | K35: 31691.39 | L35: 31451.87 | M35: 31601.99 | N35: 31225.13 | O35: 31399.15 | P35: 31843.93 | Q35: 31605.67 | R35: 32067.54 | S35: 32298.79 | T35: 33190.54 | U35: 34431.27 | V35: 35603.17
A36: 28189 | B36: EAES364 | C36: Hombres | D36: 60 a 64 | E36: Total Nacional | F36: 23647.89 | G36: 23651.77 | H36: 24128.93 | I36: 24221.38 | J36: 23795.55 | K36: 24188.15 | L36: 26665.12 | M36: 27748.31 | N36: 27685.28 | O36: 27913.67 | P36: 28741.28 | Q36: 29030.85 | R36: 29717.66 | S36: 30980.79 | T36: 32125.91 | U36: 33532.36 | V36: 34260.95
A37: 28189 | B37: EAES373 | C37: Hombres | D37: 65 y más | E37: Total Nacional | F37: 30532.19 | G37: 28735.15 | H37: 32622.94 | I37: 34136.46 | J37: 31858.86 | K37: 30323.76 | L37: 31005.29 | M37: 29526.67 | N37: 30412.35 | O37: 31850.67 | P37: 29002.54 | Q37: 30462.15 | R37: 31898.67 | S37: 31326.05 | T37: 35612.02 | U37: 35924.26 | V37: 37023.65
A38: 28201 | B38: EAES1624 | C38: Ambos sexos | D38: Menos de 25 | E38: Total Nacional | F38: 12953.62 | G38: 12565.99 | H38: 13154.92 | I38: 11954.86 | J38: 11077.39 | K38: 10506.14 | L38: 11560.18 | M38: 11039.53 | N38: 11046.39 | O38: 11472.81 | P38: 12417.98 | Q38: 12270.4 | R38: 12693.72 | S38: 12930.13 | T38: 14700.9 | U38: 14944.35 | V38: 15135.59
A39: 28201 | B39: EAES1517 | C39: Mujeres | D39: Menos de 25 | E39: Total Nacional | F39: 11370.81 | G39: 11258.44 | H39: 11715.82 | I39: 10723.02 | J39: 9920.38 | K39: 9272.53 | L39: 10316.86 | M39: 9534.67 | N39: 9488.25 | O39: 9933.23 | P39: 10735.83 | Q39: 11103.13 | R39: 11333.14 | S39: 11498.86 | T39: 13212.09 | U39: 13409.09 | V39: 13574.6
... A70: 28201 | B70: EAES1415 | C70: Hombres | D70: Todas las edades | E70: Comunidad de Madrid | F70: 28228.42 | G70: 29333.06 | H70: 29016.28 | I70: 28896.67 | J70: 29116.2 | K70: 29224.3 | L70: 29734.23 | M70: 29314.09 | N70: 29111.2 | O70: 29910.43 | P70: 29816.34 | Q70: 30530.89 | R70: 31495.31 | S70: 32213.88 | T70: 34113.4 | U70: 35052.21 | V70: 37634.49
...

Sheet EES_CCAA_2024
A1: territorio | B1: media | C1: P10 | D1: cuartil_inf | E1: mediana | F1: cuartil_sup | G1: P90 | H1: media/mediana | I1: P90/P10 | J1: dif_media_vs_Nacional_€ | K1: dif_media_vs_Nacional_% | L1: ranking_media (1=mayor)
A2: Total Nacional | B2: 29540.26 | C2: 12018.46 | D2: 17457.47 | E2: 24497.17 | F2: 36969.61 | G2: 52515.27 | H2: =B2/E2 -> 1.2058642 | I2: =G2/C2 -> 4.3695507 | J2: =B2-B$2 -> 0 | K2: =B2/B$2-1 -> 0
A3: Andalucía | B3: 26089.7 | C3: 10567.11 | D3: 15876 | E3: 21557.4 | F3: 32099.35 | G3: 46498.34 | H3: =B3/E3 -> 1.2102434 | I3: =G3/C3 -> 4.4002892 | J3: =B3-B$2 -> -3450.56 | K3: =B3/B$2-1 -> -0.11680872 | L3: =RANK(B3,B$3:B$19,0) -> 14
A4: Aragón | B4: 28061.94 | C4: 12053.34 | D4: 18356.18 | E4: 24936.2 | F4: 34535.16 | G4: 45912.52 | H4: =B4/E4 -> 1.1253495 | I4: =G4/C4 -> 3.8091118 | J4: =B4-B$2 -> -1478.32 | K4: =B4/B$2-1 -> -0.050044245 | L4: =RANK(B4,B$3:B$19,0) -> 7
A5: Asturias, Principado de | B5: 28562.31 | C5: 11058.23 | D5: 16690.52 | E5: 24196.64 | F5: 36057.57 | G5: 51000 | H5: =B5/E5 -> 1.1804246 | I5: =G5/C5 -> 4.6119497 | J5: =B5-B$2 -> -977.95 | K5: =B5/B$2-1 -> -0.033105667 | L5: =RANK(B5,B$3:B$19,0) -> 6
A6: Balears, Illes | B6: 29075.06 | C6: 14986.07 | D6: 19546.12 | E6: 24962.01 | F6: 33965.77 | G6: 47715.88 | H6: =B6/E6 -> 1.1647724 | I6: =G6/C6 -> 3.1840156 | J6: =B6-B$2 -> -465.2 | K6: =B6/B$2-1 -> -0.015748 | L6: =RANK(B6,B$3:B$19,0) -> 5
A7: Canarias | B7: 25120.38 | C7: 11877.7 | D7: 16305.72 | E7: 20631.84 | F7: 29218.96 | G7: 45093.89 | H7: =B7/E7 -> 1.217554 | I7: =G7/C7 -> 3.796517 | J7: =B7-B$2 -> -4419.88 | K7: =B7/B$2-1 -> -0.14962224 | L7: =RANK(B7,B$3:B$19,0) -> 16
A8: Cantabria | B8: 27097.17 | C8: 10799.3 | D8: 17044.41 | E8: 23246.78 | F8: 34226.38 | G8: 47183.35 | H8: =B8/E8 -> 1.1656311 | I8: =G8/C8 -> 4.3691119 | J8: =B8-B$2 -> -2443.09 | K8: =B8/B$2-1 -> -0.082703741 | L8: =RANK(B8,B$3:B$19,0) -> 9
A9: Castilla y León | B9: 26177.28 | C9: 11349.61 | D9: 17011.37 | E9: 22566.96 | F9: 32392.34 | G9: 44688.93 | H9: =B9/E9 -> 1.1599826 | I9: =G9/C9 -> 3.937486 | J9: =B9-B$2 -> -3362.98 | K9: =B9/B$2-1 -> -0.11384395 | L9: =RANK(B9,B$3:B$19,0) -> 13
A10: Castilla - La Mancha | B10: 26062.05 | C10: 11674.14 | D10: 17082.24 | E10: 22045.52 | F10: 31131.79 | G10: 45023.64 | H10: =B10/E10 -> 1.1821926 | I10: =G10/C10 -> 3.8566987 | J10: =B10-B$2 -> -3478.21 | K10: =B10/B$2-1 -> -0.11774473 | L10: =RANK(B10,B$3:B$19,0) -> 15
A11: Cataluña | B11: 31730.05 | C11: 12645.23 | D11: 18678.37 | E11: 27132.93 | F11: 39776.8 | G11: 56220.78 | H11: =B11/E11 -> 1.1694295 | I11: =G11/C11 -> 4.4460069 | J11: =B11-B$2 -> 2189.79 | K11: =B11/B$2-1 -> 0.074129002 | L11: =RANK(B11,B$3:B$19,0) -> 4
A12: Comunitat Valenciana | B12: 26816.98 | C12: 10522.98 | D12: 16723.14 | E12: 22652.43 | F12: 33230.36 | G12: 46991.77 | H12: =B12/E12 -> 1.1838456 | I12: =G12/C12 -> 4.4656333 | J12: =B12-B$2 -> -2723.28 | K12: =B12/B$2-1 -> -0.092188762 | L12: =RANK(B12,B$3:B$19,0) -> 10
A13: Extremadura | B13: 24979.44 | C13: 9243 | D13: 15876 | E13: 20904.64 | F13: 31096.89 | G13: 43833.88 | H13: =B13/E13 -> 1.1949232 | I13: =G13/C13 -> 4.7423867 | J13: =B13-B$2 -> -4560.82 | K13: =B13/B$2-1 -> -0.15439336 | L13: =RANK(B13,B$3:B$19,0) -> 17
A14: Galicia | B14: 26547.27 | C14: 12147.86 | D14: 17010 | E14: 22603.14 | F14: 31587.21 | G14: 44681.64 | H14: =B14/E14 -> 1.1744948 | I14: =G14/C14 -> 3.6781491 | J14: =B14-B$2 -> -2992.99 | K14: =B14/B$2-1 -> -0.10131901 | L14: =RANK(B14,B$3:B$19,0) -> 11
... A19: Rioja, La | B19: 27855.4 | C19: 12188.08 | D19: 17718.12 | E19: 24501.28 | F19: 34568.19 | G19: 47172.71 | H19: =B19/E19 -> 1.1368957 | I19: =G19/C19 -> 3.8703971 | J19: =B19-B$2 -> -1684.86 | K19: =B19/B$2-1 -> -0.057036059 | L19: =RANK(B19,B$3:B$19,0) -> 8
A21: Salario bruto anual 2024, ambos sexos, euros (INE EAES, tabla 28191 por CCAA). Los ratios y diferencias son fórmulas.

Sheet EES_Sector_Ocup_Contrato
A1: dimension | B1: tabla_INE | C1: cod_INE | D1: categoria | E1: 2008 | F1: 2009 | G1: 2010 | H1: 2011 | I1: 2012 | J1: 2013 | K1: 2014 | L1: 2015 | M1: 2016 | N1: 2017 | O1: 2018 | P1: 2019 | Q1: 2020 | R1: 2021 | S1: 2022 | T1: 2023 | U1: 2024 | V1: var_nominal_2008-2024_% | W1: vs_media_total_2024_%
A2: Sector (CNAE-09) | B2: 28185 | C2: EAES291 | D2: Total | E2: 21883.42 | F2: 22511.47 | G2: 22790.2 | H2: 22899.35 | I2: 22726.44 | J2: 22697.86 | K2: 22858.17 | L2: 23106.3 | M2: 23156.34 | N2: 23646.5 | O2: 24009.12 | P2: 24395.98 | Q2: 25165.51 | R2: 25896.82 | S2: 26948.87 | T2: 28049.94 | U2: 29540.26 | V2: =(U2/E2-1)*100 -> 34.989229 | W2: =(U2/U$2-1)*100 -> 0
A3: Sector (CNAE-09) | B3: 28185 | C3: EAES290 | D3: B Industrias extractivas | E3: 26647.03 | F3: 27051.36 | G3: 28373.35 | H3: 29223.47 | I3: 30236.84 | J3: 31389.5 | K3: 32971.21 | L3: 32494.07 | M3: 32400.69 | N3: 32555.75 | O3: 33990.57 | P3: 34159.42 | Q3: 34424.68 | R3: 34866.39 | S3: 36308.58 | T3: 38869.23 | U3: 41951.74 | V3: =(U3/E3-1)*100 -> 57.434956 | W3: =(U3/U$2-1)*100 -> 42.015473
A4: Sector (CNAE-09) | B4: 28185 | C4: EAES289 | D4: C Industria manufacturera | E4: 23615.61 | F4: 23907.49 | G4: 24863.7 | H4: 25308.11 | I4: 25510.48 | J4: 26042.43 | K4: 26476.73 | L4: 26543.77 | M4: 26698.42 | N4: 27214.3 | O4: 27640.12 | P4: 27604.74 | Q4: 27875.98 | R4: 28585.65 | S4: 30000.69 | T4: 31064.13 | U4: 32881.61 | V4: =(U4/E4-1)*100 -> 39.236759 | W4: =(U4/U$2-1)*100 -> 11.311173
A5: Sector (CNAE-09) | B5: 28185 | C5: EAES288 | D5: D Energía eléctrica gas vapor aire acond. | E5: 48578.65 | F5: 50536.7 | G5: 48803.35 | H5: 50371.41 | I5: 52324.67 | J5: 52827.56 | K5: 51034.67 | L5: 51919.72 | M5: 50992.09 | N5: 52014.79 | O5: 51237.33 | P5: 52162.53 | Q5: 53775.71 | R5: 52985.83 | S5: 55470.69 | T5: 54447.96 | U5: 57931.81 | V5: =(U5/E5-1)*100 -> 19.253643 | W5: =(U5/U$2-1)*100 -> 96.111375
A6: Sector (CNAE-09) | B6: 28185 | C6: EAES287 | D6: E Agua saneamiento residuos | E6: 22590.49 | F6: 23617.24 | G6: 24972.27 | H6: 25570.26 | I6: 25188.51 | J6: 25291.38 | K6: 25959.23 | L6: 26340.27 | M6: 26319.91 | N6: 26937.32 | O6: 27289.63 | P6: 27486.42 | Q6: 27854.25 | R6: 29277.93 | S6: 30444.93 | T6: 30957.29 | U6: 32362.61 | V6: =(U6/E6-1)*100 -> 43.257672 | W6: =(U6/U$2-1)*100 -> 9.554249
A7: Sector (CNAE-09) | B7: 28185 | C7: EAES286 | D7: F Construcción | E7: 20706.74 | F7: 21774.7 | G7: 21962.13 | H7: 22541 | I7: 22686.24 | J7: 22720.53 | K7: 22608.41 | L7: 22660.82 | M7: 22163.46 | N7: 22607.96 | O7: 22971.05 | P7: 22789.3 | Q7: 23104.64 | R7: 24136.94 | S7: 25149.41 | T7: 25469.87 | U7: 26965.09 | V7: =(U7/E7-1)*100 -> 30.223734 | W7: =(U7/U$2-1)*100 -> -8.7174927
A8: Sector (CNAE-09) | B8: 28185 | C8: EAES285 | D8: G Comercio | E8: 18545.85 | F8: 19498.77 | G8: 19008.19 | H8: 19444.62 | I8: 19473.68 | J8: 19069.16 | K8: 19771.86 | L8: 19651.05 | M8: 19781.4 | N8: 20608.77 | O8: 21006.17 | P8: 21120.76 | Q8: 21393.49 | R8: 22215.28 | S8: 23209.55 | T8: 24137.4 | U8: 25778.97 | V8: =(U8/E8-1)*100 -> 39.001286 | W8: =(U8/U$2-1)*100 -> -12.732759
A9: Sector (CNAE-09) | B9: 28185 | C9: EAES284 | D9: H Transporte y almacenamiento | E9: 21823.95 | F9: 22196.86 | G9: 22990.76 | H9: 23346.59 | I9: 23454.25 | J9: 23525.42 | K9: 23604.85 | L9: 23937.81 | M9: 23611.32 | N9: 24079.84 | O9: 24653.86 | P9: 24368.8 | Q9: 25033.4 | R9: 25545.48 | S9: 27354.39 | T9: 27687.67 | U9: 28910.3 | V9: =(U9/E9-1)*100 -> 32.47052 | W9: =(U9/U$2-1)*100 -> -2.1325472
A10: Sector (CNAE-09) | B10: 28185 | C10: EAES283 | D10: I Hostelería | E10: 13957.49 | F10: 13996.7 | G10: 14629.55 | H10: 14234.54 | I10: 13867.02 | J10: 13851.08 | K10: 13636.04 | L10: 13977.06 | M10: 14125.34 | N10: 14540.14 | O10: 14345.3 | P10: 14561.75 | Q10: 14136.95 | R10: 14632.81 | S10: 16274.71 | T10: 16985.78 | U10: 17653.42 | V10: =(U10/E10-1)*100 -> 26.479904 | W10: =(U10/U$2-1)*100 -> -40.239456
A11: Sector (CNAE-09) | B11: 28185 | C11: EAES282 | D11: J Información y comunicaciones | E11: 30628.48 | F11: 31551.65 | G11: 32425.68 | H11: 32491.04 | I11: 32522.11 | J11: 33137.17 | K11: 32754.21 | L11: 33046.23 | M11: 32448.31 | N11: 33664.26 | O11: 33117.64 | P11: 34641.28 | Q11: 35663.8 | R11: 36630.48 | S11: 37438.55 | T11: 39674.43 | U11: 42741.94 | V11: =(U11/E11-1)*100 -> 39.549661 | W11: =(U11/U$2-1)*100 -> 44.690467
A12: Sector (CNAE-09) | B12: 28185 | C12: EAES281 | D12: K Financieras y seguros | E12: 41619.07 | F12: 41863.11 | G12: 41638.7 | H12: 41124.22 | I12: 41905.6 | J12: 39607.49 | K12: 40696.06 | L12: 41547.07 | M12: 42684.65 | N12: 43773.58 | O12: 45034.53 | P12: 44302.71 | Q12: 45921.78 | R12: 46122.24 | S12: 47239.53 | T12: 48922.8 | U12: 51862.9 | V12: =(U12/E12-1)*100 -> 24.613308 | W12: =(U12/U$2-1)*100 -> 75.566837
A13: Sector (CNAE-09) | B13: 28185 | C13: EAES280 | D13: L Inmobiliarias | E13: 19533.83 | F13: 19770.52 | G13: 19879.3 | H13: 20349.1 | I13: 19806.64 | J13: 19156 | K13: 20619.89 | L13: 20540.02 | M13: 20899.35 | N13: 21299.08 | O13: 21249.15 | P13: 23333.16 | Q13: 23354.7 | R13: 24835.23 | S13: 26172.9 | T13: 27443.78 | U13: 28854.03 | V13: =(U13/E13-1)*100 -> 47.713121 | W13: =(U13/U$2-1)*100 -> -2.323033
... A20: Sector (CNAE-09) | B20: 28185 | C20: EAES273 | D20: S Otros servicios | E20: 15412.44 | F20: 15868.73 | G20: 16544.57 | H20: 17035.17 | I20: 16918.36 | J20: 16734.95 | K20: 16225.41 | L20: 16033.97 | M20: 15782.15 | N20: 16202.92 | O20: 16374.23 | P20: 17066.82 | Q20: 17468.15 | R20: 18220.77 | S20: 18269.96 | T20: 19751.59 | U20: 20951.43 | V20: =(U20/E20-1)*100 -> 35.938437 | W20: =(U20/U$2-1)*100 -> -29.074998
A21: Ocupación (CNO-11) | B21: 28186 | C21: EAES2556 | D21: Todas las ocupaciones | E21: 21883.42 | F21: 22511.47 | G21: 22790.2 | H21: 22899.35 | I21: 22726.44 | J21: 22697.86 | K21: 22858.17 | L21: 23106.3 | M21: 23156.34 | N21: 23646.5 | O21: 24009.12 | P21: 24395.98 | Q21: 25165.51 | R21: 25896.82 | S21: 26948.87 | T21: 28049.94 | U21: 29540.26 | V21: =(U21/E21-1)*100 -> 34.989229 | W21: =(U21/U$21-1)*100 -> 0
A22: Ocupación (CNO-11) | B22: 28186 | C22: EAES2553 | D22: Directores y gerentes | E22: 57259.16 | F22: 58895.19 | G22: 56602.81 | H22: 54396.44 | I22: 53165.69 | J22: 51594.26 | K22: 52512.99 | L22: 51645.86 | M22: 50530.8 | N22: 51010.54 | O22: 54341.32 | P22: 56634.74 | Q22: 58023.75 | R22: 59219.83 | S22: 59478.63 | T22: 60985.96 | U22: 63865.45 | V22: =(U22/E22-1)*100 -> 11.537525 | W22: =(U22/U$21-1)*100 -> 116.198
A23: Ocupación (CNO-11) | B23: 28186 | C23: EAES2550 | D23: Técnicos y profesionales científicos e intelectuales de salud y enseñanza | E23: 29319.57 | F23: 30536.16 | G23: 31054.93 | H23: 30087.55 | I23: 29460.87 | J23: 29807.74 | K23: 28838.91 | L23: 29669.62 | M23: 30653.34 | N23: 31627.9 | O23: 31607.73 | P23: 33199.26 | Q23: 34809.61 | R23: 36101.1 | S23: 37456.34 | T23: 38857.91 | U23: 40554.53 | V23: =(U23/E23-1)*100 -> 38.318979 | W23: =(U23/U$21-1)*100 -> 37.285623
A24: Ocupación (CNO-11) | B24: 28186 | C24: EAES2547 | D24: Otros técnicos y profesionales científicos e intelectuales | E24: 34027.21 | F24: 35991.91 | G24: 35196.58 | H24: 34368.77 | I24: 34975.77 | J24: 35885.97 | K24: 37100.54 | L24: 36287.87 | M24: 37049.91 | N24: 36181.36 | O24: 37908.75 | P24: 37244.45 | Q24: 38523.51 | R24: 39871.28 | S24: 41382.28 | T24: 42996.72 | U24: 45513.91 | V24: =(U24/E24-1)*100 -> 33.757396 | W24: =(U24/U$21-1)*100 -> 54.074169
A25: Ocupación (CNO-11) | B25: 28186 | C25: EAES2544 | D25: Técnicos y profesionales de apoyo | E25: 27771.52 | F25: 28684.28 | G25: 27914 | H25: 28176.89 | I25: 28360.42 | J25: 28501.99 | K25: 28232.05 | L25: 28943.22 | M25: 28585.99 | N25: 29238.49 | O25: 29261.35 | P25: 29247.01 | Q25: 30067.52 | R25: 31321.69 | S25: 31899.95 | T25: 33242.65 | U25: 34917.46 | V25: =(U25/E25-1)*100 -> 25.731181 | W25: =(U25/U$21-1)*100 -> 18.202954
A26: Ocupación (CNO-11) | B26: 28186 | C26: EAES2541 | D26: Empleados de oficina que no atienden al público | E26: 20793.7 | F26: 21312.78 | G26: 21245.68 | H26: 21646.35 | I26: 21228.39 | J26: 20983.35 | K26: 20852.87 | L26: 21331.32 | M26: 21517.9 | N26: 22487.64 | O26: 24266.55 | P26: 22354.77 | Q26: 23632.89 | R26: 24680.03 | S26: 27402.9 | T26: 28148.26 | U26: 29918.88 | V26: =(U26/E26-1)*100 -> 43.88435 | W26: =(U26/U$21-1)*100 -> 1.2817084
