Workbook

Sheet LEEME
A1: Base de conocimiento — Vivienda y alquiler (España y Comunidad de Madrid)
A3: Descripción
A4: Precio de la vivienda (índices oficiales, valor tasado, precio medio de transacción, compraventas e hipotecas) y alquiler (índice de evolución, índice de actualización legal y niveles €/m² del sistema SERPAVI), con foco en España y la Comunidad de Madrid.
A5: Fecha de consulta: 2026-10-21. Los cálculos propios están en fórmulas visibles; los indicadores en amarillo son aproximaciones no oficiales.
A7: Índice de hojas
A8: Hoja | B8: Contenido | C8: Cobertura
A9: Resumen_Vivienda | B9: Cuadro de indicadores clave de compra y alquiler. | C9: Último dato
A10: IPV_Anual | B10: Índice de Precios de Vivienda (general, nueva, segunda mano) y variaciones, medias anuales. | C10: 2007–2025
A11: IPV_Indicadores | B11: Caída desde el máximo, recuperación desde el mínimo y otras métricas calculadas. | C11: 2007–2025
A12: IPV_Trimestral | B12: IPV trimestral con variaciones trimestral, anual y acumulada. | C12: 2023T3–2026T2
A13: Mercado_Madrid_2T2026 | B13: Valor tasado, transacciones, compraventas e hipotecas: Madrid frente a España (boletín). | C13: 2025T4–2026-05 según fila
A14: Alquiler_IPVA | B14: Índice de precios de vivienda en alquiler (base 2015) por tipo de edificación. | C14: 2013–2024
A15: Alquiler_IRAV | B15: Índice de referencia para actualizar los alquileres (nacional). | C15: dic-2025 a sep-2026
A16: Alquiler_SERPAVI_2022 | B16: Renta en €/m² y cuantía mensual de alquiler por CCAA: media y percentiles 25/75. | C16: 2022
A17: Esfuerzo_Alquiler_Madrid_2022 | B17: Alquiler frente a salario bruto en Madrid (indicativo). | C17: 2022
A18: Idealista_CCAA | B18: Precios de oferta de alquiler y venta (€/m²), variaciones, rentabilidad bruta y ranking por CCAA y España. | C18: sep-2026
A19: Idealista_Provincias | B19: Lo mismo por provincia (50) y ciudades autónomas. | C19: sep-2026
... A23: Idealista_Esfuerzo | B23: Alquiler de oferta de un piso (m² editable) frente al salario bruto mediano por CCAA (indicativo). | C23: sep-2026 / 2024
A24: FUENTES | B24: Origen de cada bloque.
A26: Notas, límites y huecos conocidos
A27: • El IPV (INE) es un índice de precios de compraventa; no da €/m². El €/m² procede del valor tasado (Ministerio de Vivienda), que es un valor de tasación hipotecaria, no el precio de cierre.
A28: • Alquiler: no existe una serie única oficial de niveles. IPVA mide la evolución (todos los contratos), IRAV es una referencia legal y SERPAVI da niveles (€/m²) pero la hoja solo contiene 2022 por CCAA.
A29: • SERPAVI 2011–2024 por municipio y distrito (incluidos los distritos de Madrid capital) está en una hoja de cálculo del Ministerio de Vivienda (67,8 MB) que este entorno no pudo descargar; la nota de síntesis estaba bloqueada para lectura automática. Pendiente de cargar manualmente (URL en FUENTES).
A30: • Idealista (hojas Idealista_*): son precios de OFERTA publicados por un portal privado en sus informes públicos de la sala de prensa; solo se dispone de los últimos 12 meses (hay un enlace a datos anteriores que no se descargó). No son oficiales ni precios de cierre, y Idealista cambió de metodología en julio de 2026. Se transcriben tal cual los informes de septiembre de 2026.
A31: • No incluidos (huecos): Fotocasa y otros portales; estadística notarial y registral; tenencia de vivienda y sobrecarga de coste (ECV); ETDP/compraventas por municipio; visados de obra nueva (existen en el boletín, no se transcribieron); datos del Ayuntamiento de Madrid por distrito; histórico de Idealista anterior a oct-2025.
A32: • Valores marcados como provisionales en el boletín (compraventas, transacciones, hipotecas) pueden revisarse. El IPV del boletín (índice general 4T 2025) está en una base distinta (2007) de la tabla del INE (2025=100).
A33: • Madrid vs España en el boletín: Madrid = Comunidad de Madrid. Tasas siempre interanuales.
A35: Convención de colores
A36: Azul: dato copiado de la fuente (valor fijo)
A37: Negro: fórmula de esta hoja
A38: Verde: fórmula que enlaza con otra hoja
... A40: Fondo amarillo claro: estimación no oficial (elaboración propia)

Sheet Resumen_Vivienda
A1: Resumen de vivienda y alquiler — España y Comunidad de Madrid
A2: Los valores enlazan con las hojas de detalle (verde). Compraventa: INE/Ministerio de Vivienda; alquiler: INE y Ministerio de Vivienda (SERPAVI).
A4: Indicador | B4: Periodo | C4: España | D4: Madrid | E4: Madrid − España | F4: Madrid / España | G4: Nota
A5: IPV general, variación anual (%) | B5: 2026T2 | C5: =IPV_Trimestral!N16 -> 12.2 | D5: =IPV_Trimestral!N4 -> 12.9 | E5: =D5-C5 -> 0.7 | G5: IPV_Trimestral (INE)
A6: IPV segunda mano, variación anual (%) | B6: 2026T2 | C6: =IPV_Trimestral!N24 -> 12.9 | D6: =IPV_Trimestral!N12 -> 14.1 | E6: =D6-C6 -> 1.2 | G6: IPV_Trimestral
A7: IPV vivienda nueva, variación anual (%) | B7: 2026T2 | C7: =IPV_Trimestral!N20 -> 7.4 | D7: =IPV_Trimestral!N8 -> 5.6 | E7: =D7-C7 -> -1.8 | G7: IPV_Trimestral
A8: IPV 2025 respecto al mínimo de la serie (%) | B8: 2025 | C8: =IPV_Indicadores!B9 -> 86.884449 | D8: =IPV_Indicadores!C9 -> 116.32847 | E8: =D8-C8 -> 29.444024 | G8: IPV_Indicadores
A9: IPV 2025 respecto al máximo previo a la crisis (%) | B9: 2025 | C9: =IPV_Indicadores!B8 -> 20.257351 | D9: =IPV_Indicadores!C8 -> 25.908112 | E9: =D9-C9 -> 5.6507615 | G9: IPV_Indicadores
A10: Valor tasado vivienda libre (€/m²) | B10: 1T 2026 | C10: =Mercado_Madrid_2T2026!F2 -> 2315.7 | D10: =Mercado_Madrid_2T2026!D2 -> 4048 | E10: =D10-C10 -> 1732.3 | F10: =D10/C10 -> 1.7480675 | G10: Ministerio de Vivienda vía boletín de la Comunidad de Madrid
A11: Valor tasado vivienda libre, variación anual (%) | B11: 1T 2026 | C11: =Mercado_Madrid_2T2026!G2 -> 13.9 | D11: =Mercado_Madrid_2T2026!E2 -> 16.4 | E11: =D11-C11 -> 2.5
A12: Valor medio de la transacción de vivienda libre (€) | B12: 1T 2026 | C12: =Mercado_Madrid_2T2026!F16 -> 221746.2 | D12: =Mercado_Madrid_2T2026!D16 -> 393857 | E12: =D12-C12 -> 172110.8 | F12: =D12/C12 -> 1.7761612 | G12: Provisional
A13: Compraventas de vivienda (nº, mes) | B13: mayo 2026 | C13: =Mercado_Madrid_2T2026!F9 -> 56462 | D13: =Mercado_Madrid_2T2026!D9 -> 6194 | G13: Provisional
A14: Compraventas, variación anual (%) | B14: mayo 2026 | C14: =Mercado_Madrid_2T2026!G9 -> -7.3 | D14: =Mercado_Madrid_2T2026!E9 -> -11.2 | E14: =D14-C14 -> -3.9
A15: Cuota hipotecaria mensual media (€) | B15: 1T 2026 | C15: =Mercado_Madrid_2T2026!F27 -> 807.8 | D15: =Mercado_Madrid_2T2026!D27 -> 1277.4 | E15: =D15-C15 -> 469.6 | F15: =D15/C15 -> 1.581332
A16: Cuota hipotecaria / coste salarial (%) | B16: 1T 2026 | C16: =Mercado_Madrid_2T2026!F28 -> 34 | D16: =Mercado_Madrid_2T2026!D28 -> 44 | E16: =D16-C16 -> 10
A17: Alquiler de piso, renta media (€/m² y mes) | B17: 2022 | D17: =Alquiler_SERPAVI_2022!D14 -> 11.1 | G17: SERPAVI; España total sin dato en la fuente; Madrid es la CCAA con mayor renta entre las que tienen dato (Navarra y País Vasco n.d.)
A18: Alquiler de piso, cuantía mensual media (€) | B18: 2022 | D18: =Alquiler_SERPAVI_2022!J14 -> 738 | G18: SERPAVI
A19: Índice de precios de alquiler (IPVA), variación anual (%) | B19: 2024 | C19: =Alquiler_IPVA!O9 -> 3.5 | D19: =Alquiler_IPVA!O3 -> 3.4 | E19: =D19-C19 -> -0.1 | G19: Alquiler_IPVA (INE)
A20: Índice de precios de alquiler (IPVA) acumulado 2015–2024 (%) | B20: 2024 | C20: =Alquiler_IPVA!C16 -> 22.92 | D20: =Alquiler_IPVA!B16 -> 22.246 | E20: =D20-C20 -> -0.674
A21: IRAV (actualización legal del alquiler), variación anual (%) | B21: sep-2026 | C21: =Alquiler_IRAV!B11 -> 2.54 | G21: Nacional
A22: Alquiler medio / salario bruto mediano de Madrid (%) | B22: 2022 | D22: =Esfuerzo_Alquiler_Madrid_2022!B13 -> 35.138019 | G22: Indicativo (ver hoja)
A23: Precios de oferta de Idealista (anuncios, no contratos ni compraventas cerradas)
A24: Alquiler de oferta (€/m² y mes) | B24: sep-2026 | C24: =Idealista_CCAA!B2 -> 15.1 | D24: =Idealista_CCAA!B18 -> 21.6 | E24: =D24-C24 -> 6.5 | F24: =D24/C24 -> 1.4304636 | G24: Idealista_CCAA. Madrid = Comunidad de Madrid
A25: Alquiler de oferta, variación anual (%) | B25: sep-2026 | C25: =Idealista_CCAA!E2 -> 5.6 | D25: =Idealista_CCAA!E18 -> 5.7 | E25: =D25-C25 -> 0.1 | G25: Idealista_CCAA
A26: Venta de oferta (€/m²) | B26: sep-2026 | C26: =Idealista_CCAA!H2 -> 2930 | D26: =Idealista_CCAA!H18 -> 5065 | E26: =D26-C26 -> 2135 | F26: =D26/C26 -> 1.7286689 | G26: Idealista_CCAA. Cambio de metodología en jul-2026
A27: Venta de oferta, variación anual (%) | B27: sep-2026 | C27: =Idealista_CCAA!K2 -> 11.8 | D27: =Idealista_CCAA!K18 -> 6.9 | E27: =D27-C27 -> -4.9 | G27: Idealista_CCAA
A28: Rentabilidad bruta de oferta: alquiler×12 ÷ venta (%) | B28: sep-2026 | C28: =Idealista_CCAA!L2 -> 6.1843003 | D28: =Idealista_CCAA!L18 -> 5.1174729 | E28: =D28-C28 -> -1.0668275 | G28: Cálculo propio (no oficial)
A29: Alquiler de oferta, Madrid ciudad (€/m² y mes) | B29: sep-2026 | D29: =Idealista_Madrid_Distritos!B2 -> 23.4 | G29: Idealista_Madrid_Distritos
A30: Alquiler de un piso de 70 m², Madrid ciudad (€/mes) | B30: sep-2026 | D30: =Idealista_Madrid_Distritos!N2 -> 1638 | G30: Cálculo propio (70 m² × €/m²)
A31: Alquiler de 70 m² ÷ salario bruto mediano mensual (%) | B31: sep-2026 / 2024 | C31: =Idealista_Esfuerzo!F9 -> 51.777409 | D31: =Idealista_Esfuerzo!F24 -> 64.712753 | E31: =D31-C31 -> 12.935344 | G31: Idealista_Esfuerzo; indicativo, salario individual bruto (EES 2024)

Sheet IPV_Anual
A1: territorio | B1: serie | C1: unidad | D1: 2007 | E1: 2008 | F1: 2009 | G1: 2010 | H1: 2011 | I1: 2012 | J1: 2013 | K1: 2014 | L1: 2015 | M1: 2016 | N1: 2017 | O1: 2018 | P1: 2019 | Q1: 2020 | R1: 2021 | S1: 2022 | T1: 2023 | U1: 2024 | V1: 2025
A2: Madrid | B2: Índice general | C2: base 2025=100 | D2: 79.423 | E2: 74.931 | F2: 67.172 | G2: 67.436 | H2: 61.579 | I2: 52.133 | J2: 46.226 | K2: 47.414 | L2: 50.135 | M2: 54.43 | N2: 60.665 | O2: 66.843 | P2: 70.762 | Q2: 71.974 | R2: 73.802 | S2: 78.829 | T2: 81.928 | U2: 88.214 | V2: 100
A3: Madrid | B3: Índice vivienda nueva | C3: base 2025=100 | D3: 63.116 | E3: 63.326 | F3: 56.069 | G3: 56.838 | H3: 53.737 | I3: 46.278 | J3: 41.262 | K3: 43.02 | L3: 45.965 | M3: 50.109 | N3: 54.739 | O3: 58.216 | P3: 62.618 | Q3: 66.565 | R3: 70.086 | S3: 75.28 | T3: 81.443 | U3: 89.155 | V3: 100
A4: Madrid | B4: Índice vivienda segunda mano | C4: base 2025=100 | D4: 88.724 | E4: 79.836 | F4: 72.413 | G4: 72.239 | H4: 64.528 | I4: 54.203 | J4: 47.856 | K4: 48.68 | L4: 51.356 | M4: 55.716 | N4: 62.299 | O4: 69.096 | P4: 72.907 | Q4: 73.405 | R4: 74.835 | S4: 79.798 | T4: 82.068 | U4: 87.995 | V4: 100
A5: Madrid | B5: Variación anual general | C5: % | D5: 6.9 | E5: -5.7 | F5: -10.4 | G5: 0.4 | H5: -8.7 | I5: -15.3 | J5: -11.3 | K5: 2.6 | L5: 5.7 | M5: 8.6 | N5: 11.5 | O5: 10.2 | P5: 5.9 | Q5: 1.7 | R5: 2.5 | S5: 6.8 | T5: 3.9 | U5: 7.7 | V5: 13.4
A6: Madrid | B6: Variación anual vivienda nueva | C6: % | D6: 8.4 | E6: 0.3 | F6: -11.5 | G6: 1.4 | H6: -5.5 | I6: -13.9 | J6: -10.8 | K6: 4.3 | L6: 6.8 | M6: 9 | N6: 9.2 | O6: 6.4 | P6: 7.6 | Q6: 6.3 | R6: 5.3 | S6: 7.4 | T6: 8.2 | U6: 9.5 | V6: 12.2
A7: Madrid | B7: Variación anual vivienda segunda mano | C7: % | D7: 5.9 | E7: -10 | F7: -9.3 | G7: -0.2 | H7: -10.7 | I7: -16 | J7: -11.7 | K7: 1.7 | L7: 5.5 | M7: 8.5 | N7: 11.8 | O7: 10.9 | P7: 5.5 | Q7: 0.7 | R7: 1.9 | S7: 6.6 | T7: 2.8 | U7: 7.2 | V7: 13.6
A8: Total Nacional | B8: Índice general | C8: base 2025=100 | D8: 83.155 | E8: 81.897 | F8: 76.42 | G8: 74.898 | H8: 69.386 | I8: 59.853 | J8: 53.509 | K8: 53.669 | L8: 55.585 | M8: 58.177 | N8: 61.776 | O8: 65.921 | P8: 69.257 | Q8: 70.722 | R8: 73.332 | S8: 78.75 | T8: 81.867 | U8: 88.749 | V8: 100
A9: Total Nacional | B9: Índice vivienda nueva | C9: base 2025=100 | D9: 63.288 | E9: 65.94 | F9: 63.213 | G9: 61.531 | H9: 58.351 | I9: 51.181 | J9: 45.85 | K9: 46.248 | L9: 48.438 | M9: 51.598 | N9: 54.659 | O9: 58.147 | P9: 62.403 | Q9: 66.457 | R9: 69.524 | S9: 75.032 | T9: 81.053 | U9: 89.851 | V9: 100
A10: Total Nacional | B10: Índice vivienda segunda mano | C10: base 2025=100 | D10: 94.904 | E10: 88.988 | F10: 80.981 | G10: 80.013 | H10: 72.452 | I10: 61.699 | J10: 54.971 | K10: 55.021 | L10: 56.877 | M10: 59.361 | N10: 63.071 | O10: 67.334 | P10: 70.523 | Q10: 71.517 | R10: 74.079 | S10: 79.473 | T10: 82.011 | U10: 88.566 | V10: 100
A11: Total Nacional | B11: Variación anual general | C11: % | D11: 9.8 | E11: -1.5 | F11: -6.7 | G11: -2 | H11: -7.4 | I11: -13.7 | J11: -10.6 | K11: 0.3 | L11: 3.6 | M11: 4.7 | N11: 6.2 | O11: 6.7 | P11: 5.1 | Q11: 2.1 | R11: 3.7 | S11: 7.4 | T11: 4 | U11: 8.4 | V11: 12.7
A12: Total Nacional | B12: Variación anual vivienda nueva | C12: % | D12: 11.9 | E12: 4.2 | F12: -4.1 | G12: -2.7 | H12: -5.2 | I12: -12.3 | J12: -10.4 | K12: 0.9 | L12: 4.7 | M12: 6.5 | N12: 5.9 | O12: 6.4 | P12: 7.3 | Q12: 6.5 | R12: 4.6 | S12: 7.9 | T12: 8 | U12: 10.9 | V12: 11.3
A13: Total Nacional | B13: Variación anual vivienda segunda mano | C13: % | D13: 8.2 | E13: -6.2 | F13: -9 | G13: -1.2 | H13: -9.4 | I13: -14.8 | J13: -10.9 | K13: 0.1 | L13: 3.4 | M13: 4.4 | N13: 6.3 | O13: 6.8 | P13: 4.7 | Q13: 1.4 | R13: 3.6 | S13: 7.3 | T13: 3.2 | U13: 8 | V13: 12.9
A15: Índice de Precios de Vivienda (IPV, INE), medias anuales, base 2025 = 100 (tablas 80271). Variaciones en %. Precio de compraventa de vivienda (nueva y de segunda mano), no alquiler ni €/m².

Sheet IPV_Indicadores
A1: indicador (índice general) | B1: España | C1: Madrid | D1: Madrid − España
A2: Índice 2007 (base 2025=100) | B2: =IPV_Anual!D8 -> 83.155 | C2: =IPV_Anual!D2 -> 79.423 | D2: =C2-B2 -> -3.732
A3: Máximo previo a la crisis (2007–2009) | B3: =MAX(IPV_Anual!D8:F8) -> 83.155 | C3: =MAX(IPV_Anual!D2:F2) -> 79.423 | D3: =C3-B3 -> -3.732
A4: Mínimo de la serie | B4: =MIN(IPV_Anual!D8:V8) -> 53.509 | C4: =MIN(IPV_Anual!D2:V2) -> 46.226 | D4: =C4-B4 -> -7.283
A5: Año del mínimo | B5: =INDEX(IPV_Anual!D$1:V$1,MATCH(MIN(IPV_Anual!D8:V8),IPV_Anual!D8:V8,0)) -> 2013 | C5: =INDEX(IPV_Anual!D$1:V$1,MATCH(MIN(IPV_Anual!D2:V2),IPV_Anual!D2:V2,0)) -> 2013
A6: Índice 2025 | B6: =IPV_Anual!V8 -> 100 | C6: =IPV_Anual!V2 -> 100 | D6: =C6-B6 -> 0
A7: Caída del máximo previo al mínimo (%) | B7: =(B4/B3-1)*100 -> -35.651494 | C7: =(C4/C3-1)*100 -> -41.797716 | D7: =C7-B7 -> -6.1462218
A8: 2025 respecto al máximo previo a la crisis (%) | B8: =(B6/B3-1)*100 -> 20.257351 | C8: =(C6/C3-1)*100 -> 25.908112 | D8: =C8-B8 -> 5.6507615
A9: 2025 respecto al mínimo (%) | B9: =(B6/B4-1)*100 -> 86.884449 | C9: =(C6/C4-1)*100 -> 116.32847 | D9: =C9-B9 -> 29.444024
A10: Variación media anual 2014–2025 (%, media aritmética) | B10: =AVERAGE(IPV_Anual!K11:V11) -> 5.4083333 | C10: =AVERAGE(IPV_Anual!K5:V5) -> 6.7083333 | D10: =C10-B10 -> 1.3
A11: Variación anual 2025 publicada (%) | B11: =IPV_Anual!V11 -> 12.7 | C11: =IPV_Anual!V5 -> 13.4 | D11: =C11-B11 -> 0.7
A12: Variación 2025 recalculada con los índices (%) | B12: =(IPV_Anual!V8/IPV_Anual!U8-1)*100 -> 12.677326 | C12: =(IPV_Anual!V2/IPV_Anual!U2-1)*100 -> 13.360691 | D12: =C12-B12 -> 0.68336511
A15: El máximo previo a la crisis se toma entre 2007 y 2009. Todo son fórmulas sobre IPV_Anual.

Sheet IPV_Trimestral
A1: territorio | B1: serie | C1: 2023T3 | D1: 2023T4 | E1: 2024T1 | F1: 2024T2 | G1: 2024T3 | H1: 2024T4 | I1: 2025T1 | J1: 2025T2 | K1: 2025T3 | L1: 2025T4 | M1: 2026T1 | N1: 2026T2
A2: Madrid | B2: General - Índice (base 2025=100) | C2: 83.52 | D2: 82.634 | E2: 84.621 | F2: 87.504 | G2: 89.567 | H2: 91.164 | I2: 94.468 | J2: 99.111 | K2: 102.306 | L2: 104.115 | M2: 107.296 | N2: 111.85
A3: Madrid | B3: General - Var. trimestral % | C3: 2.3 | D3: -1.1 | E3: 2.4 | F3: 3.4 | G3: 2.4 | H3: 1.8 | I3: 3.6 | J3: 4.9 | K3: 3.2 | L3: 1.8 | M3: 3.1 | N3: 4.2
A4: Madrid | B4: General - Var. anual % | C4: 4.1 | D4: 4.5 | E4: 5.9 | F4: 7.2 | G4: 7.2 | H4: 10.3 | I4: 11.6 | J4: 13.3 | K4: 14.2 | L4: 14.2 | M4: 13.6 | N4: 12.9
A5: Madrid | B5: General - Var. en lo que va de año % | C5: 5.6 | D5: 4.5 | E5: 2.4 | F5: 5.9 | G5: 8.4 | H5: 10.3 | I5: 3.6 | J5: 8.7 | K5: 12.2 | L5: 14.2 | M5: 3.1 | N5: 7.4
A6: Madrid | B6: Vivienda nueva - Índice | C6: 83.961 | D6: 83.163 | E6: 86.308 | F6: 89.192 | G6: 90.428 | H6: 90.692 | I6: 96.866 | J6: 101.099 | K6: 100.203 | L6: 101.833 | M6: 103.572 | N6: 106.728
A7: Madrid | B7: Vivienda nueva - Var. trimestral % | C7: 4.3 | D7: -1 | E7: 3.8 | F7: 3.3 | G7: 1.4 | H7: 0.3 | I7: 6.8 | J7: 4.4 | K7: -0.9 | L7: 1.6 | M7: 1.7 | N7: 3
A8: Madrid | B8: Vivienda nueva - Var. anual % | C8: 11.6 | D8: 9.8 | E8: 10.4 | F8: 10.8 | G8: 7.7 | H8: 9.1 | I8: 12.2 | J8: 13.3 | K8: 10.8 | L8: 12.3 | M8: 6.9 | N8: 5.6
A9: Madrid | B9: Vivienda nueva - Var. en lo que va de año % | C9: 10.8 | D9: 9.8 | E9: 3.8 | F9: 7.3 | G9: 8.7 | H9: 9.1 | I9: 6.8 | J9: 11.5 | K9: 10.5 | L9: 12.3 | M9: 1.7 | N9: 4.8
A10: Madrid | B10: Vivienda segunda mano - Índice | C10: 83.414 | D10: 82.504 | E10: 84.245 | F10: 87.127 | G10: 89.365 | H10: 91.245 | I10: 94.057 | J10: 98.771 | K10: 102.666 | L10: 104.506 | M10: 107.894 | N10: 112.649
A11: Madrid | B11: Vivienda segunda mano - Var. trimestral % | C11: 1.8 | D11: -1.1 | E11: 2.1 | F11: 3.4 | G11: 2.6 | H11: 2.1 | I11: 3.1 | J11: 5 | K11: 3.9 | L11: 1.8 | M11: 3.2 | N11: 4.4
A12: Madrid | B12: Vivienda segunda mano - Var. anual % | C12: 2.1 | D12: 3.1 | E12: 4.8 | F12: 6.3 | G12: 7.1 | H12: 10.6 | I12: 11.6 | J12: 13.4 | K12: 14.9 | L12: 14.5 | M12: 14.7 | N12: 14.1
A13: Madrid | B13: Vivienda segunda mano - Var. en lo que va de año % | C13: 4.3 | D13: 3.1 | E13: 2.1 | F13: 5.6 | G13: 8.3 | H13: 10.6 | I13: 3.1 | J13: 8.2 | K13: 12.5 | L13: 14.5 | M13: 3.2 | N13: 7.8
... A25: Total Nacional | B25: Vivienda segunda mano - Var. en lo que va de año % | C25: 4.7 | D25: 3.6 | E25: 2.2 | F25: 6 | G25: 9 | H25: 11.1 | I25: 3.2 | J25: 7.6 | K25: 11.2 | L25: 13.1 | M25: 3.5 | N25: 7.4
A27: IPV trimestral (INE tabla 80270), base 2025 = 100 (media 2025 = 100). Variaciones en %. Último trimestre: 2026T2.

Sheet Mercado_Madrid_2T2026
A1: bloque | B1: indicador | C1: periodo | D1: madrid | E1: madrid_var_anual_pct | F1: espana | G1: espana_var_anual_pct | H1: unidad | I1: estado
A2: Valor tasado | B2: Vivienda libre total | C2: 1T 2026 | D2: 4048 | E2: 16.4 | F2: 2315.7 | G2: 13.9 | H2: €/m²
A3: Valor tasado | B3: Vivienda libre hasta 5 años | C3: 1T 2026 | D3: 4590.7 | E3: 18.6 | F3: 2685.2 | G3: 13.9 | H3: €/m²
A4: Valor tasado | B4: Vivienda libre más de 5 años | C4: 1T 2026 | D4: 4025.6 | E4: 16.3 | F4: 2303.8 | G4: 13.8 | H4: €/m²
A5: Valor tasado | B5: Vivienda protegida | C5: 1T 2026 | D5: 1503.6 | E5: 5 | F5: 1222.3 | G5: 4.5 | H5: €/m²
A6: Valor tasado | B6: Suelo urbano | C6: 1T 2026 | D6: 380.6 | E6: 24.2 | F6: 187.8 | G6: 8.7 | H6: €/m²
A7: IPV (base INE 2007) | B7: General | C7: 4T 2025 | D7: 207.67 | E7: 14.2 | F7: 186.75 | G7: 12.9 | H7: índice
A8: IPV (base INE 2007) | B8: Segunda mano | C8: 1T 2026 | D8: 107.89 | E8: 14.7 | F8: 107.67 | G8: 13.5 | H8: índice
A9: Compraventas | B9: Total | C9: mayo 2026 | D9: 6194 | E9: -11.2 | F9: 56462 | G9: -7.3 | H9: nº | I9: provisional
A10: Compraventas | B10: Libre | C10: mayo 2026 | D10: 5861 | E10: -11.5 | F10: 52831 | G10: -7.2 | H10: nº | I10: provisional
A11: Compraventas | B11: Protegida | C11: mayo 2026 | D11: 333 | E11: -7.2 | F11: 3631 | G11: -8.3 | H11: nº | I11: provisional
A12: Compraventas | B12: Nueva | C12: mayo 2026 | D12: 1231 | E12: -19.2 | F12: 11888 | G12: -6 | H12: nº | I12: provisional
A13: Compraventas | B13: Usada | C13: mayo 2026 | D13: 4963 | E13: -9 | F13: 44574 | G13: -7.6 | H13: nº | I13: provisional
A14: Transacciones vivienda libre | B14: Número | C14: 1T 2026 | D14: 18462 | E14: -14.3 | F14: 159317 | G14: -11 | H14: nº | I14: provisional
A15: Transacciones vivienda libre | B15: Valor | C15: 1T 2026 | D15: 7271387.2 | E15: -7.7 | F15: 35327939 | G15: -3.7 | H15: miles € | I15: provisional
A16: Transacciones vivienda libre | B16: Valor medio | C16: 1T 2026 | D16: 393857 | E16: 7.6 | F16: 221746.2 | G16: 8.2 | H16: € | I16: provisional
A17: Transacciones vivienda libre | B17: Nueva: número | C17: 1T 2026 | D17: 1261 | E17: -28.4 | F17: 13025 | G17: -12.2 | H17: nº | I17: provisional
A18: Transacciones vivienda libre | B18: Nueva: valor medio | C18: 1T 2026 | D18: 455094.5 | E18: -0.3 | F18: 307781.6 | G18: 6.4 | H18: € | I18: provisional
A19: Transacciones vivienda libre | B19: Usada: número | C19: 1T 2026 | D19: 17201 | E19: -13 | F19: 146292 | G19: -10.9 | H19: nº | I19: provisional
A20: Transacciones vivienda libre | B20: Usada: valor medio | C20: 1T 2026 | D20: 389367.7 | E20: 8.8 | F20: 214086.1 | G20: 8.5 | H20: € | I20: provisional
... A25: Hipotecas | B25: Hipotecas constituidas importe | C25: mayo 2026 | D25: 1657468 | E25: 12.5 | F25: 7381626 | G25: 9.6 | H25: miles € | I25: provisional
A26: Hipotecas | B26: Duración media | C26: 1T 2026 | D26: 299 | E26: -5.7 | F26: 305 | G26: 0.7 | H26: meses
A27: Hipotecas | B27: Cuota mensual media | C27: 1T 2026 | D27: 1277.4 | E27: 12.3 | F27: 807.8 | G27: 8.4 | H27: €
A28: Hipotecas | B28: Cuota respecto al coste salarial | C28: 1T 2026 | D28: 44 | E28: 8.6 | F28: 34 | G28: 4.9 | H28: %
A30: Boletín trimestral de la vivienda, Comunidad de Madrid, 2.º trimestre 2026 (1.ª edición, julio 2026). Reúne datos del Ministerio de Vivienda (valor tasado), INE (compraventas, transacciones, hipotecas, IPV) y visados de arquitectos. Las tasas son interanuales. Valores provisionales donde se indica. El boletín no incluye alquiler. Los visados de obra nueva no se transcribieron.

Sheet Alquiler_IPVA
A1: territorio | B1: serie | C1: unidad | D1: 2013 | E1: 2014 | F1: 2015 | G1: 2016 | H1: 2017 | I1: 2018 | J1: 2019 | K1: 2020 | L1: 2021 | M1: 2022 | N1: 2023 | O1: 2024
A2: Madrid | B2: Total - Índice | C2: base 2015=100 | D2: 100.486 | E2: 99.568 | F2: 100 | G2: 101.755 | H2: 103.653 | I2: 106.485 | J2: 110.717 | K2: 111.433 | L2: 112.539 | M2: 115.294 | N2: 118.178 | O2: 122.246
A3: Madrid | B3: Total - Variación anual | C3: % | D3: -3.1 | E3: -0.9 | F3: 0.4 | G3: 1.8 | H3: 1.9 | I3: 2.7 | J3: 4 | K3: 0.6 | L3: 1 | M3: 2.4 | N3: 2.5 | O3: 3.4
A4: Madrid | B4: Vivienda unifamiliar - Índice | C4: base 2015=100 | D4: 99.86 | E4: 99.205 | F4: 100 | G4: 101.305 | H4: 102.999 | I4: 104.718 | J4: 106.716 | K4: 107.279 | L4: 109.206 | M4: 111.966 | N4: 114.383 | O4: 117.708
A5: Madrid | B5: Vivienda unifamiliar - Variación anual | C5: % | D5: -2.6 | E5: -0.7 | F5: 0.8 | G5: 1.3 | H5: 1.7 | I5: 1.7 | J5: 1.9 | K5: 0.5 | L5: 1.8 | M5: 2.5 | N5: 2.2 | O5: 2.9
A6: Madrid | B6: Vivienda colectiva - Índice | C6: base 2015=100 | D6: 100.531 | E6: 99.594 | F6: 100 | G6: 101.787 | H6: 103.701 | I6: 106.612 | J6: 110.998 | K6: 111.724 | L6: 112.774 | M6: 115.529 | N6: 118.443 | O6: 122.559
A7: Madrid | B7: Vivienda colectiva - Variación anual | C7: % | D7: -3.1 | E7: -0.9 | F7: 0.4 | G7: 1.8 | H7: 1.9 | I7: 2.8 | J7: 4.1 | K7: 0.7 | L7: 0.9 | M7: 2.4 | N7: 2.5 | O7: 3.5
A8: Total Nacional | B8: Total - Índice | C8: base 2015=100 | D8: 100.493 | E8: 99.741 | F8: 100 | G8: 101.681 | H8: 103.528 | I8: 106.247 | J8: 109.999 | K8: 110.942 | L8: 112.694 | M8: 115.684 | N8: 118.727 | O8: 122.92
A9: Total Nacional | B9: Total - Variación anual | C9: % | D9: -2.6 | E9: -0.7 | F9: 0.3 | G9: 1.7 | H9: 1.8 | I9: 2.6 | J9: 3.5 | K9: 0.9 | L9: 1.6 | M9: 2.7 | N9: 2.6 | O9: 3.5
A10: Total Nacional | B10: Vivienda unifamiliar - Índice | C10: base 2015=100 | D10: 99.347 | E10: 99.367 | F10: 100 | G10: 101.744 | H10: 103.327 | I10: 105.205 | J10: 106.79 | K10: 107.422 | L10: 109.513 | M10: 112.215 | N10: 114.608 | O10: 118.005
A11: Total Nacional | B11: Vivienda unifamiliar - Variación anual | C11: % | D11: -1.7 | E11: 0 | F11: 0.6 | G11: 1.7 | H11: 1.6 | I11: 1.8 | J11: 1.5 | K11: 0.6 | L11: 1.9 | M11: 2.5 | N11: 2.1 | O11: 3
A12: Total Nacional | B12: Vivienda colectiva - Índice | C12: base 2015=100 | D12: 100.629 | E12: 99.786 | F12: 100 | G12: 101.673 | H12: 103.553 | I12: 106.378 | J12: 110.4 | K12: 111.382 | L12: 113.088 | M12: 116.115 | N12: 119.24 | O12: 123.533
A13: Total Nacional | B13: Vivienda colectiva - Variación anual | C13: % | D13: -2.7 | E13: -0.8 | F13: 0.2 | G13: 1.7 | H13: 1.8 | I13: 2.7 | J13: 3.8 | K13: 0.9 | L13: 1.5 | M13: 2.7 | N13: 2.7 | O13: 3.6
A15: Indicadores derivados (fórmulas) | B15: Madrid | C15: España
A16: Crecimiento acumulado 2015–2024 (%) | B16: =(O2/100-1)*100 -> 22.246 | C16: =(O8/100-1)*100 -> 22.92
A17: Crecimiento acumulado 2019–2024 (%) | B17: =(O2/J2-1)*100 -> 10.413035 | C17: =(O8/J8-1)*100 -> 11.74647
A19: Índice de Precios de Vivienda en Alquiler (IPVA, INE), medias anuales, base 2015 = 100 (tabla 59056). Mide la evolución del precio del alquiler a partir de datos tributarios; la variación suele ser menor que la de los alquileres de contratos nuevos porque incluye los contratos en vigor. Último año: 2024.

Sheet Alquiler_IRAV
A1: periodo | B1: IRAV_variacion_anual_%
A2: 2025-12 | B2: 2.32
A3: 2026-01 | B3: 2.14
A4: 2026-02 | B4: 2.16
A5: 2026-03 | B5: 2.47
A6: 2026-04 | B6: 2.4
A7: 2026-05 | B7: 2.48
A8: 2026-06 | B8: 2.44
A9: 2026-07 | B9: 2.49
A10: 2026-08 | B10: 2.47
A11: 2026-09 | B11: 2.54
A13: Índice de Referencia de Arrendamientos de Vivienda (IRAV, INE, tabla 72975): tasa nacional que limita la actualización anual de los contratos de alquiler. Es un índice de referencia legal, no el precio de mercado.

Sheet Alquiler_SERPAVI_2022
A1: territorio | B1: anio | C1: vc_contratos | D1: vc_renta_media_eur_m2 | E1: vc_renta_p25 | F1: vc_renta_p75 | G1: vc_sup_media_m2 | H1: vc_sup_p25 | I1: vc_sup_p75 | J1: vc_cuantia_media_eur | K1: vc_cuantia_p25 | L1: vc_cuantia_p75 | M1: vu_contratos | N1: vu_renta_media_eur_m2 | O1: vu_renta_p25 | P1: vu_renta_p75 | Q1: vu_sup_media_m2 | R1: vu_sup_p25 | S1: vu_sup_p75 | T1: vu_cuantia_media_eur | U1: vu_cuantia_p25 | V1: vu_cuantia_p75 | W1: VC €/m² ÷ mediana CCAA | X1: ranking VC €/m² (1=mayor) | Y1: VC alquiler anual medio €
A2: Andalucía | B2: 2022 | C2: 210162 | D2: 6.6 | E2: 4.9 | F2: 8.7 | G2: 82 | H2: 65 | I2: 102 | J2: 500 | K2: 398 | L2: 650 | M2: 41838 | N2: 4.5 | O2: 3 | P2: 6.5 | Q2: 140 | R2: 104 | S2: 201 | T2: 499 | U2: 350 | V2: 703 | W2: =IF(D2="","",D2/MEDIAN(D$2:D$20)) -> 1.0153846 | X2: =IF(D2="","",RANK(D2,D$2:D$20,0)) -> 7 | Y2: =IF(J2="","",J2*12) -> 6000
A3: Aragón | B3: 2022 | C3: 74133 | D3: 6.5 | E3: 5 | F3: 8 | G3: 75 | H3: 61 | I3: 94 | J3: 456 | K3: 375 | L3: 560 | M3: 6950 | N3: 3.5 | O3: 2.3 | P3: 4.8 | Q3: 178 | R3: 129 | S3: 251 | T3: 400 | U3: 290 | V3: 540 | W3: =IF(D3="","",D3/MEDIAN(D$2:D$20)) -> 1 | X3: =IF(D3="","",RANK(D3,D$2:D$20,0)) -> 8 | Y3: =IF(J3="","",J3*12) -> 5472
A4: Asturias (Principado de) | B4: 2022 | C4: 52555 | D4: 6.1 | E4: 4.8 | F4: 7.8 | G4: 76 | H4: 61 | I4: 91 | J4: 440 | K4: 355 | L4: 521 | M4: 4078 | N4: 4 | O4: 2.5 | P4: 5.7 | Q4: 144 | R4: 91 | S4: 217 | T4: 390 | U4: 267 | V4: 583 | W4: =IF(D4="","",D4/MEDIAN(D$2:D$20)) -> 0.93846154 | X4: =IF(D4="","",RANK(D4,D$2:D$20,0)) -> 10 | Y4: =IF(J4="","",J4*12) -> 5280
A5: Balears (Illes) | B5: 2022 | C5: 63188 | D5: 8.6 | E5: 6.3 | F5: 11.5 | G5: 84 | H5: 64 | I5: 106 | J5: 671 | K5: 520 | L5: 850 | M5: 34816 | N5: 5.9 | O5: 3.6 | P5: 9.2 | Q5: 167 | R5: 108 | S5: 262 | T5: 675 | U5: 465 | V5: 1000 | W5: =IF(D5="","",D5/MEDIAN(D$2:D$20)) -> 1.3230769 | X5: =IF(D5="","",RANK(D5,D$2:D$20,0)) -> 4 | Y5: =IF(J5="","",J5*12) -> 8052
A6: Canarias | B6: 2022 | C6: 88129 | D6: 7 | E6: 5.4 | F6: 9 | G6: 75 | H6: 59 | I6: 94 | J6: 500 | K6: 400 | L6: 601 | M6: 22297 | N6: 5.6 | O6: 3.2 | P6: 8.4 | Q6: 122 | R6: 74 | S6: 209 | T6: 501 | U6: 400 | V6: 708 | W6: =IF(D6="","",D6/MEDIAN(D$2:D$20)) -> 1.0769231 | X6: =IF(D6="","",RANK(D6,D$2:D$20,0)) -> 6 | Y6: =IF(J6="","",J6*12) -> 6000
A7: Cantabria | B7: 2022 | C7: 24884 | D7: 6.5 | E7: 5.2 | F7: 8.2 | G7: 77 | H7: 64 | I7: 93 | J7: 479 | K7: 400 | L7: 583 | M7: 2420 | N7: 4.7 | O7: 3.4 | P7: 6.1 | Q7: 159 | R7: 106 | S7: 223 | T7: 500 | U7: 389 | V7: 684 | W7: =IF(D7="","",D7/MEDIAN(D$2:D$20)) -> 1 | X7: =IF(D7="","",RANK(D7,D$2:D$20,0)) -> 8 | Y7: =IF(J7="","",J7*12) -> 5748
A8: Castilla y León | B8: 2022 | C8: 101524 | D8: 5.5 | E8: 4.2 | F8: 6.9 | G8: 85 | H8: 69 | I8: 103 | J8: 435 | K8: 350 | L8: 525 | M8: 11554 | N8: 3.5 | O8: 2.4 | P8: 4.7 | Q8: 163 | R8: 116 | S8: 227 | T8: 400 | U8: 280 | V8: 550 | W8: =IF(D8="","",D8/MEDIAN(D$2:D$20)) -> 0.84615385 | X8: =IF(D8="","",RANK(D8,D$2:D$20,0)) -> 11 | Y8: =IF(J8="","",J8*12) -> 5220
A9: Castilla-La Mancha | B9: 2022 | C9: 59292 | D9: 5.3 | E9: 4 | F9: 6.7 | G9: 88 | H9: 71 | I9: 108 | J9: 425 | K9: 344 | L9: 527 | M9: 16210 | N9: 3.4 | O9: 2.3 | P9: 4.8 | Q9: 169 | R9: 130 | S9: 226 | T9: 400 | U9: 300 | V9: 600 | W9: =IF(D9="","",D9/MEDIAN(D$2:D$20)) -> 0.81538462 | X9: =IF(D9="","",RANK(D9,D$2:D$20,0)) -> 14 | Y9: =IF(J9="","",J9*12) -> 5100
A10: Cataluña | B10: 2022 | C10: 442821 | D10: 9 | E10: 6.4 | F10: 12.2 | G10: 74 | H10: 60 | I10: 92 | J10: 648 | K10: 490 | L10: 815 | M10: 57041 | N10: 5.4 | O10: 3.2 | P10: 7.9 | Q10: 174 | R10: 116 | S10: 251 | T10: 623 | U10: 432 | V10: 900 | W10: =IF(D10="","",D10/MEDIAN(D$2:D$20)) -> 1.3846154 | X10: =IF(D10="","",RANK(D10,D$2:D$20,0)) -> 2 | Y10: =IF(J10="","",J10*12) -> 7776
A11: Comunidad Valenciana | B11: 2022 | C11: 215994 | D11: 5.5 | E11: 4.1 | F11: 7.4 | G11: 90 | H11: 71 | I11: 108 | J11: 456 | K11: 354 | L11: 600 | M11: 27795 | N11: 4.7 | O11: 3 | P11: 6.8 | Q11: 150 | R11: 100 | S11: 215 | T11: 475 | U11: 344 | V11: 684 | W11: =IF(D11="","",D11/MEDIAN(D$2:D$20)) -> 0.84615385 | X11: =IF(D11="","",RANK(D11,D$2:D$20,0)) -> 11 | Y11: =IF(J11="","",J11*12) -> 5472
A12: Extremadura | B12: 2022 | C12: 23841 | D12: 4.5 | E12: 3.5 | F12: 5.7 | G12: 92 | H12: 75 | I12: 111 | J12: 395 | K12: 308 | L12: 473 | M12: 5026 | N12: 2.8 | O12: 1.9 | P12: 3.8 | Q12: 159 | R12: 118 | S12: 225 | T12: 300 | U12: 232 | V12: 425 | W12: =IF(D12="","",D12/MEDIAN(D$2:D$20)) -> 0.69230769 | X12: =IF(D12="","",RANK(D12,D$2:D$20,0)) -> 17 | Y12: =IF(J12="","",J12*12) -> 4740
A13: Galicia | B13: 2022 | C13: 124654 | D13: 5.2 | E13: 3.8 | F13: 7.1 | G13: 86 | H13: 69 | I13: 106 | J13: 400 | K13: 325 | L13: 500 | M13: 13677 | N13: 3.2 | O13: 2 | P13: 4.9 | Q13: 193 | R13: 122 | S13: 281 | T13: 372 | U13: 263 | V13: 550 | W13: =IF(D13="","",D13/MEDIAN(D$2:D$20)) -> 0.8 | X13: =IF(D13="","",RANK(D13,D$2:D$20,0)) -> 15 | Y13: =IF(J13="","",J13*12) -> 4800
... A15: Murcia (Región de) | B15: 2022 | C15: 42435 | D15: 4.8 | E15: 3.6 | F15: 6.4 | G15: 96 | H15: 75 | I15: 116 | J15: 404 | K15: 330 | L15: 517 | M15: 656 | N15: 3.8 | O15: 2.8 | P15: 5.1 | Q15: 134 | R15: 96 | S15: 190 | T15: 400 | U15: 300 | V15: 500 | W15: =IF(D15="","",D15/MEDIAN(D$2:D$20)) -> 0.73846154 | X15: =IF(D15="","",RANK(D15,D$2:D$20,0)) -> 16 | Y15: =IF(J15="","",J15*12) -> 4848
A16: Navarra (Com. Foral de) | B16: 2022 | W16: =IF(D16="","",D16/MEDIAN(D$2:D$20)) | X16: =IF(D16="","",RANK(D16,D$2:D$20,0)) | Y16: =IF(J16="","",J16*12)
A17: País Vasco | B17: 2022 | W17: =IF(D17="","",D17/MEDIAN(D$2:D$20)) | X17: =IF(D17="","",RANK(D17,D$2:D$20,0)) | Y17: =IF(J17="","",J17*12)
A18: Rioja (La) | B18: 2022 | C18: 14769 | D18: 5.4 | E18: 4.2 | F18: 6.8 | G18: 87 | H18: 73 | I18: 104 | J18: 450 | K18: 350 | L18: 531 | M18: 2762 | N18: 3.2 | O18: 2.1 | P18: 4.5 | Q18: 215 | R18: 146 | S18: 289 | T18: 362 | U18: 267 | V18: 500 | W18: =IF(D18="","",D18/MEDIAN(D$2:D$20)) -> 0.83076923 | X18: =IF(D18="","",RANK(D18,D$2:D$20,0)) -> 13 | Y18: =IF(J18="","",J18*12) -> 5400
A19: Ceuta | B19: 2022 | C19: 2147 | D19: 8.8 | E19: 7.1 | F19: 11.1 | G19: 75 | H19: 56 | I19: 98 | J19: 650 | K19: 550 | L19: 779 | M19: 5845 | N19: 8.1 | O19: 5.3 | P19: 11.4 | Q19: 66 | R19: 47 | S19: 116 | T19: 550 | U19: 400 | V19: 725 | W19: =IF(D19="","",D19/MEDIAN(D$2:D$20)) -> 1.3538462 | X19: =IF(D19="","",RANK(D19,D$2:D$20,0)) -> 3 | Y19: =IF(J19="","",J19*12) -> 7800
A20: Melilla | B20: 2022 | C20: 2453 | D20: 8.6 | E20: 6.9 | F20: 10.6 | G20: 69 | H20: 53 | I20: 91 | J20: 588 | K20: 500 | L20: 700 | M20: 4078 | N20: 6.4 | O20: 4.3 | P20: 8.7 | Q20: 86 | R20: 59 | S20: 142 | T20: 500 | U20: 390 | V20: 630 | W20: =IF(D20="","",D20/MEDIAN(D$2:D$20)) -> 1.3230769 | X20: =IF(D20="","",RANK(D20,D$2:D$20,0)) -> 4 | Y20: =IF(J20="","",J20*12) -> 7056
A21: España (total) | B21: 2022 | C21: 1983803 | M21: 267719 | W21: =IF(D21="","",D21/MEDIAN(D$2:D$20)) | X21: =IF(D21="","",RANK(D21,D$2:D$20,0)) | Y21: =IF(J21="","",J21*12)
A23: Sistema Estatal de Referencia del Precio del Alquiler de Vivienda (SERPAVI), Ministerio de Vivienda, datos 2022 (publicación de 26/02/2024). vc = vivienda colectiva (pisos), vu = vivienda unifamiliar. Renta en €/m² y mes; cuantía en € al mes. Navarra y País Vasco no figuran (n.d.). La fila "España (total)" solo trae número de contratos. La base completa 2011–2024 con detalle por municipio y distrito (incluidos los distritos de Madrid) existe en el Ministerio, pero no se pudo descargar desde este entorno; ver FUENTES.

Sheet Esfuerzo_Alquiler_Madrid_2022
A1: Esfuerzo del alquiler frente al salario — Comunidad de Madrid, 2022 (indicativo)
A2: Compara la cuantía mensual media de un alquiler de piso (SERPAVI 2022) con el salario bruto individual de 2022 (EES). No es la renta del hogar: es solo un orden de magnitud.
A4: concepto | B4: valor | C4: fuente / fórmula
A5: Alquiler mensual medio, piso (vivienda colectiva) € | B5: =Alquiler_SERPAVI_2022!J14 -> 738 | C5: SERPAVI 2022
A6: Alquiler mensual, percentil 25 € | B6: =Alquiler_SERPAVI_2022!K14 -> 600 | C6: SERPAVI 2022
A7: Alquiler mensual, percentil 75 € | B7: =Alquiler_SERPAVI_2022!L14 -> 945 | C7: SERPAVI 2022
A8: Salario bruto anual medio, Madrid 2022 € | B8: 31230.73 | C8: INE EES tabla 28191 (dato fijo)
A9: Salario bruto anual mediano, Madrid 2022 € | B9: 25203.47 | C9: INE EES tabla 28191 (dato fijo)
A10: Salario bruto anual mediano, España 2022 € | B10: 22383.11 | C10: INE EES tabla 28191 (dato fijo)
A12: Alquiler medio anual € (×12) | B12: =B5*12 -> 8856
A13: Alquiler medio / salario bruto mediano de Madrid (%) | B13: =B5*12/B9*100 -> 35.138019
A14: Alquiler medio / salario bruto medio de Madrid (%) | B14: =B5*12/B8*100 -> 28.356686
A15: Alquiler P25 / salario bruto mediano de Madrid (%) | B15: =B6*12/B9*100 -> 28.567495
A16: Alquiler P75 / salario bruto mediano de Madrid (%) | B16: =B7*12/B9*100 -> 44.993804
A17: Alquiler medio de Madrid / salario bruto mediano de España (%) | B17: =B5*12/B10*100 -> 39.565547
A19: Limitaciones: salario bruto (no neto), individual (no del hogar) y de todos los asalariados; el alquiler SERPAVI 2022 es el de contratos declarados (no solo nuevos). Los porcentajes sirven para comparar territorios o sensibilidades, no como tasa de esfuerzo oficial.

Sheet Idealista_CCAA
A1: territorio | B1: Alquiler €/m² (sep-2026) | C1: alq. var. mensual % | D1: alq. var. trimestral % | E1: alq. var. anual % | F1: alq. máximo histórico | G1: alq. % sobre máximo | H1: Venta €/m² (sep-2026) | I1: venta var. mensual % | J1: venta var. trimestral % | K1: venta var. anual % | L1: Rentabilidad bruta % (alq×12 ÷ venta) | M1: Años de alquiler = precio de venta | N1: ranking alquiler (1 = más caro) | O1: ranking venta (1 = más caro)
A2: España | B2: 15.1 | C2: -0.3 | D2: -0.4 | E2: 5.6 | F2: 15.3 (jul 2026) | G2: -1.2 | H2: 2930 | I2: 0.2 | J2: 0.5 | K2: 11.8 | L2: =IF(OR(B2="",H2=""),"",B2*12/H2*100) -> 6.1843003 | M2: =IF(OR(B2="",H2=""),"",H2/(B2*12)) -> 16.169978
A3: Andalucía | B3: 14.1 | C3: 0.3 | D3: -1.4 | E3: 5.2 | F3: 14.3 (may 2026) | G3: -1.8 | H3: 2952 | I3: 0.5 | J3: 1.7 | K3: 10 | L3: =IF(OR(B3="",H3=""),"",B3*12/H3*100) -> 5.7317073 | M3: =IF(OR(B3="",H3=""),"",H3/(B3*12)) -> 17.446809 | N3: =IF(B3="","",RANK(B3,B$3:B$21,0)) -> 6 | O3: =IF(H3="","",RANK(H3,H$3:H$21,0)) -> 6
A4: Aragón | B4: 11.2 | C4: -0.4 | D4: -0.5 | E4: 9.6 | F4: 11.3 (jul 2026) | G4: -0.7 | H4: 1689 | I4: -0.1 | J4: 1.1 | K4: 13.7 | L4: =IF(OR(B4="",H4=""),"",B4*12/H4*100) -> 7.9573712 | M4: =IF(OR(B4="",H4=""),"",H4/(B4*12)) -> 12.566964 | N4: =IF(B4="","",RANK(B4,B$3:B$21,0)) -> 10 | O4: =IF(H4="","",RANK(H4,H$3:H$21,0)) -> 13
A5: Asturias | B5: 10.9 | C5: 0.4 | D5: 0.2 | E5: 9.3 | F5: 11.7 (jun 2008) | G5: -6.6 | H5: 1892 | I5: 0.2 | J5: 1.9 | K5: 12.6 | L5: =IF(OR(B5="",H5=""),"",B5*12/H5*100) -> 6.9133192 | M5: =IF(OR(B5="",H5=""),"",H5/(B5*12)) -> 14.464832 | N5: =IF(B5="","",RANK(B5,B$3:B$21,0)) -> 11 | O5: =IF(H5="","",RANK(H5,H$3:H$21,0)) -> 12
A6: Baleares | B6: 20.2 | C6: 1.2 | D6: 0.8 | E6: 3.6 | F6: 20.3 (may 2026) | G6: -0.2 | H6: 5593 | I6: 0 | J6: 0.7 | K6: 4.1 | L6: =IF(OR(B6="",H6=""),"",B6*12/H6*100) -> 4.3339889 | M6: =IF(OR(B6="",H6=""),"",H6/(B6*12)) -> 23.073432 | N6: =IF(B6="","",RANK(B6,B$3:B$21,0)) -> 2 | O6: =IF(H6="","",RANK(H6,H$3:H$21,0)) -> 1
A7: Canarias | B7: 15.2 | C7: -1 | D7: -1 | E7: 4.3 | F7: 15.5 (jul 2026) | G7: -1.9 | H7: 3349 | I7: 0.4 | J7: -0.4 | K7: 6.3 | L7: =IF(OR(B7="",H7=""),"",B7*12/H7*100) -> 5.4464019 | M7: =IF(OR(B7="",H7=""),"",H7/(B7*12)) -> 18.360746 | N7: =IF(B7="","",RANK(B7,B$3:B$21,0)) -> 4 | O7: =IF(H7="","",RANK(H7,H$3:H$21,0)) -> 4
A8: Cantabria | B8: 11.8 | C8: -0.3 | D8: 1.6 | E8: 5.4 | F8: 13.8 (jul 2007) | G8: -14.3 | H8: 2408 | I8: 0.7 | J8: 3.4 | K8: 14.6 | L8: =IF(OR(B8="",H8=""),"",B8*12/H8*100) -> 5.8803987 | M8: =IF(OR(B8="",H8=""),"",H8/(B8*12)) -> 17.00565 | N8: =IF(B8="","",RANK(B8,B$3:B$21,0)) -> 8 | O8: =IF(H8="","",RANK(H8,H$3:H$21,0)) -> 9
A9: Castilla y León | B9: 9.7 | C9: 0.1 | D9: -0.9 | E9: 6.7 | F9: 9.8 (jun 2026) | G9: -0.9 | H9: 1386 | I9: -0.2 | J9: 1.5 | K9: 12 | L9: =IF(OR(B9="",H9=""),"",B9*12/H9*100) -> 8.3982684 | M9: =IF(OR(B9="",H9=""),"",H9/(B9*12)) -> 11.907216 | N9: =IF(B9="","",RANK(B9,B$3:B$21,0)) -> 14 | O9: =IF(H9="","",RANK(H9,H$3:H$21,0)) -> 17
A10: Castilla-La Mancha | B10: 8.8 | C10: -0.1 | D10: 0.1 | E10: 8.3 | F10: 8.9 (jul 2026) | G10: -1 | H10: 1157 | I10: 0 | J10: 1.5 | K10: 15.5 | L10: =IF(OR(B10="",H10=""),"",B10*12/H10*100) -> 9.1270527 | M10: =IF(OR(B10="",H10=""),"",H10/(B10*12)) -> 10.956439 | N10: =IF(B10="","",RANK(B10,B$3:B$21,0)) -> 17 | O10: =IF(H10="","",RANK(H10,H$3:H$21,0)) -> 18
A11: Cataluña | B11: 15.9 | C11: -0.3 | D11: 0.3 | E11: 2.2 | F11: 16.0 (jul 2026) | G11: -1 | H11: 3092 | I11: 0.4 | J11: 0.9 | K11: 12.2 | L11: =IF(OR(B11="",H11=""),"",B11*12/H11*100) -> 6.1707633 | M11: =IF(OR(B11="",H11=""),"",H11/(B11*12)) -> 16.205451 | N11: =IF(B11="","",RANK(B11,B$3:B$21,0)) -> 3 | O11: =IF(H11="","",RANK(H11,H$3:H$21,0)) -> 5
A12: Ceuta | H12: 2698 | I12: -2 | J12: -2.1 | K12: 13.1 | L12: =IF(OR(B12="",H12=""),"",B12*12/H12*100) | M12: =IF(OR(B12="",H12=""),"",H12/(B12*12)) | N12: =IF(B12="","",RANK(B12,B$3:B$21,0)) | O12: =IF(H12="","",RANK(H12,H$3:H$21,0)) -> 7
A13: Comunitat Valenciana | B13: 13.2 | C13: -0.4 | D13: 0.7 | E13: 6 | F13: 13.3 (ago 2026) | G13: -0.4 | H13: 2497 | I13: 0.3 | J13: 1.3 | K13: 10.1 | L13: =IF(OR(B13="",H13=""),"",B13*12/H13*100) -> 6.3436123 | M13: =IF(OR(B13="",H13=""),"",H13/(B13*12)) -> 15.763889 | N13: =IF(B13="","",RANK(B13,B$3:B$21,0)) -> 7 | O13: =IF(H13="","",RANK(H13,H$3:H$21,0)) -> 8
A14: Euskadi | B14: 15 | C14: 0.8 | D14: 0.3 | E14: -0.3 | F14: 15.1 (ago 2025) | G14: -0.8 | H14: 3805 | I14: 0.5 | J14: 2.2 | K14: 11.2 | L14: =IF(OR(B14="",H14=""),"",B14*12/H14*100) -> 4.7306176 | M14: =IF(OR(B14="",H14=""),"",H14/(B14*12)) -> 21.138889 | N14: =IF(B14="","",RANK(B14,B$3:B$21,0)) -> 5 | O14: =IF(H14="","",RANK(H14,H$3:H$21,0)) -> 3
A15: Extremadura | B15: 7.7 | C15: -0.6 | D15: 0.4 | E15: 5.7 | F15: 7.8 (ago 2026) | G15: -0.6 | H15: 1049 | I15: 0 | J15: -0.6 | K15: 7.6 | L15: =IF(OR(B15="",H15=""),"",B15*12/H15*100) -> 8.8083889 | M15: =IF(OR(B15="",H15=""),"",H15/(B15*12)) -> 11.352814 | N15: =IF(B15="","",RANK(B15,B$3:B$21,0)) -> 18 | O15: =IF(H15="","",RANK(H15,H$3:H$21,0)) -> 19
A16: Galicia | B16: 9.9 | C16: -0.2 | D16: 0.2 | E16: 4.7 | F16: 10.0 (jul 2026) | G16: -1.1 | H16: 1671 | I16: 0.3 | J16: 1.4 | K16: 10.3 | L16: =IF(OR(B16="",H16=""),"",B16*12/H16*100) -> 7.1095153 | M16: =IF(OR(B16="",H16=""),"",H16/(B16*12)) -> 14.065657 | N16: =IF(B16="","",RANK(B16,B$3:B$21,0)) -> 13 | O16: =IF(H16="","",RANK(H16,H$3:H$21,0)) -> 15
A17: La Rioja | B17: 9.5 | C17: -1.7 | D17: -0.9 | E17: 5.3 | F17: 9.7 (jul 2026) | G17: -2 | H17: 1515 | I17: -0.2 | J17: -0.3 | K17: 6.5 | L17: =IF(OR(B17="",H17=""),"",B17*12/H17*100) -> 7.5247525 | M17: =IF(OR(B17="",H17=""),"",H17/(B17*12)) -> 13.289474 | N17: =IF(B17="","",RANK(B17,B$3:B$21,0)) -> 15 | O17: =IF(H17="","",RANK(H17,H$3:H$21,0)) -> 16
A18: Madrid Comunidad | B18: 21.6 | C18: 0.5 | D18: 1.4 | E18: 5.7 | F18: 21.6 (sep 2026) | G18: 0 | H18: 5065 | I18: 0.1 | J18: -1.7 | K18: 6.9 | L18: =IF(OR(B18="",H18=""),"",B18*12/H18*100) -> 5.1174729 | M18: =IF(OR(B18="",H18=""),"",H18/(B18*12)) -> 19.540895 | N18: =IF(B18="","",RANK(B18,B$3:B$21,0)) -> 1 | O18: =IF(H18="","",RANK(H18,H$3:H$21,0)) -> 2
A19: Melilla | B19: 11.3 | C19: -2.8 | D19: -3.2 | E19: 8.6 | F19: 11.7 (jul 2026) | G19: -3.6 | H19: 2086 | I19: 1.2 | J19: 2.3 | K19: 4 | L19: =IF(OR(B19="",H19=""),"",B19*12/H19*100) -> 6.5004794 | M19: =IF(OR(B19="",H19=""),"",H19/(B19*12)) -> 15.383481 | N19: =IF(B19="","",RANK(B19,B$3:B$21,0)) -> 9 | O19: =IF(H19="","",RANK(H19,H$3:H$21,0)) -> 10
A20: Murcia Región | B20: 9.5 | C20: -0.6 | D20: 1.3 | E20: 4.8 | F20: 9.6 (jul 2026) | G20: -0.8 | H20: 1689 | I20: 0.5 | J20: 1.8 | K20: 13.9 | L20: =IF(OR(B20="",H20=""),"",B20*12/H20*100) -> 6.749556 | M20: =IF(OR(B20="",H20=""),"",H20/(B20*12)) -> 14.815789 | N20: =IF(B20="","",RANK(B20,B$3:B$21,0)) -> 15 | O20: =IF(H20="","",RANK(H20,H$3:H$21,0)) -> 13
A21: Navarra | B21: 10.6 | C21: -0.8 | D21: -1.7 | E21: 0.9 | F21: 10.8 (dic 2025) | G21: -1.7 | H21: 1980 | I21: 0.2 | J21: -0.7 | K21: 10.1 | L21: =IF(OR(B21="",H21=""),"",B21*12/H21*100) -> 6.4242424 | M21: =IF(OR(B21="",H21=""),"",H21/(B21*12)) -> 15.566038 | N21: =IF(B21="","",RANK(B21,B$3:B$21,0)) -> 12 | O21: =IF(H21="","",RANK(H21,H$3:H$21,0)) -> 11
A23: Idealista, informes de precios de la sala de prensa (septiembre 2026): precio medio de OFERTA en anuncios, €/m² construido. No son precios de cierre ni contratos firmados. Ceuta no figura en la tabla de alquiler. La rentabilidad bruta y los años de alquiler son cálculos propios (amarillo): no descuentan impuestos, gastos, impagos ni vacíos, y comparan precios de oferta. Idealista cambió de metodología en julio de 2026: las series anteriores pueden no ser comparables.

Sheet Idealista_Provincias
A1: CCAA | B1: provincia | C1: tipo | D1: Alquiler €/m² | E1: alq. var. mensual % | F1: alq. var. trimestral % | G1: alq. var. anual % | H1: Venta €/m² | I1: venta var. mensual % | J1: venta var. trimestral % | K1: venta var. anual % | L1: Rentabilidad bruta % | M1: Años de alquiler | N1: ranking alquiler (1 = más caro) | O1: ranking venta (1 = más caro)
A2: Andalucía | B2: Almería | C2: provincia | D2: 9 | E2: -0.3 | F2: 0.1 | G2: 4.7 | H2: 1673 | I2: 0.3 | J2: 1.6 | K2: 14.3 | L2: =IF(OR(D2="",H2=""),"",D2*12/H2*100) -> 6.4554692 | M2: =IF(OR(D2="",H2=""),"",H2/(D2*12)) -> 15.490741 | N2: =IF(D2="","",RANK(D2,D$2:D$53,0)) -> 35 | O2: =IF(H2="","",RANK(H2,H$2:H$53,0)) -> 30
A3: Andalucía | B3: Cádiz | C3: provincia | D3: 11.6 | E3: -0.9 | F3: -4.1 | G3: 5.2 | H3: 2539 | I3: 0.6 | J3: 2.1 | K3: 9.9 | L3: =IF(OR(D3="",H3=""),"",D3*12/H3*100) -> 5.4824734 | M3: =IF(OR(D3="",H3=""),"",H3/(D3*12)) -> 18.239943 | N3: =IF(D3="","",RANK(D3,D$2:D$53,0)) -> 17 | O3: =IF(H3="","",RANK(H3,H$2:H$53,0)) -> 13
A4: Andalucía | B4: Córdoba | C4: provincia | D4: 9 | E4: -0.4 | F4: -1.2 | G4: 4 | H4: 1420 | I4: 0.5 | J4: -0.3 | K4: 9.3 | L4: =IF(OR(D4="",H4=""),"",D4*12/H4*100) -> 7.6056338 | M4: =IF(OR(D4="",H4=""),"",H4/(D4*12)) -> 13.148148 | N4: =IF(D4="","",RANK(D4,D$2:D$53,0)) -> 35 | O4: =IF(H4="","",RANK(H4,H$2:H$53,0)) -> 36
A5: Andalucía | B5: Granada | C5: provincia | D5: 10.3 | E5: -0.6 | F5: 0.2 | G5: 3.6 | H5: 1890 | I5: 1 | J5: 1.7 | K5: 13 | L5: =IF(OR(D5="",H5=""),"",D5*12/H5*100) -> 6.5396825 | M5: =IF(OR(D5="",H5=""),"",H5/(D5*12)) -> 15.291262 | N5: =IF(D5="","",RANK(D5,D$2:D$53,0)) -> 23 | O5: =IF(H5="","",RANK(H5,H$2:H$53,0)) -> 22
A6: Andalucía | B6: Huelva | C6: provincia | D6: 10.1 | E6: -3.5 | F6: -8.4 | G6: 7.8 | H6: 1817 | I6: 0.8 | J6: 2 | K6: 11.6 | L6: =IF(OR(D6="",H6=""),"",D6*12/H6*100) -> 6.6703357 | M6: =IF(OR(D6="",H6=""),"",H6/(D6*12)) -> 14.991749 | N6: =IF(D6="","",RANK(D6,D$2:D$53,0)) -> 25 | O6: =IF(H6="","",RANK(H6,H$2:H$53,0)) -> 23
A7: Andalucía | B7: Jaén | C7: provincia | D7: 7 | E7: -0.8 | F7: -5.2 | G7: 1.6 | H7: 879 | I7: 0 | J7: -0.9 | K7: 3.1 | L7: =IF(OR(D7="",H7=""),"",D7*12/H7*100) -> 9.556314 | M7: =IF(OR(D7="",H7=""),"",H7/(D7*12)) -> 10.464286 | N7: =IF(D7="","",RANK(D7,D$2:D$53,0)) -> 51 | O7: =IF(H7="","",RANK(H7,H$2:H$53,0)) -> 51
A8: Andalucía | B8: Málaga | C8: provincia | D8: 18.8 | E8: 0.4 | F8: 1.2 | G8: 5.7 | H8: 4317 | I8: 0.5 | J8: 1.9 | K8: 6.6 | L8: =IF(OR(D8="",H8=""),"",D8*12/H8*100) -> 5.2258513 | M8: =IF(OR(D8="",H8=""),"",H8/(D8*12)) -> 19.135638 | N8: =IF(D8="","",RANK(D8,D$2:D$53,0)) -> 3 | O8: =IF(H8="","",RANK(H8,H$2:H$53,0)) -> 4
A9: Andalucía | B9: Sevilla | C9: provincia | D9: 12.2 | E9: -0.4 | F9: 0.2 | G9: 4.1 | H9: 2080 | I9: 0.3 | J9: 0.7 | K9: 14.7 | L9: =IF(OR(D9="",H9=""),"",D9*12/H9*100) -> 7.0384615 | M9: =IF(OR(D9="",H9=""),"",H9/(D9*12)) -> 14.20765 | N9: =IF(D9="","",RANK(D9,D$2:D$53,0)) -> 12 | O9: =IF(H9="","",RANK(H9,H$2:H$53,0)) -> 17
A10: Aragón | B10: Huesca | C10: provincia | D10: 9.5 | E10: -1.1 | F10: 0.7 | G10: 10.2 | H10: 1779 | I10: -0.3 | J10: 5.7 | K10: 12.2 | L10: =IF(OR(D10="",H10=""),"",D10*12/H10*100) -> 6.4080944 | M10: =IF(OR(D10="",H10=""),"",H10/(D10*12)) -> 15.605263 | N10: =IF(D10="","",RANK(D10,D$2:D$53,0)) -> 30 | O10: =IF(H10="","",RANK(H10,H$2:H$53,0)) -> 24
A11: Aragón | B11: Teruel | C11: provincia | D11: 8 | E11: -0.3 | F11: 4.5 | G11: 3.6 | H11: 889 | I11: 0.1 | J11: -0.4 | K11: 11.2 | L11: =IF(OR(D11="",H11=""),"",D11*12/H11*100) -> 10.79865 | M11: =IF(OR(D11="",H11=""),"",H11/(D11*12)) -> 9.2604167 | N11: =IF(D11="","",RANK(D11,D$2:D$53,0)) -> 46 | O11: =IF(H11="","",RANK(H11,H$2:H$53,0)) -> 50
A12: Aragón | B12: Zaragoza | C12: provincia | D12: 11.7 | E12: -0.1 | F12: -0.1 | G12: 9.7 | H12: 1777 | I12: 0 | J12: 0.1 | K12: 14.4 | L12: =IF(OR(D12="",H12=""),"",D12*12/H12*100) -> 7.9009567 | M12: =IF(OR(D12="",H12=""),"",H12/(D12*12)) -> 12.656695 | N12: =IF(D12="","",RANK(D12,D$2:D$53,0)) -> 16 | O12: =IF(H12="","",RANK(H12,H$2:H$53,0)) -> 25
A13: Asturias | B13: Asturias | C13: CCAA uniprovincial | D13: 10.9 | E13: 0.4 | F13: 0.2 | G13: 9.3 | H13: 1892 | I13: 0.2 | J13: 1.9 | K13: 12.6 | L13: =IF(OR(D13="",H13=""),"",D13*12/H13*100) -> 6.9133192 | M13: =IF(OR(D13="",H13=""),"",H13/(D13*12)) -> 14.464832 | N13: =IF(D13="","",RANK(D13,D$2:D$53,0)) -> 20 | O13: =IF(H13="","",RANK(H13,H$2:H$53,0)) -> 21
... A35: Cataluña | B35: Tarragona | C35: provincia | D35: 9.9 | E35: -0.2 | F35: -2.2 | G35: 2.9 | H35: 1922 | I35: 0.8 | J35: 1.6 | K35: 10.2 | L35: =IF(OR(D35="",H35=""),"",D35*12/H35*100) -> 6.1810614 | M35: =IF(OR(D35="",H35=""),"",H35/(D35*12)) -> 16.178451 | N35: =IF(D35="","",RANK(D35,D$2:D$53,0)) -> 27 | O35: =IF(H35="","",RANK(H35,H$2:H$53,0)) -> 20
A36: Ceuta | B36: Ceuta | C36: ciudad autónoma | H36: 2698 | I36: -2 | J36: -2.1 | K36: 13.1 | L36: =IF(OR(D36="",H36=""),"",D36*12/H36*100) | M36: =IF(OR(D36="",H36=""),"",H36/(D36*12)) | N36: =IF(D36="","",RANK(D36,D$2:D$53,0)) | O36: =IF(H36="","",RANK(H36,H$2:H$53,0)) -> 11
A37: Comunitat Valenciana | B37: Alicante | C37: provincia | D37: 12.7 | E37: 0.3 | F37: 1.3 | G37: 7.1 | H37: 2767 | I37: 0.3 | J37: 1.3 | K37: 7.8 | L37: =IF(OR(D37="",H37=""),"",D37*12/H37*100) -> 5.5077701 | M37: =IF(OR(D37="",H37=""),"",H37/(D37*12)) -> 18.156168 | N37: =IF(D37="","",RANK(D37,D$2:D$53,0)) -> 11 | O37: =IF(H37="","",RANK(H37,H$2:H$53,0)) -> 10
A38: Comunitat Valenciana | B38: Castellón | C38: provincia | D38: 9.4 | E38: -1.3 | F38: 2.4 | G38: 9.5 | H38: 1663 | I38: 1.1 | J38: 3.3 | K38: 11.9 | L38: =IF(OR(D38="",H38=""),"",D38*12/H38*100) -> 6.7829224 | M38: =IF(OR(D38="",H38=""),"",H38/(D38*12)) -> 14.742908 | N38: =IF(D38="","",RANK(D38,D$2:D$53,0)) -> 34 | O38: =IF(H38="","",RANK(H38,H$2:H$53,0)) -> 31
A39: Comunitat Valenciana | B39: València | C39: provincia | D39: 14.2 | E39: -0.5 | F39: 0.4 | G39: 5 | H39: 2208 | I39: 0 | J39: 0.6 | K39: 15.1 | L39: =IF(OR(D39="",H39=""),"",D39*12/H39*100) -> 7.7173913 | M39: =IF(OR(D39="",H39=""),"",H39/(D39*12)) -> 12.957746 | N39: =IF(D39="","",RANK(D39,D$2:D$53,0)) -> 9 | O39: =IF(H39="","",RANK(H39,H$2:H$53,0)) -> 15
A40: Euskadi | B40: Guipúzcoa | C40: provincia | D40: 16.1 | E40: 1.4 | F40: 2.3 | G40: -3 | H40: 4743 | I40: 1.2 | J40: 2.9 | K40: 12.7 | L40: =IF(OR(D40="",H40=""),"",D40*12/H40*100) -> 4.0733713 | M40: =IF(OR(D40="",H40=""),"",H40/(D40*12)) -> 24.549689 | N40: =IF(D40="","",RANK(D40,D$2:D$53,0)) -> 5 | O40: =IF(H40="","",RANK(H40,H$2:H$53,0)) -> 3
A41: Euskadi | B41: Vizcaya | C41: provincia | D41: 15.3 | E41: 0.6 | F41: 0 | G41: 3.2 | H41: 3588 | I41: -0.1 | J41: 1 | K41: 9.6 | L41: =IF(OR(D41="",H41=""),"",D41*12/H41*100) -> 5.1170569 | M41: =IF(OR(D41="",H41=""),"",H41/(D41*12)) -> 19.542484 | N41: =IF(D41="","",RANK(D41,D$2:D$53,0)) -> 6 | O41: =IF(H41="","",RANK(H41,H$2:H$53,0)) -> 5
A42: Euskadi | B42: Álava | C42: provincia | D42: 12 | E42: -0.2 | F42: -2.2 | G42: -4 | H42: 2652 | I42: -0.9 | J42: -0.5 | K42: 6 | L42: =IF(OR(D42="",H42=""),"",D42*12/H42*100) -> 5.4298643 | M42: =IF(OR(D42="",H42=""),"",H42/(D42*12)) -> 18.416667 | N42: =IF(D42="","",RANK(D42,D$2:D$53,0)) -> 13 | O42: =IF(H42="","",RANK(H42,H$2:H$53,0)) -> 12
A43: Extremadura | B43: Badajoz | C43: provincia | D43: 7.8 | E43: 0.2 | F43: 2 | G43: 7 | H43: 1069 | I43: 0.2 | J43: 0.1 | K43: 10.4 | L43: =IF(OR(D43="",H43=""),"",D43*12/H43*100) -> 8.7558466 | M43: =IF(OR(D43="",H43=""),"",H43/(D43*12)) -> 11.42094 | N43: =IF(D43="","",RANK(D43,D$2:D$53,0)) -> 48 | O43: =IF(H43="","",RANK(H43,H$2:H$53,0)) -> 45
A44: Extremadura | B44: Cáceres | C44: provincia | D44: 7.7 | E44: -1.3 | F44: -1.2 | G44: 4.5 | H44: 1026 | I44: -0.2 | J44: -1.4 | K44: 4.6 | L44: =IF(OR(D44="",H44=""),"",D44*12/H44*100) -> 9.005848 | M44: =IF(OR(D44="",H44=""),"",H44/(D44*12)) -> 11.103896 | N44: =IF(D44="","",RANK(D44,D$2:D$53,0)) -> 49 | O44: =IF(H44="","",RANK(H44,H$2:H$53,0)) -> 46
A45: Galicia | B45: A Coruña | C45: provincia | D45: 9.9 | E45: 0.1 | F45: 2.1 | G45: 2.5 | H45: 1773 | I45: 0.2 | J45: 1.4 | K45: 13.3 | L45: =IF(OR(D45="",H45=""),"",D45*12/H45*100) -> 6.7005076 | M45: =IF(OR(D45="",H45=""),"",H45/(D45*12)) -> 14.924242 | N45: =IF(D45="","",RANK(D45,D$2:D$53,0)) -> 27 | O45: =IF(H45="","",RANK(H45,H$2:H$53,0)) -> 26
A46: Galicia | B46: Lugo | C46: provincia | D46: 8.1 | E46: -1 | F46: -0.2 | G46: 7.7 | H46: 1212 | I46: 0.3 | J46: 3.1 | K46: 7.6 | L46: =IF(OR(D46="",H46=""),"",D46*12/H46*100) -> 8.019802 | M46: =IF(OR(D46="",H46=""),"",H46/(D46*12)) -> 12.469136 | N46: =IF(D46="","",RANK(D46,D$2:D$53,0)) -> 44 | O46: =IF(H46="","",RANK(H46,H$2:H$53,0)) -> 40
A47: Galicia | B47: Ourense | C47: provincia | D47: 8.2 | E47: 0.1 | F47: 2.9 | G47: 6.6 | H47: 960 | I47: 0.9 | J47: 0.2 | K47: -3.6 | L47: =IF(OR(D47="",H47=""),"",D47*12/H47*100) -> 10.25 | M47: =IF(OR(D47="",H47=""),"",H47/(D47*12)) -> 9.7560976 | N47: =IF(D47="","",RANK(D47,D$2:D$53,0)) -> 42 | O47: =IF(H47="","",RANK(H47,H$2:H$53,0)) -> 48
A48: Galicia | B48: Pontevedra | C48: provincia | D48: 11 | E48: -1.4 | F48: -2.5 | G48: 7.8 | H48: 2056 | I48: 0.7 | J48: 1 | K48: 11.3 | L48: =IF(OR(D48="",H48=""),"",D48*12/H48*100) -> 6.4202335 | M48: =IF(OR(D48="",H48=""),"",H48/(D48*12)) -> 15.575758 | N48: =IF(D48="","",RANK(D48,D$2:D$53,0)) -> 19 | O48: =IF(H48="","",RANK(H48,H$2:H$53,0)) -> 18
... A53: Navarra | B53: Navarra | C53: CCAA uniprovincial | D53: 10.6 | E53: -0.8 | F53: -1.7 | G53: 0.9 | H53: 1980 | I53: 0.2 | J53: -0.7 | K53: 10.1 | L53: =IF(OR(D53="",H53=""),"",D53*12/H53*100) -> 6.4242424 | M53: =IF(OR(D53="",H53=""),"",H53/(D53*12)) -> 15.566038 | N53: =IF(D53="","",RANK(D53,D$2:D$53,0)) -> 21 | O53: =IF(H53="","",RANK(H53,H$2:H$53,0)) -> 19
A55: Idealista (sep-2026), 50 provincias y 2 ciudades autónomas. Las CCAA uniprovinciales repiten los valores de la comunidad. Madrid provincia = Comunidad de Madrid. Precios de oferta, no de cierre. Ceuta solo tiene venta.

Sheet Idealista_Madrid_Distritos
A1: distrito | B1: Alquiler €/m² | C1: alq. mensual % | D1: alq. trimestral % | E1: alq. anual % | F1: alq. máximo histórico | G1: Venta €/m² | H1: venta mensual % | I1: venta trimestral % | J1: venta anual % | K1: venta máximo histórico | L1: Rentabilidad bruta % | M1: Años de alquiler | N1: Alquiler piso de 70 m² (€/mes) | O1: alquiler ÷ media de la ciudad | P1: ranking alquiler (1 = más caro) | Q1: ranking venta (1 = más caro)
A2: Madrid (ciudad) | B2: 23.4 | C2: 0.5 | D2: 1.2 | E2: 4.8 | F2: 23.4 (sep 2026) | G2: 6458 | H2: -0.2 | I2: -1.8 | J2: 2.4 | K2: 6619 (abr 2026) | L2: =B2*12/G2*100 -> 4.3480954 | M2: =G2/(B2*12) -> 22.998575 | N2: =B2*70 -> 1638 | O2: =B2/B$2 -> 1
A3: Arganzuela | B3: 22.4 | C3: 0.3 | D3: 0.4 | E3: 6.3 | F3: 22.4 (sep 2026) | G3: 6384 | H3: 0.6 | I3: 0 | J3: 6.4 | K3: 6410 (may 2026) | L3: =B3*12/G3*100 -> 4.2105263 | M3: =G3/(B3*12) -> 23.75 | N3: =B3*70 -> 1568 | O3: =B3/B$2 -> 0.95726496 | P3: =RANK(B3,B$3:B$23,0) -> 7 | Q3: =RANK(G3,G$3:G$23,0) -> 6
A4: Barajas | B4: 17.2 | C4: -0.2 | D4: -0.5 | E4: 5.1 | F4: 17.6 (may 2026) | G4: 4971 | H4: -3.9 | I4: -1.6 | J4: 8.8 | K4: 5171 (ago 2026) | L4: =B4*12/G4*100 -> 4.1520821 | M4: =G4/(B4*12) -> 24.084302 | N4: =B4*70 -> 1204 | O4: =B4/B$2 -> 0.73504274 | P4: =RANK(B4,B$3:B$23,0) -> 19 | Q4: =RANK(G4,G$3:G$23,0) -> 12
A5: Barrio de Salamanca | B5: 28.5 | C5: 0.5 | D5: 1.5 | E5: 5 | F5: 28.5 (sep 2026) | G5: 10865 | H5: 0.2 | I5: -0.9 | J5: -1.2 | K5: 11328 (mar 2026) | L5: =B5*12/G5*100 -> 3.147722 | M5: =G5/(B5*12) -> 31.769006 | N5: =B5*70 -> 1995 | O5: =B5/B$2 -> 1.2179487 | P5: =RANK(B5,B$3:B$23,0) -> 1 | Q5: =RANK(G5,G$3:G$23,0) -> 1
A6: Carabanchel | B6: 19.3 | C6: 1.3 | D6: 4.4 | E6: 10.4 | F6: 19.3 (sep 2026) | G6: 3829 | H6: -0.3 | I6: 0 | J6: 9.4 | K6: 3842 (ago 2026) | L6: =B6*12/G6*100 -> 6.0485767 | M6: =G6/(B6*12) -> 16.532815 | N6: =B6*70 -> 1351 | O6: =B6/B$2 -> 0.82478632 | P6: =RANK(B6,B$3:B$23,0) -> 13 | Q6: =RANK(G6,G$3:G$23,0) -> 18
A7: Centro | B7: 26.1 | C7: 0.5 | D7: 0.9 | E7: 2 | F7: 26.1 (sep 2026) | G7: 7771 | H7: 0.3 | I7: 0 | J7: 3.7 | K7: 7794 (may 2026) | L7: =B7*12/G7*100 -> 4.0303693 | M7: =G7/(B7*12) -> 24.811622 | N7: =B7*70 -> 1827 | O7: =B7/B$2 -> 1.1153846 | P7: =RANK(B7,B$3:B$23,0) -> 2 | Q7: =RANK(G7,G$3:G$23,0) -> 5
A8: Chamartín | B8: 23.7 | C8: 0.6 | D8: 1 | E8: 2.9 | F8: 23.7 (sep 2026) | G8: 8127 | H8: -1.2 | I8: -2.1 | J8: 4.6 | K8: 8343 (may 2026) | L8: =B8*12/G8*100 -> 3.4994463 | M8: =G8/(B8*12) -> 28.575949 | N8: =B8*70 -> 1659 | O8: =B8/B$2 -> 1.0128205 | P8: =RANK(B8,B$3:B$23,0) -> 5 | Q8: =RANK(G8,G$3:G$23,0) -> 4
A9: Chamberí | B9: 26 | C9: 1.2 | D9: 1.3 | E9: 3.5 | F9: 26.0 (sep 2026) | G9: 9159 | H9: -0.5 | I9: -1 | J9: 2.6 | K9: 9359 (mar 2026) | L9: =B9*12/G9*100 -> 3.4064854 | M9: =G9/(B9*12) -> 29.355769 | N9: =B9*70 -> 1820 | O9: =B9/B$2 -> 1.1111111 | P9: =RANK(B9,B$3:B$23,0) -> 3 | Q9: =RANK(G9,G$3:G$23,0) -> 2
A10: Ciudad Lineal | B10: 20.1 | C10: 0.4 | D10: 1.8 | E10: 5.2 | F10: 20.1 (sep 2026) | G10: 5242 | H10: 0.8 | I10: -1.5 | J10: 8 | K10: 5327 (may 2026) | L10: =B10*12/G10*100 -> 4.6012972 | M10: =G10/(B10*12) -> 21.733002 | N10: =B10*70 -> 1407 | O10: =B10/B$2 -> 0.85897436 | P10: =RANK(B10,B$3:B$23,0) -> 9 | Q10: =RANK(G10,G$3:G$23,0) -> 11
A11: Fuencarral | B11: 18.9 | C11: 1 | D11: 0.6 | E11: 6.8 | F11: 18.9 (sep 2026) | G11: 5593 | H11: -0.3 | I11: -0.5 | J11: 5.5 | K11: 5645 (jul 2026) | L11: =B11*12/G11*100 -> 4.0550688 | M11: =G11/(B11*12) -> 24.660494 | N11: =B11*70 -> 1323 | O11: =B11/B$2 -> 0.80769231 | P11: =RANK(B11,B$3:B$23,0) -> 15 | Q11: =RANK(G11,G$3:G$23,0) -> 9
A12: Hortaleza | B12: 19.5 | C12: 3.1 | D12: 4 | E12: 9.3 | F12: 19.5 (sep 2026) | G12: 5440 | H12: -0.8 | I12: -2.6 | J12: 7 | K12: 5586 (jun 2026) | L12: =B12*12/G12*100 -> 4.3014706 | M12: =G12/(B12*12) -> 23.247863 | N12: =B12*70 -> 1365 | O12: =B12/B$2 -> 0.83333333 | P12: =RANK(B12,B$3:B$23,0) -> 11 | Q12: =RANK(G12,G$3:G$23,0) -> 10
A13: Latina | B13: 19.5 | C13: 0.1 | D13: 4.1 | E13: 7.6 | F13: 19.6 (jul 2026) | G13: 4045 | H13: 0 | I13: 1.2 | J13: 6.5 | K13: 4045 (sep 2026) | L13: =B13*12/G13*100 -> 5.7849197 | M13: =G13/(B13*12) -> 17.286325 | N13: =B13*70 -> 1365 | O13: =B13/B$2 -> 0.83333333 | P13: =RANK(B13,B$3:B$23,0) -> 11 | Q13: =RANK(G13,G$3:G$23,0) -> 15
A14: Moncloa | B14: 21.8 | C14: -0.5 | D14: -0.7 | E14: 1 | F14: 22.1 (may 2026) | G14: 6317 | H14: -0.2 | I14: -0.5 | J14: 1.3 | K14: 6401 (abr 2026) | L14: =B14*12/G14*100 -> 4.1412063 | M14: =G14/(B14*12) -> 24.147554 | N14: =B14*70 -> 1526 | O14: =B14/B$2 -> 0.93162393 | P14: =RANK(B14,B$3:B$23,0) -> 8 | Q14: =RANK(G14,G$3:G$23,0) -> 7
... A23: Villaverde | B23: 18.2 | C23: 1.8 | D23: 1.5 | E23: 14.5 | F23: 18.2 (sep 2026) | G23: 3365 | H23: 1.9 | I23: 3.4 | J23: 23.7 | K23: 3365 (sep 2026) | L23: =B23*12/G23*100 -> 6.4903418 | M23: =G23/(B23*12) -> 15.407509 | N23: =B23*70 -> 1274 | O23: =B23/B$2 -> 0.77777778 | P23: =RANK(B23,B$3:B$23,0) -> 16 | Q23: =RANK(G23,G$3:G$23,0) -> 21
A25: Idealista (sep-2026), 21 distritos de Madrid capital (fila 2 = media de la ciudad). Precios de oferta. Rentabilidad bruta y alquiler de 70 m² son cálculos propios (amarillo). Distritos con pocos anuncios pueden tener variaciones mensuales muy volátiles.

Sheet Idealista_Madrid_Municipios
A1: municipio (provincia de Madrid) | B1: Alquiler €/m² | C1: alq. mensual % | D1: alq. trimestral % | E1: alq. anual % | F1: alq. máximo histórico | G1: Venta €/m² | H1: venta mensual % | I1: venta trimestral % | J1: venta anual % | K1: venta máximo histórico | L1: Rentabilidad bruta % | M1: Años de alquiler | N1: ranking venta (1 = más caro)
A2: Madrid | B2: 23.4 | C2: 0.5 | D2: 1.2 | E2: 4.8 | F2: 23.4 (sep 2026) | G2: 6458 | H2: -0.2 | I2: -1.8 | J2: 2.4 | K2: 6619 (abr 2026) | L2: =IF(OR(B2="",G2=""),"",B2*12/G2*100) -> 4.3480954 | M2: =IF(OR(B2="",G2=""),"",G2/(B2*12)) -> 22.998575 | N2: =IF(G2="","",RANK(G2,G$2:G$72,0)) -> 2
A3: Alcalá de Henares | B3: 14.2 | C3: 0 | D3: 2.6 | E3: 9.9 | F3: 14.2 (ago 2026) | G3: 3014 | H3: 1.5 | I3: 3.6 | J3: 17.1 | K3: 3014 (sep 2026) | L3: =IF(OR(B3="",G3=""),"",B3*12/G3*100) -> 5.6536165 | M3: =IF(OR(B3="",G3=""),"",G3/(B3*12)) -> 17.687793 | N3: =IF(G3="","",RANK(G3,G$2:G$72,0)) -> 23
A4: Alcobendas | B4: 17.5 | C4: 2.5 | D4: 2.1 | E4: 2.9 | F4: 17.5 (sep 2026) | G4: 4111 | H4: 0.4 | I4: -0.8 | J4: 1.1 | K4: 4146 (jun 2026) | L4: =IF(OR(B4="",G4=""),"",B4*12/G4*100) -> 5.1082462 | M4: =IF(OR(B4="",G4=""),"",G4/(B4*12)) -> 19.57619 | N4: =IF(G4="","",RANK(G4,G$2:G$72,0)) -> 8
A5: Alcorcón | B5: 15.1 | C5: -0.1 | D5: 3.6 | E5: 1.3 | F5: 15.1 (ago 2026) | G5: 3537 | H5: 0.6 | I5: 2.5 | J5: 12.4 | K5: 3537 (sep 2026) | L5: =IF(OR(B5="",G5=""),"",B5*12/G5*100) -> 5.1229856 | M5: =IF(OR(B5="",G5=""),"",G5/(B5*12)) -> 19.519868 | N5: =IF(G5="","",RANK(G5,G$2:G$72,0)) -> 13
A6: Algete | G6: 2315 | H6: 1.1 | I6: 3.7 | J6: 4.1 | K6: 2315 (sep 2026) | L6: =IF(OR(B6="",G6=""),"",B6*12/G6*100) | M6: =IF(OR(B6="",G6=""),"",G6/(B6*12)) | N6: =IF(G6="","",RANK(G6,G$2:G$72,0)) -> 57
A7: Alpedrete | G7: 3000 | H7: 2.1 | I7: 4.5 | J7: 19.4 | K7: 3000 (sep 2026) | L7: =IF(OR(B7="",G7=""),"",B7*12/G7*100) | M7: =IF(OR(B7="",G7=""),"",G7/(B7*12)) | N7: =IF(G7="","",RANK(G7,G$2:G$72,0)) -> 25
A8: Aranjuez | B8: 12.4 | C8: -3.2 | D8: -3.3 | E8: 8.2 | F8: 12.9 (jun 2026) | G8: 2384 | H8: -0.4 | I8: 3.6 | J8: 19 | K8: 2395 (jun 2008) | L8: =IF(OR(B8="",G8=""),"",B8*12/G8*100) -> 6.2416107 | M8: =IF(OR(B8="",G8=""),"",G8/(B8*12)) -> 16.021505 | N8: =IF(G8="","",RANK(G8,G$2:G$72,0)) -> 54
