Workbook

Sheet LEEME
A1: Base de conocimiento — Población (España y Comunidad de Madrid)
A3: Descripción
A4: Población residente por sexo, edad (grupos de 5 años), nacionalidad (española/extranjera) y comunidad autónoma a 1 de julio de 2026 (INE, provisional), histórico 1971–2026, indicadores demográficos (esperanza de vida, fecundidad, edad mediana, envejecimiento), proyecciones del INE 2026–2076 y el padrón de Madrid capital.
A5: Fecha de consulta: 2026-10-21. Los cálculos propios están en fórmulas visibles; los indicadores en amarillo son aproximaciones no oficiales.
A7: Índice de hojas
A8: Hoja | B8: Contenido | C8: Cobertura
A9: Resumen_Poblacion | B9: Cuadro de indicadores clave España frente a Madrid. | C9: Último dato
A10: Pob_CCAA_1jul2026 | B10: Población por CCAA: total, sexo, nacionalidad, peso, personas por hogar. | C10: 1-jul-2026
A11: Edad_Total / _Hombres / _Mujeres / _Extranjeros | B11: Población por grupo quinquenal de edad (0–4 … 90+) y territorio (España + 19 CCAA), con comprobaciones de suma. | C11: 1-jul-2026
A12: Estructura_Edad | B12: % por tramos de edad, índice de envejecimiento, dependencia, % de extranjeros y rankings por CCAA. | C12: 1-jul-2026
A13: Piramide_Mad_vs_Esp | B13: Pirámides comparables (% por edad y sexo) de Madrid y España. | C13: 1-jul-2026
A14: Historico_1971_2026 | B14: Población a 1 de enero de España y Madrid, por sexo, con tasas y TCAC calculables. | C14: 1971–2026
A15: Trimestral_2021_2026 | B15: Población trimestral de España y Madrid. | C15: 2021T1–2026T3 (1-jul)
A16: Indicadores_Demograficos | B16: Esperanza de vida, edad mediana y media, índice de envejecimiento, natalidad, mortalidad, fecundidad por CCAA. | C16: 2024 / 1-ene-2025
A17: Proyecciones_INE | B17: Proyecciones de población 2026–2076 (INE, 17-jun-2026) y comparación con la de 2024. | C17: 2026–2076
A18: Madrid_Ciudad_Padron_2026 | B18: Padrón del municipio de Madrid a 1-ene-2026: población, componentes del cambio. | C18: 2025–2026
A19: FUENTES | B19: Origen de cada bloque.
A21: Notas, límites y huecos conocidos
A22: • Los datos del INE a 1-jul-2026 son provisionales y se revisarán. Las estimaciones trimestrales de la ECP no coinciden exactamente con el padrón continuo de enero que publica el INE cada año ni con el padrón del Ayuntamiento de Madrid.
A23: • Madrid = Comunidad de Madrid (7,2 millones). El municipio de Madrid (3,5 millones) solo aparece en la hoja Madrid_Ciudad_Padron_2026.
A24: • Edades en grupos de 5 años por CCAA. La población por edad simple existe en las tablas 59238 (CCAA) y 59583 (nacional) del INE, no incluidas aquí. La estructura por nacionalidad se limita a española/extranjera; no se ha cargado el país de origen (tablas 77019, 56942).
A25: • Indicadores demográficos de 2024 (IDB) y edades medias a 1-ene-2025: son los últimos publicados por el INE. España no figura en la tabla de esperanza de vida por CCAA; se añadió de la tabla nacional.
A26: • No incluidos: población por provincia y municipio (excepto Madrid capital en totales), por distrito de Madrid (datos.madrid.es bloqueó la lectura automatizada), movimientos migratorios y flujos interiores, hogares por tamaño (tabla 60131), país de nacimiento.
A27: • Las series históricas de 2003–2012 de España son estimaciones (con decimales en la fuente, aquí redondeadas); cualquier comparación de crecimiento entre periodos debe leerse con esa cautela.
A29: Convención de colores
A30: Azul: dato copiado de la fuente (valor fijo)
A31: Negro: fórmula de esta hoja
A32: Verde: fórmula que enlaza con otra hoja
A33: Fondo naranja claro: dato con muestra pequeña / poco fiable según la fuente
A34: Fondo amarillo claro: estimación no oficial (elaboración propia)

Sheet Resumen_Poblacion
A1: Resumen de población — España y Comunidad de Madrid
A2: Población residente a 1 de julio de 2026 (provisional, INE). Los valores enlazan con las hojas de detalle (verde).
A4: Indicador | B4: Periodo | C4: España | D4: Madrid | E4: Madrid − España | F4: Madrid / España | G4: Nota
A5: Población total | B5: 1-jul-2026 | C5: =Edad_Total!B2 -> 49801559 | D5: =Edad_Total!O2 -> 7201554 | F5: =D5/C5 -> 0.14460499 | G5: Madrid = Comunidad de Madrid
A6: Madrid como % de la población de España | B6: 1-jul-2026 | D6: =Edad_Total!O2/Edad_Total!B2*100 -> 14.460499
A7: Hombres | B7: 1-jul-2026 | C7: =Edad_Hombres!B2 -> 24462607 | D7: =Edad_Hombres!O2 -> 3450616
A8: Mujeres | B8: 1-jul-2026 | C8: =Edad_Mujeres!B2 -> 25338952 | D8: =Edad_Mujeres!O2 -> 3750938
A9: Mujeres por 100 hombres | B9: 1-jul-2026 | C9: =Estructura_Edad!N2 -> 103.58239 | D9: =Estructura_Edad!N15 -> 108.70343 | E9: =D9-C9 -> 5.1210455
A10: Población de nacionalidad extranjera | B10: 1-jul-2026 | C10: =Edad_Extranjeros!B2 -> 7437543 | D10: =Edad_Extranjeros!O2 -> 1229486
A11: % de nacionalidad extranjera | B11: 1-jul-2026 | C11: =Estructura_Edad!L2 -> 14.934358 | D11: =Estructura_Edad!L15 -> 17.07251 | E11: =D11-C11 -> 2.1381518
A12: % de 0 a 14 años | B12: 1-jul-2026 | C12: =Estructura_Edad!C2 -> 12.389257 | D12: =Estructura_Edad!C15 -> 12.705036 | E12: =D12-C12 -> 0.31577888
A13: % de 15 a 64 años | B13: 1-jul-2026 | C13: =Estructura_Edad!D2 -> 66.404263 | D13: =Estructura_Edad!D15 -> 67.921687 | E13: =D13-C13 -> 1.5174249
A14: % de 65 años y más | B14: 1-jul-2026 | C14: =Estructura_Edad!E2 -> 21.206481 | D14: =Estructura_Edad!E15 -> 19.373277 | E14: =D14-C14 -> -1.8332038
A15: % de 80 años y más | B15: 1-jul-2026 | C15: =Estructura_Edad!F2 -> 6.3486567 | D15: =Estructura_Edad!F15 -> 5.9867912 | E15: =D15-C15 -> -0.36186549
A16: Índice de envejecimiento (65+ ÷ 0–14 × 100) | B16: 1-jul-2026 | C16: =Estructura_Edad!G2 -> 171.1683 | D16: =Estructura_Edad!G15 -> 152.48503 | E16: =D16-C16 -> -18.683278 | G16: Cálculo propio con grupos de 5 años
A17: Tasa de dependencia (0–14 y 65+ sobre 15–64) | B17: 1-jul-2026 | C17: =Estructura_Edad!H2 -> 50.592742 | D17: =Estructura_Edad!H15 -> 47.22838 | E17: =D17-C17 -> -3.3643625
A18: Edad mediana (años) | B18: 1-ene-2025 | C18: =Indicadores_Demograficos!F2 -> 45.83 | D18: =Indicadores_Demograficos!F15 -> 44.22 | E18: =D18-C18 -> -1.61 | G18: INE, indicadores demográficos básicos
A19: Edad media (años) | B19: 1-ene-2025 | C19: =Indicadores_Demograficos!I2 -> 44.55 | D19: =Indicadores_Demograficos!I15 -> 43.42 | E19: =D19-C19 -> -1.13
A20: Esperanza de vida al nacer (años) | B20: 2024 | C20: =Indicadores_Demograficos!B2 -> 84.01 | D20: =Indicadores_Demograficos!B15 -> 85.58 | E20: =D20-C20 -> 1.57
A21: Indicador coyuntural de fecundidad (hijos por mujer) | B21: 2024 | C21: =Indicadores_Demograficos!P2 -> 1.1 | D21: =Indicadores_Demograficos!P15 -> 1.09 | E21: =D21-C21 -> -0.01
A22: Natalidad (‰) | B22: 2024 | C22: =Indicadores_Demograficos!N2 -> 6.49 | D22: =Indicadores_Demograficos!N15 -> 7.19 | E22: =D22-C22 -> 0.7
A23: Mortalidad (‰) | B23: 2024 | C23: =Indicadores_Demograficos!O2 -> 8.87 | D23: =Indicadores_Demograficos!O15 -> 7 | E23: =D23-C23 -> -1.87
A24: Saldo vegetativo (‰) | B24: 2024 | C24: =Indicadores_Demograficos!M2 -> -2.37 | D24: =Indicadores_Demograficos!M15 -> 0.19 | E24: =D24-C24 -> 2.56 | G24: Madrid, junto con Baleares, Murcia, Ceuta y Melilla, tiene saldo natural no negativo
A25: Personas por hogar | B25: 1-jul-2026 | C25: =Pob_CCAA_1jul2026!K2 -> 2.49 | D25: =Pob_CCAA_1jul2026!K15 -> 2.58 | E25: =D25-C25 -> 0.09
A26: Hogares estimados (población ÷ tamaño medio) | B26: 1-jul-2026 | C26: =Pob_CCAA_1jul2026!L2 -> 20000626 | D26: =Pob_CCAA_1jul2026!L15 -> 2791300 | G26: Cálculo propio
A27: Crecimiento de la población 1-jul-2021 a 1-jul-2026 (%) | B27: 5 años | C27: =(Trimestral_2021_2026!B24/Trimestral_2021_2026!B4-1)*100 -> 5.1845555 | D27: =(Trimestral_2021_2026!G24/Trimestral_2021_2026!G4-1)*100 -> 7.2031842 | E27: =D27-C27 -> 2.0186287
A28: Crecimiento de la población 1-jul-2025 a 1-jul-2026 (%) | B28: 1 año | C28: =(Trimestral_2021_2026!B24/Trimestral_2021_2026!B20-1)*100 -> 0.89997734 | D28: =(Trimestral_2021_2026!G24/Trimestral_2021_2026!G20-1)*100 -> 0.7533324 | E28: =D28-C28 -> -0.14664494
A29: Crecimiento de la población 1971–2026 (%) | B29: 55 años | C29: =(Historico_1971_2026!B57/Historico_1971_2026!B2-1)*100 -> 45.697534 | D29: =(Historico_1971_2026!F57/Historico_1971_2026!F2-1)*100 -> 90.594685 | E29: =D29-C29 -> 44.897151
A30: Variación proyectada 2026–2041 (INE, %) | B30: 2041 | C30: =Proyecciones_INE!B7 -> 8.6 | D30: =Proyecciones_INE!B13 -> 14.4 | E30: =D30-C30 -> 5.8 | G30: Proyecciones_INE (publicadas 17-jun-2026)

Sheet Pob_CCAA_1jul2026
A1: territorio | B1: Población total | C1: Hombres | D1: Mujeres | E1: Españoles | F1: Extranjeros | G1: % de la población de España | H1: % mujeres | I1: % extranjeros | J1: Hombres por 100 mujeres | K1: Personas por hogar (INE) | L1: Hogares estimados (población ÷ tamaño medio) | M1: ranking por población (1 = mayor)
A2: España | B2: =Edad_Total!B2 -> 49801559 | C2: =Edad_Hombres!B2 -> 24462607 | D2: =Edad_Mujeres!B2 -> 25338952 | E2: =B2-F2 -> 42364016 | F2: =Edad_Extranjeros!B2 -> 7437543 | G2: =B2/B$2*100 -> 100 | H2: =D2/B2*100 -> 50.879837 | I2: =F2/B2*100 -> 14.934358 | J2: =C2/D2*100 -> 96.54151 | K2: 2.49 | L2: =B2/K2 -> 20000626
A3: Andalucía | B3: =Edad_Total!C2 -> 8778051 | C3: =Edad_Hombres!C2 -> 4325544 | D3: =Edad_Mujeres!C2 -> 4452507 | E3: =B3-F3 -> 7791129 | F3: =Edad_Extranjeros!C2 -> 986922 | G3: =B3/B$2*100 -> 17.626057 | H3: =D3/B3*100 -> 50.723184 | I3: =F3/B3*100 -> 11.243065 | J3: =C3/D3*100 -> 97.148505 | K3: 2.52 | L3: =B3/K3 -> 3483353.6 | M3: =RANK(B3,B$3:B$21,0) -> 1
A4: Aragón | B4: =Edad_Total!D2 -> 1389298 | C4: =Edad_Hombres!D2 -> 692004 | D4: =Edad_Mujeres!D2 -> 697294 | E4: =B4-F4 -> 1165714 | F4: =Edad_Extranjeros!D2 -> 223584 | G4: =B4/B$2*100 -> 2.7896677 | H4: =D4/B4*100 -> 50.190384 | I4: =F4/B4*100 -> 16.093308 | J4: =C4/D4*100 -> 99.241353 | K4: 2.37 | L4: =B4/K4 -> 586201.69 | M4: =RANK(B4,B$3:B$21,0) -> 11
A5: Asturias | B5: =Edad_Total!E2 -> 1026726 | C5: =Edad_Hombres!E2 -> 490857 | D5: =Edad_Mujeres!E2 -> 535869 | E5: =B5-F5 -> 942639 | F5: =Edad_Extranjeros!E2 -> 84087 | G5: =B5/B$2*100 -> 2.0616343 | H5: =D5/B5*100 -> 52.192016 | I5: =F5/B5*100 -> 8.1898189 | J5: =C5/D5*100 -> 91.600186 | K5: 2.2 | L5: =B5/K5 -> 466693.64 | M5: =RANK(B5,B$3:B$21,0) -> 14
A6: Baleares | B6: =Edad_Total!F2 -> 1266279 | C6: =Edad_Hombres!F2 -> 630803 | D6: =Edad_Mujeres!F2 -> 635476 | E6: =B6-F6 -> 986864 | F6: =Edad_Extranjeros!F2 -> 279415 | G6: =B6/B$2*100 -> 2.5426493 | H6: =D6/B6*100 -> 50.184517 | I6: =F6/B6*100 -> 22.065832 | J6: =C6/D6*100 -> 99.264646 | K6: 2.65 | L6: =B6/K6 -> 477841.13 | M6: =RANK(B6,B$3:B$21,0) -> 12
A7: Canarias | B7: =Edad_Total!G2 -> 2277705 | C7: =Edad_Hombres!G2 -> 1123287 | D7: =Edad_Mujeres!G2 -> 1154418 | E7: =B7-F7 -> 1928015 | F7: =Edad_Extranjeros!G2 -> 349690 | G7: =B7/B$2*100 -> 4.5735616 | H7: =D7/B7*100 -> 50.683385 | I7: =F7/B7*100 -> 15.352734 | J7: =C7/D7*100 -> 97.303316 | K7: 2.6 | L7: =B7/K7 -> 876040.38 | M7: =RANK(B7,B$3:B$21,0) -> 7
A8: Cantabria | B8: =Edad_Total!H2 -> 599056 | C8: =Edad_Hombres!H2 -> 290615 | D8: =Edad_Mujeres!H2 -> 308441 | E8: =B8-F8 -> 545567 | F8: =Edad_Extranjeros!H2 -> 53489 | G8: =B8/B$2*100 -> 1.202886 | H8: =D8/B8*100 -> 51.487841 | I8: =F8/B8*100 -> 8.9288814 | J8: =C8/D8*100 -> 94.220613 | K8: 2.36 | L8: =B8/K8 -> 253837.29 | M8: =RANK(B8,B$3:B$21,0) -> 16
A9: Castilla y León | B9: =Edad_Total!I2 -> 2427156 | C9: =Edad_Hombres!I2 -> 1197212 | D9: =Edad_Mujeres!I2 -> 1229944 | E9: =B9-F9 -> 2192341 | F9: =Edad_Extranjeros!I2 -> 234815 | G9: =B9/B$2*100 -> 4.8736547 | H9: =D9/B9*100 -> 50.674287 | I9: =F9/B9*100 -> 9.6744915 | J9: =C9/D9*100 -> 97.338741 | K9: 2.23 | L9: =B9/K9 -> 1088410.8 | M9: =RANK(B9,B$3:B$21,0) -> 6
A10: Castilla-La Mancha | B10: =Edad_Total!J2 -> 2169241 | C10: =Edad_Hombres!J2 -> 1091733 | D10: =Edad_Mujeres!J2 -> 1077508 | E10: =B10-F10 -> 1883124 | F10: =Edad_Extranjeros!J2 -> 286117 | G10: =B10/B$2*100 -> 4.3557693 | H10: =D10/B10*100 -> 49.67212 | I10: =F10/B10*100 -> 13.189729 | J10: =C10/D10*100 -> 101.32018 | K10: 2.5 | L10: =B10/K10 -> 867696.4 | M10: =RANK(B10,B$3:B$21,0) -> 9
A11: Cataluña | B11: =Edad_Total!K2 -> 8233788 | C11: =Edad_Hombres!K2 -> 4075424 | D11: =Edad_Mujeres!K2 -> 4158364 | E11: =B11-F11 -> 6635388 | F11: =Edad_Extranjeros!K2 -> 1598400 | G11: =B11/B$2*100 -> 16.533193 | H11: =D11/B11*100 -> 50.503656 | I11: =F11/B11*100 -> 19.412693 | J11: =C11/D11*100 -> 98.005466 | K11: 2.54 | L11: =B11/K11 -> 3241648.8 | M11: =RANK(B11,B$3:B$21,0) -> 2
A12: Comunitat Valenciana | B12: =Edad_Total!L2 -> 5574948 | C12: =Edad_Hombres!L2 -> 2751166 | D12: =Edad_Mujeres!L2 -> 2823782 | E12: =B12-F12 -> 4401133 | F12: =Edad_Extranjeros!L2 -> 1173815 | G12: =B12/B$2*100 -> 11.194324 | H12: =D12/B12*100 -> 50.651271 | I12: =F12/B12*100 -> 21.055174 | J12: =C12/D12*100 -> 97.428413 | K12: 2.48 | L12: =B12/K12 -> 2247962.9 | M12: =RANK(B12,B$3:B$21,0) -> 4
A13: Extremadura | B13: =Edad_Total!M2 -> 1055849 | C13: =Edad_Hombres!M2 -> 521897 | D13: =Edad_Mujeres!M2 -> 533952 | E13: =B13-F13 -> 1001861 | F13: =Edad_Extranjeros!M2 -> 53988 | G13: =B13/B$2*100 -> 2.1201123 | H13: =D13/B13*100 -> 50.570868 | I13: =F13/B13*100 -> 5.1132312 | J13: =C13/D13*100 -> 97.742306 | K13: 2.33 | L13: =B13/K13 -> 453154.08 | M13: =RANK(B13,B$3:B$21,0) -> 13
A14: Galicia | B14: =Edad_Total!N2 -> 2734494 | C14: =Edad_Hombres!N2 -> 1318709 | D14: =Edad_Mujeres!N2 -> 1415785 | E14: =B14-F14 -> 2531258 | F14: =Edad_Extranjeros!N2 -> 203236 | G14: =B14/B$2*100 -> 5.4907799 | H14: =D14/B14*100 -> 51.775027 | I14: =F14/B14*100 -> 7.4323074 | J14: =C14/D14*100 -> 93.143309 | K14: 2.38 | L14: =B14/K14 -> 1148947.1 | M14: =RANK(B14,B$3:B$21,0) -> 5
A15: Madrid | B15: =Edad_Total!O2 -> 7201554 | C15: =Edad_Hombres!O2 -> 3450616 | D15: =Edad_Mujeres!O2 -> 3750938 | E15: =B15-F15 -> 5972068 | F15: =Edad_Extranjeros!O2 -> 1229486 | G15: =B15/B$2*100 -> 14.460499 | H15: =D15/B15*100 -> 52.085119 | I15: =F15/B15*100 -> 17.07251 | J15: =C15/D15*100 -> 91.993416 | K15: 2.58 | L15: =B15/K15 -> 2791300 | M15: =RANK(B15,B$3:B$21,0) -> 3
A16: Murcia | B16: =Edad_Total!P2 -> 1616189 | C16: =Edad_Hombres!P2 -> 809334 | D16: =Edad_Mujeres!P2 -> 806855 | E16: =B16-F16 -> 1344809 | F16: =Edad_Extranjeros!P2 -> 271380 | G16: =B16/B$2*100 -> 3.2452578 | H16: =D16/B16*100 -> 49.923307 | I16: =F16/B16*100 -> 16.791353 | J16: =C16/D16*100 -> 100.30724 | K16: 2.7 | L16: =B16/K16 -> 598588.52 | M16: =RANK(B16,B$3:B$21,0) -> 10
A17: Navarra | B17: =Edad_Total!Q2 -> 692026 | C17: =Edad_Hombres!Q2 -> 343437 | D17: =Edad_Mujeres!Q2 -> 348589 | E17: =B17-F17 -> 596129 | F17: =Edad_Extranjeros!Q2 -> 95897 | G17: =B17/B$2*100 -> 1.3895669 | H17: =D17/B17*100 -> 50.37224 | I17: =F17/B17*100 -> 13.857427 | J17: =C17/D17*100 -> 98.522042 | K17: 2.5 | L17: =B17/K17 -> 276810.4 | M17: =RANK(B17,B$3:B$21,0) -> 15
A18: País Vasco | B18: =Edad_Total!R2 -> 2257392 | C18: =Edad_Hombres!R2 -> 1100960 | D18: =Edad_Mujeres!R2 -> 1156432 | E18: =B18-F18 -> 2013168 | F18: =Edad_Extranjeros!R2 -> 244224 | G18: =B18/B$2*100 -> 4.5327738 | H18: =D18/B18*100 -> 51.228675 | I18: =F18/B18*100 -> 10.818856 | J18: =C18/D18*100 -> 95.203177 | K18: 2.32 | L18: =B18/K18 -> 973013.79 | M18: =RANK(B18,B$3:B$21,0) -> 8
A19: La Rioja | B19: =Edad_Total!S2 -> 330756 | C19: =Edad_Hombres!S2 -> 163319 | D19: =Edad_Mujeres!S2 -> 167437 | E19: =B19-F19 -> 279069 | F19: =Edad_Extranjeros!S2 -> 51687 | G19: =B19/B$2*100 -> 0.66414788 | H19: =D19/B19*100 -> 50.622513 | I19: =F19/B19*100 -> 15.626927 | J19: =C19/D19*100 -> 97.540567 | K19: 2.33 | L19: =B19/K19 -> 141955.36 | M19: =RANK(B19,B$3:B$21,0) -> 17
A20: Ceuta | B20: =Edad_Total!T2 -> 84435 | C20: =Edad_Hombres!T2 -> 42552 | D20: =Edad_Mujeres!T2 -> 41883 | E20: =B20-F20 -> 78385 | F20: =Edad_Extranjeros!T2 -> 6050 | G20: =B20/B$2*100 -> 0.16954289 | H20: =D20/B20*100 -> 49.603837 | I20: =F20/B20*100 -> 7.1652751 | J20: =C20/D20*100 -> 101.59731 | K20: 3.07 | L20: =B20/K20 -> 27503.257 | M20: =RANK(B20,B$3:B$21,0) -> 19
A21: Melilla | B21: =Edad_Total!U2 -> 86616 | C21: =Edad_Hombres!U2 -> 43138 | D21: =Edad_Mujeres!U2 -> 43478 | E21: =B21-F21 -> 75355 | F21: =Edad_Extranjeros!U2 -> 11261 | G21: =B21/B$2*100 -> 0.17392227 | H21: =D21/B21*100 -> 50.196269 | I21: =F21/B21*100 -> 13.001062 | J21: =C21/D21*100 -> 99.217995 | K21: 3.13 | L21: =B21/K21 -> 27672.843 | M21: =RANK(B21,B$3:B$21,0) -> 18
A22: Suma de las 19 CCAA | B22: =SUM(B3:B21) -> 49801559 | C22: =SUM(C3:C21) -> 24462607 | D22: =SUM(D3:D21) -> 25338952 | E22: =SUM(E3:E21) -> 42364016 | F22: =SUM(F3:F21) -> 7437543
A23: Diferencia con el total nacional | B23: =B22-B2 -> 0 | C23: =C22-C2 -> 0 | D23: =D22-D2 -> 0 | E23: =E22-E2 -> 0 | F23: =F22-F2 -> 0
A25: Población residente a 1 de julio de 2026 (provisional), Estadística Continua de Población del INE. Los datos enlazan con las hojas Edad_*. Tamaño medio del hogar: INE tabla 60132 (1-jul-2026); los hogares estimados son población ÷ tamaño medio (cálculo propio, amarillo; el INE publica el número exacto de hogares en la tabla 60131, no descargada).

Sheet Edad_Total
A1: grupo de edad | B1: España | C1: Andalucía | D1: Aragón | E1: Asturias | F1: Baleares | G1: Canarias | H1: Cantabria | I1: Castilla y León | J1: Castilla-La Mancha | K1: Cataluña | L1: Comunitat Valenciana | M1: Extremadura | N1: Galicia | O1: Madrid | P1: Murcia | Q1: Navarra | R1: País Vasco | S1: La Rioja | T1: Ceuta | U1: Melilla | V1: Suma de las 19 CCAA | W1: Diferencia con el total nacional
A2: Todas las edades | B2: 49801559 | C2: 8778051 | D2: 1389298 | E2: 1026726 | F2: 1266279 | G2: 2277705 | H2: 599056 | I2: 2427156 | J2: 2169241 | K2: 8233788 | L2: 5574948 | M2: 1055849 | N2: 2734494 | O2: 7201554 | P2: 1616189 | Q2: 692026 | R2: 2257392 | S2: 330756 | T2: 84435 | U2: 86616 | V2: =SUM(C2:U2) -> 49801559 | W2: =V2-B2 -> 0
A3: 0-4 | B3: 1678170 | C3: 317820 | D3: 46283 | E3: 25162 | F3: 45228 | G3: 62436 | H3: 16122 | I3: 68438 | J3: 78128 | K3: 283645 | L3: 191768 | M3: 34760 | N3: 73053 | O3: 257571 | P3: 66166 | Q3: 24184 | R3: 68954 | S3: 11038 | T3: 3444 | U3: 3970 | V3: =SUM(C3:U3) -> 1678170 | W3: =V3-B3 -> 0
A4: 5-9 | B4: 2036914 | C4: 382637 | D4: 56076 | E4: 32250 | F4: 54097 | G4: 81628 | H4: 21407 | I4: 84460 | J4: 94399 | K4: 344940 | L4: 233477 | M4: 41827 | N4: 94028 | O4: 297193 | P4: 79090 | Q4: 30575 | R4: 85264 | S4: 13628 | T4: 4404 | U4: 5534 | V4: =SUM(C4:U4) -> 2036914 | W4: =V4-B4 -> 0
A5: 10-14 | B5: 2454959 | C5: 454748 | D5: 68051 | E5: 40148 | F5: 61850 | G5: 99133 | H5: 27108 | I5: 103708 | J5: 113698 | K5: 415492 | L5: 281099 | M5: 48688 | N5: 114548 | O5: 360196 | P5: 93291 | Q5: 37359 | R5: 107134 | S5: 16667 | T5: 5483 | U5: 6558 | V5: =SUM(C5:U5) -> 2454959 | W5: =V5-B5 -> 0
A6: 15-19 | B6: 2746606 | C6: 513864 | D6: 74825 | E6: 45838 | F6: 68153 | G6: 117736 | H6: 31328 | I6: 114835 | J6: 123909 | K6: 467954 | L6: 314437 | M6: 55022 | N6: 126914 | O6: 399633 | P6: 101979 | Q6: 40590 | R6: 118688 | S6: 18316 | T6: 6131 | U6: 6454 | V6: =SUM(C6:U6) -> 2746606 | W6: =V6-B6 -> 0
A7: 20-24 | B7: 2812349 | C7: 508447 | D7: 75969 | E7: 44863 | F7: 73555 | G7: 131568 | H7: 30856 | I7: 118291 | J7: 121420 | K7: 487600 | L7: 317947 | M7: 54861 | N7: 126599 | O7: 426872 | P7: 100494 | Q7: 40786 | R7: 121587 | S7: 18013 | T7: 6306 | U7: 6315 | V7: =SUM(C7:U7) -> 2812349 | W7: =V7-B7 -> 0
A8: 25-29 | B8: 2828033 | C8: 484555 | D8: 75914 | E8: 43722 | F8: 82624 | G8: 137575 | H8: 27605 | I8: 114347 | J8: 118084 | K8: 507228 | L8: 315937 | M8: 53050 | N8: 124274 | O8: 459280 | P8: 96170 | Q8: 39366 | R8: 119753 | S8: 17000 | T8: 5622 | U8: 5927 | V8: =SUM(C8:U8) -> 2828033 | W8: =V8-B8 -> 0
A9: 30-34 | B9: 2925915 | C9: 508850 | D9: 77766 | E9: 45473 | F9: 88472 | G9: 141601 | H9: 28193 | I9: 116691 | J9: 123551 | K9: 525904 | L9: 328295 | M9: 56184 | N9: 131519 | O9: 473991 | P9: 96557 | Q9: 38366 | R9: 116339 | S9: 17033 | T9: 5357 | U9: 5773 | V9: =SUM(C9:U9) -> 2925915 | W9: =V9-B9 -> 0
A10: 35-39 | B10: 3080859 | C10: 552391 | D10: 81858 | E10: 52718 | F10: 91934 | G10: 152101 | H10: 32393 | I10: 127515 | J10: 135287 | K10: 532566 | L10: 348190 | M10: 63072 | N10: 148024 | O10: 470307 | P10: 102128 | Q10: 39261 | R10: 121170 | S10: 18996 | T10: 5461 | U10: 5487 | V10: =SUM(C10:U10) -> 3080859 | W10: =V10-B10 -> 0
A11: 40-44 | B11: 3419433 | C11: 617908 | D11: 91514 | E11: 65705 | F11: 97567 | G11: 165351 | H11: 40092 | I11: 149655 | J11: 151214 | K11: 567939 | L11: 385618 | M11: 69355 | N11: 179566 | O11: 504262 | P11: 113373 | Q11: 44782 | R11: 141627 | S11: 21951 | T11: 5988 | U11: 5966 | V11: =SUM(C11:U11) -> 3419433 | W11: =V11-B11 -> 0
A12: 45-49 | B12: 4015072 | C12: 710237 | D12: 109699 | E12: 83525 | F12: 107319 | G12: 189659 | H12: 50361 | I12: 182209 | J12: 174424 | K12: 665579 | L12: 455847 | M12: 78660 | N12: 225978 | O12: 579662 | P12: 133119 | Q12: 54158 | R12: 175137 | S12: 26888 | T12: 6384 | U12: 6227 | V12: =SUM(C12:U12) -> 4015072 | W12: =V12-B12 -> 0
A13: 50-54 | B13: 4054598 | C13: 704414 | D13: 111914 | E13: 88177 | F13: 104708 | G13: 202224 | H13: 50679 | I13: 190150 | J13: 171918 | K13: 668636 | L13: 451372 | M13: 81559 | N13: 229395 | O13: 591331 | P13: 128319 | Q13: 55605 | R13: 185169 | S13: 27035 | T13: 6360 | U13: 5633 | V13: =SUM(C13:U13) -> 4054598 | W13: =V13-B13 -> 0
... A21: 90+ | B21: 708141 | C21: 89446 | D21: 25379 | E21: 22744 | F21: 11907 | G21: 21391 | H21: 10979 | I21: 62619 | J21: 33730 | K21: 112496 | L21: 63911 | M21: 18756 | N21: 63061 | O21: 98455 | P21: 15515 | Q21: 10700 | R21: 40322 | S21: 5807 | T21: 481 | U21: 442 | V21: =SUM(C21:U21) -> 708141 | W21: =V21-B21 -> 0
A22: Suma de los 19 grupos de edad | B22: =SUM(B3:B21) -> 49801559 | C22: =SUM(C3:C21) -> 8778051 | D22: =SUM(D3:D21) -> 1389298 | E22: =SUM(E3:E21) -> 1026726 | F22: =SUM(F3:F21) -> 1266279 | G22: =SUM(G3:G21) -> 2277705 | H22: =SUM(H3:H21) -> 599056 | I22: =SUM(I3:I21) -> 2427156 | ... U22: =SUM(U3:U21) -> 86616
A23: Diferencia con "Todas las edades" | B23: =B22-B2 -> 0 | C23: =C22-C2 -> 0 | D23: =D22-D2 -> 0 | E23: =E22-E2 -> 0 | F23: =F22-F2 -> 0 | G23: =G22-G2 -> 0 | H23: =H22-H2 -> 0 | I23: =I22-I2 -> 0 | ... U23: =U22-U2 -> 0
A25: Estadística Continua de Población (INE, tabla 59587), población residente a 1 de julio de 2026 (datos provisionales). Todas las nacionalidades, ambos sexos. Fila 22-23: comprobaciones (deben ser 0).

Sheet Edad_Hombres
A1: grupo de edad | B1: España | C1: Andalucía | D1: Aragón | E1: Asturias | F1: Baleares | G1: Canarias | H1: Cantabria | I1: Castilla y León | J1: Castilla-La Mancha | K1: Cataluña | L1: Comunitat Valenciana | M1: Extremadura | N1: Galicia | O1: Madrid | P1: Murcia | Q1: Navarra | R1: País Vasco | S1: La Rioja | T1: Ceuta | U1: Melilla | V1: Suma de las 19 CCAA | W1: Diferencia con el total nacional
A2: Todas las edades | B2: 24462607 | C2: 4325544 | D2: 692004 | E2: 490857 | F2: 630803 | G2: 1123287 | H2: 290615 | I2: 1197212 | J2: 1091733 | K2: 4075424 | L2: 2751166 | M2: 521897 | N2: 1318709 | O2: 3450616 | P2: 809334 | Q2: 343437 | R2: 1100960 | S2: 163319 | T2: 42552 | U2: 43138 | V2: =SUM(C2:U2) -> 24462607 | W2: =V2-B2 -> 0
A3: 0-4 | B3: 862695 | C3: 163119 | D3: 23765 | E3: 13010 | F3: 23176 | G3: 31948 | H3: 8292 | I3: 35410 | J3: 40389 | K3: 145970 | L3: 98688 | M3: 17873 | N3: 37449 | O3: 132557 | P3: 33793 | Q3: 12520 | R3: 35325 | S3: 5625 | T3: 1771 | U3: 2015 | V3: =SUM(C3:U3) -> 862695 | W3: =V3-B3 -> 0
A4: 5-9 | B4: 1045841 | C4: 196491 | D4: 28771 | E4: 16588 | F4: 27818 | G4: 41959 | H4: 10946 | I4: 43346 | J4: 48563 | K4: 176587 | L4: 120193 | M4: 21519 | N4: 48333 | O4: 152507 | P4: 40694 | Q4: 15642 | R4: 43789 | S4: 7005 | T4: 2267 | U4: 2823 | V4: =SUM(C4:U4) -> 1045841 | W4: =V4-B4 -> 0
A5: 10-14 | B5: 1263648 | C5: 234078 | D5: 34963 | E5: 20767 | F5: 31748 | G5: 50813 | H5: 13951 | I5: 53550 | J5: 58336 | K5: 214599 | L5: 144872 | M5: 24988 | N5: 59078 | O5: 184765 | P5: 48120 | Q5: 19235 | R5: 55005 | S5: 8589 | T5: 2831 | U5: 3360 | V5: =SUM(C5:U5) -> 1263648 | W5: =V5-B5 -> 0
A6: 15-19 | B6: 1425869 | C6: 265905 | D6: 39150 | E6: 23616 | F6: 35675 | G6: 62097 | H6: 16093 | I6: 59490 | J6: 64145 | K6: 244717 | L6: 163337 | M6: 28546 | N6: 65700 | O6: 205382 | P6: 53192 | Q6: 21020 | R6: 61892 | S6: 9518 | T6: 3094 | U6: 3300 | V6: =SUM(C6:U6) -> 1425869 | W6: =V6-B6 -> 0
A7: 20-24 | B7: 1459733 | C7: 264259 | D7: 40308 | E7: 23262 | F7: 37834 | G7: 67339 | H7: 15791 | I7: 61274 | J7: 64090 | K7: 258256 | L7: 165247 | M7: 28083 | N7: 65516 | O7: 215642 | P7: 53052 | Q7: 21039 | R7: 63150 | S7: 9224 | T7: 3178 | U7: 3189 | V7: =SUM(C7:U7) -> 1459733 | W7: =V7-B7 -> 0
A8: 25-29 | B8: 1461430 | C8: 252683 | D8: 40715 | E8: 22592 | F8: 41847 | G8: 68786 | H8: 14156 | I8: 60010 | J8: 63239 | K8: 266309 | L8: 163669 | M8: 27469 | N8: 63908 | O8: 228290 | P8: 50671 | Q8: 20365 | R8: 61985 | S8: 8779 | T8: 2909 | U8: 3048 | V8: =SUM(C8:U8) -> 1461430 | W8: =V8-B8 -> 0
A9: 30-34 | B9: 1495335 | C9: 260132 | D9: 40698 | E9: 22760 | F9: 44876 | G9: 71107 | H9: 14365 | I9: 60641 | J9: 65167 | K9: 272862 | L9: 168573 | M9: 28682 | N9: 66843 | O9: 234748 | P9: 50165 | Q9: 19935 | R9: 59528 | S9: 8637 | T9: 2736 | U9: 2880 | V9: =SUM(C9:U9) -> 1495335 | W9: =V9-B9 -> 0
A10: 35-39 | B10: 1552717 | C10: 277790 | D10: 42115 | E10: 26198 | F10: 46724 | G10: 75812 | H10: 16091 | I10: 65288 | J10: 69954 | K10: 271621 | L10: 175623 | M10: 32162 | N10: 74180 | O10: 231729 | P10: 51680 | Q10: 19915 | R10: 60959 | S10: 9494 | T10: 2739 | U10: 2643 | V10: =SUM(C10:U10) -> 1552717 | W10: =V10-B10 -> 0
A11: 40-44 | B11: 1705943 | C11: 307195 | D11: 46735 | E11: 32406 | F11: 49504 | G11: 81708 | H11: 19864 | I11: 75698 | J11: 77527 | K11: 285682 | L11: 192446 | M11: 35139 | N11: 89413 | O11: 245592 | P11: 56674 | Q11: 22395 | R11: 70963 | S11: 11012 | T11: 3028 | U11: 2962 | V11: =SUM(C11:U11) -> 1705943 | W11: =V11-B11 -> 0
A12: 45-49 | B12: 2012335 | C12: 355322 | D12: 55918 | E12: 41288 | F12: 54759 | G12: 94883 | H12: 25105 | I12: 91973 | J12: 89992 | K12: 336536 | L12: 229553 | M12: 39299 | N12: 112281 | O12: 281493 | P12: 68723 | Q12: 27337 | R12: 88021 | S12: 13536 | T12: 3304 | U12: 3012 | V12: =SUM(C12:U12) -> 2012335 | W12: =V12-B12 -> 0
A13: 50-54 | B13: 2030098 | C13: 351136 | D13: 57288 | E13: 43481 | F13: 53653 | G13: 101799 | H13: 25111 | I13: 95687 | J13: 87878 | K13: 338369 | L13: 227562 | M13: 41013 | N13: 113216 | O13: 287048 | P13: 65730 | Q13: 28174 | R13: 92961 | S13: 13792 | T13: 3352 | U13: 2848 | V13: =SUM(C13:U13) -> 2030098 | W13: =V13-B13 -> 0
... A21: 90+ | B21: 214828 | C21: 27671 | D21: 7859 | E21: 6472 | F21: 3585 | G21: 6723 | H21: 3024 | I21: 19279 | J21: 11302 | K21: 33470 | L21: 19941 | M21: 5948 | N21: 19370 | O21: 28700 | P21: 5147 | Q21: 3098 | R21: 11238 | S21: 1730 | T21: 145 | U21: 126 | V21: =SUM(C21:U21) -> 214828 | W21: =V21-B21 -> 0
A22: Suma de los 19 grupos de edad | B22: =SUM(B3:B21) -> 24462607 | C22: =SUM(C3:C21) -> 4325544 | D22: =SUM(D3:D21) -> 692004 | E22: =SUM(E3:E21) -> 490857 | F22: =SUM(F3:F21) -> 630803 | G22: =SUM(G3:G21) -> 1123287 | H22: =SUM(H3:H21) -> 290615 | I22: =SUM(I3:I21) -> 1197212 | ... U22: =SUM(U3:U21) -> 43138
A23: Diferencia con "Todas las edades" | B23: =B22-B2 -> 0 | C23: =C22-C2 -> 0 | D23: =D22-D2 -> 0 | E23: =E22-E2 -> 0 | F23: =F22-F2 -> 0 | G23: =G22-G2 -> 0 | H23: =H22-H2 -> 0 | I23: =I22-I2 -> 0 | ... U23: =U22-U2 -> 0
A25: Estadística Continua de Población (INE, tabla 59587), población residente a 1 de julio de 2026 (datos provisionales). Hombres, todas las nacionalidades.

Sheet Edad_Mujeres
A1: grupo de edad | B1: España | C1: Andalucía | D1: Aragón | E1: Asturias | F1: Baleares | G1: Canarias | H1: Cantabria | I1: Castilla y León | J1: Castilla-La Mancha | K1: Cataluña | L1: Comunitat Valenciana | M1: Extremadura | N1: Galicia | O1: Madrid | P1: Murcia | Q1: Navarra | R1: País Vasco | S1: La Rioja | T1: Ceuta | U1: Melilla | V1: Suma de las 19 CCAA | W1: Diferencia con el total nacional
A2: Todas las edades | B2: 25338952 | C2: 4452507 | D2: 697294 | E2: 535869 | F2: 635476 | G2: 1154418 | H2: 308441 | I2: 1229944 | J2: 1077508 | K2: 4158364 | L2: 2823782 | M2: 533952 | N2: 1415785 | O2: 3750938 | P2: 806855 | Q2: 348589 | R2: 1156432 | S2: 167437 | T2: 41883 | U2: 43478 | V2: =SUM(C2:U2) -> 25338952 | W2: =V2-B2 -> 0
A3: 0-4 | B3: 815475 | C3: 154701 | D3: 22518 | E3: 12152 | F3: 22052 | G3: 30488 | H3: 7830 | I3: 33028 | J3: 37739 | K3: 137675 | L3: 93080 | M3: 16887 | N3: 35604 | O3: 125014 | P3: 32373 | Q3: 11664 | R3: 33629 | S3: 5413 | T3: 1673 | U3: 1955 | V3: =SUM(C3:U3) -> 815475 | W3: =V3-B3 -> 0
A4: 5-9 | B4: 991073 | C4: 186146 | D4: 27305 | E4: 15662 | F4: 26279 | G4: 39669 | H4: 10461 | I4: 41114 | J4: 45836 | K4: 168353 | L4: 113284 | M4: 20308 | N4: 45695 | O4: 144686 | P4: 38396 | Q4: 14933 | R4: 41475 | S4: 6623 | T4: 2137 | U4: 2711 | V4: =SUM(C4:U4) -> 991073 | W4: =V4-B4 -> 0
A5: 10-14 | B5: 1191311 | C5: 220670 | D5: 33088 | E5: 19381 | F5: 30102 | G5: 48320 | H5: 13157 | I5: 50158 | J5: 55362 | K5: 200893 | L5: 136227 | M5: 23700 | N5: 55470 | O5: 175431 | P5: 45171 | Q5: 18124 | R5: 52129 | S5: 8078 | T5: 2652 | U5: 3198 | V5: =SUM(C5:U5) -> 1191311 | W5: =V5-B5 -> 0
A6: 15-19 | B6: 1320737 | C6: 247959 | D6: 35675 | E6: 22222 | F6: 32478 | G6: 55639 | H6: 15235 | I6: 55345 | J6: 59764 | K6: 223237 | L6: 151100 | M6: 26476 | N6: 61214 | O6: 194251 | P6: 48787 | Q6: 19570 | R6: 56796 | S6: 8798 | T6: 3037 | U6: 3154 | V6: =SUM(C6:U6) -> 1320737 | W6: =V6-B6 -> 0
A7: 20-24 | B7: 1352616 | C7: 244188 | D7: 35661 | E7: 21601 | F7: 35721 | G7: 64229 | H7: 15065 | I7: 57017 | J7: 57330 | K7: 229344 | L7: 152700 | M7: 26778 | N7: 61083 | O7: 211230 | P7: 47442 | Q7: 19747 | R7: 58437 | S7: 8789 | T7: 3128 | U7: 3126 | V7: =SUM(C7:U7) -> 1352616 | W7: =V7-B7 -> 0
A8: 25-29 | B8: 1366603 | C8: 231872 | D8: 35199 | E8: 21130 | F8: 40777 | G8: 68789 | H8: 13449 | I8: 54337 | J8: 54845 | K8: 240919 | L8: 152268 | M8: 25581 | N8: 60366 | O8: 230990 | P8: 45499 | Q8: 19001 | R8: 57768 | S8: 8221 | T8: 2713 | U8: 2879 | V8: =SUM(C8:U8) -> 1366603 | W8: =V8-B8 -> 0
A9: 30-34 | B9: 1430580 | C9: 248718 | D9: 37068 | E9: 22713 | F9: 43596 | G9: 70494 | H9: 13828 | I9: 56050 | J9: 58384 | K9: 253042 | L9: 159722 | M9: 27502 | N9: 64676 | O9: 239243 | P9: 46392 | Q9: 18431 | R9: 56811 | S9: 8396 | T9: 2621 | U9: 2893 | V9: =SUM(C9:U9) -> 1430580 | W9: =V9-B9 -> 0
A10: 35-39 | B10: 1528142 | C10: 274601 | D10: 39743 | E10: 26520 | F10: 45210 | G10: 76289 | H10: 16302 | I10: 62227 | J10: 65333 | K10: 260945 | L10: 172567 | M10: 30910 | N10: 73844 | O10: 238578 | P10: 50448 | Q10: 19346 | R10: 60211 | S10: 9502 | T10: 2722 | U10: 2844 | V10: =SUM(C10:U10) -> 1528142 | W10: =V10-B10 -> 0
A11: 40-44 | B11: 1713490 | C11: 310713 | D11: 44779 | E11: 33299 | F11: 48063 | G11: 83643 | H11: 20228 | I11: 73957 | J11: 73687 | K11: 282257 | L11: 193172 | M11: 34216 | N11: 90153 | O11: 258670 | P11: 56699 | Q11: 22387 | R11: 70664 | S11: 10939 | T11: 2960 | U11: 3004 | V11: =SUM(C11:U11) -> 1713490 | W11: =V11-B11 -> 0
A12: 45-49 | B12: 2002737 | C12: 354915 | D12: 53781 | E12: 42237 | F12: 52560 | G12: 94776 | H12: 25256 | I12: 90236 | J12: 84432 | K12: 329043 | L12: 226294 | M12: 39361 | N12: 113697 | O12: 298169 | P12: 64396 | Q12: 26821 | R12: 87116 | S12: 13352 | T12: 3080 | U12: 3215 | V12: =SUM(C12:U12) -> 2002737 | W12: =V12-B12 -> 0
A13: 50-54 | B13: 2024500 | C13: 353278 | D13: 54626 | E13: 44696 | F13: 51055 | G13: 100425 | H13: 25568 | I13: 94463 | J13: 84040 | K13: 330267 | L13: 223810 | M13: 40546 | N13: 116179 | O13: 304283 | P13: 62589 | Q13: 27431 | R13: 92208 | S13: 13243 | T13: 3008 | U13: 2785 | V13: =SUM(C13:U13) -> 2024500 | W13: =V13-B13 -> 0
... A21: 90+ | B21: 493313 | C21: 61775 | D21: 17520 | E21: 16272 | F21: 8322 | G21: 14668 | H21: 7955 | I21: 43340 | J21: 22428 | K21: 79026 | L21: 43970 | M21: 12808 | N21: 43691 | O21: 69755 | P21: 10368 | Q21: 7602 | R21: 29084 | S21: 4077 | T21: 336 | U21: 316 | V21: =SUM(C21:U21) -> 493313 | W21: =V21-B21 -> 0
A22: Suma de los 19 grupos de edad | B22: =SUM(B3:B21) -> 25338952 | C22: =SUM(C3:C21) -> 4452507 | D22: =SUM(D3:D21) -> 697294 | E22: =SUM(E3:E21) -> 535869 | F22: =SUM(F3:F21) -> 635476 | G22: =SUM(G3:G21) -> 1154418 | H22: =SUM(H3:H21) -> 308441 | I22: =SUM(I3:I21) -> 1229944 | ... U22: =SUM(U3:U21) -> 43478
A23: Diferencia con "Todas las edades" | B23: =B22-B2 -> 0 | C23: =C22-C2 -> 0 | D23: =D22-D2 -> 0 | E23: =E22-E2 -> 0 | F23: =F22-F2 -> 0 | G23: =G22-G2 -> 0 | H23: =H22-H2 -> 0 | I23: =I22-I2 -> 0 | ... U23: =U22-U2 -> 0
A25: Estadística Continua de Población (INE, tabla 59587), población residente a 1 de julio de 2026 (datos provisionales). Mujeres, todas las nacionalidades.

Sheet Edad_Extranjeros
A1: grupo de edad | B1: España | C1: Andalucía | D1: Aragón | E1: Asturias | F1: Baleares | G1: Canarias | H1: Cantabria | I1: Castilla y León | J1: Castilla-La Mancha | K1: Cataluña | L1: Comunitat Valenciana | M1: Extremadura | N1: Galicia | O1: Madrid | P1: Murcia | Q1: Navarra | R1: País Vasco | S1: La Rioja | T1: Ceuta | U1: Melilla | V1: Suma de las 19 CCAA | W1: Diferencia con el total nacional
A2: Todas las edades | B2: =SUM(C2:U2) -> 7437543 | C2: 986922 | D2: 223584 | E2: 84087 | F2: 279415 | G2: 349690 | H2: 53489 | I2: 234815 | J2: 286117 | K2: 1598400 | L2: 1173815 | M2: 53988 | N2: 203236 | O2: 1229486 | P2: 271380 | Q2: 95897 | R2: 244224 | S2: 51687 | T2: 6050 | U2: 11261 | V2: =SUM(C2:U2) -> 7437543 | W2: =V2-B2 -> 0
A3: 0-4 | B3: =SUM(C3:U3) -> 243182 | C3: 32429 | D3: 8446 | E3: 2492 | F3: 8321 | G3: 7542 | H3: 1315 | I3: 8140 | J3: 11051 | K3: 54673 | L3: 37605 | M3: 1963 | N3: 5581 | O3: 37506 | P3: 10841 | Q3: 3825 | R3: 8755 | S3: 2254 | T3: 129 | U3: 314 | V3: =SUM(C3:U3) -> 243182 | W3: =V3-B3 -> 0
A4: 5-9 | B4: =SUM(C4:U4) -> 299082 | C4: 39008 | D4: 10017 | E4: 3849 | F4: 10098 | G4: 11688 | H4: 2264 | I4: 11114 | J4: 14476 | K4: 59911 | L4: 51312 | M4: 2606 | N4: 8511 | O4: 45784 | P4: 11096 | Q4: 4506 | R4: 9807 | S4: 2608 | T4: 121 | U4: 306 | V4: =SUM(C4:U4) -> 299082 | W4: =V4-B4 -> 0
A5: 10-14 | B5: =SUM(C5:U5) -> 366179 | C5: 47005 | D5: 12160 | E5: 4445 | F5: 11967 | G5: 14900 | H5: 2855 | I5: 13516 | J5: 17601 | K5: 72538 | L5: 62507 | M5: 3013 | N5: 10539 | O5: 57596 | P5: 14691 | Q5: 5512 | R5: 11677 | S5: 3130 | T5: 111 | U5: 416 | V5: =SUM(C5:U5) -> 366179 | W5: =V5-B5 -> 0
A6: 15-19 | B6: =SUM(C6:U6) -> 390101 | C6: 48852 | D6: 13034 | E6: 4663 | F6: 12716 | G6: 18604 | H6: 3334 | I6: 14316 | J6: 17321 | K6: 77641 | L6: 62433 | M6: 3327 | N6: 11499 | O6: 64383 | P6: 14839 | Q6: 5912 | R6: 13528 | S6: 3103 | T6: 149 | U6: 447 | V6: =SUM(C6:U6) -> 390101 | W6: =V6-B6 -> 0
A7: 20-24 | B7: =SUM(C7:U7) -> 538736 | C7: 66965 | D7: 17370 | E7: 6282 | F7: 17014 | G7: 21953 | H7: 4543 | I7: 20093 | J7: 21319 | K7: 115445 | L7: 76562 | M7: 4272 | N7: 16527 | O7: 99455 | P7: 18317 | Q7: 7561 | R7: 20783 | S7: 3638 | T7: 159 | U7: 478 | V7: =SUM(C7:U7) -> 538736 | W7: =V7-B7 -> 0
A8: 25-29 | B8: =SUM(C8:U8) -> 733296 | C8: 88794 | D8: 21917 | E8: 8327 | F8: 25194 | G8: 26420 | H8: 5089 | I8: 24233 | J8: 27270 | K8: 171519 | L8: 99115 | M8: 5220 | N8: 21264 | O8: 142018 | P8: 23919 | Q8: 9162 | R8: 28413 | S8: 4518 | T8: 298 | U8: 606 | V8: =SUM(C8:U8) -> 733296 | W8: =V8-B8 -> 0
A9: 30-34 | B9: =SUM(C9:U9) -> 808099 | C9: 97081 | D9: 23576 | E9: 9333 | F9: 29741 | G9: 29516 | H9: 5472 | I9: 25379 | J9: 29387 | K9: 197424 | L9: 110345 | M9: 5603 | N9: 22709 | O9: 149375 | P9: 25840 | Q9: 10233 | R9: 30815 | S9: 4898 | T9: 524 | U9: 848 | V9: =SUM(C9:U9) -> 808099 | W9: =V9-B9 -> 0
A10: 35-39 | B10: =SUM(C10:U10) -> 799124 | C10: 98853 | D10: 23719 | E10: 9616 | F10: 30445 | G10: 31974 | H10: 5877 | I10: 25042 | J10: 31315 | K10: 191204 | L10: 114037 | M10: 5712 | N10: 22066 | O10: 135888 | P10: 26702 | Q10: 10482 | R10: 29070 | S10: 5382 | T10: 675 | U10: 1065 | V10: =SUM(C10:U10) -> 799124 | W10: =V10-B10 -> 0
A11: 40-44 | B11: =SUM(C11:U11) -> 747004 | C11: 97219 | D11: 23069 | E11: 8662 | F11: 29287 | G11: 31954 | H11: 5562 | I11: 23048 | J11: 30738 | K11: 169999 | L11: 109255 | M11: 5321 | N11: 20085 | O11: 122309 | P11: 26489 | Q11: 10179 | R11: 26097 | S11: 5484 | T11: 890 | U11: 1357 | V11: =SUM(C11:U11) -> 747004 | W11: =V11-B11 -> 0
A12: 45-49 | B12: =SUM(C12:U12) -> 669612 | C12: 88778 | D12: 22138 | E12: 7388 | F12: 27114 | G12: 30004 | H12: 4898 | I12: 21265 | J12: 27434 | K12: 146177 | L12: 100211 | M12: 4902 | N12: 17556 | O12: 108194 | P12: 25914 | Q12: 8800 | R12: 21568 | S12: 5048 | T12: 833 | U12: 1390 | V12: =SUM(C12:U12) -> 669612 | W12: =V12-B12 -> 0
A13: 50-54 | B13: =SUM(C13:U13) -> 527231 | C13: 70585 | D13: 17376 | E13: 5770 | F13: 21831 | G13: 27556 | H13: 3880 | I13: 16122 | J13: 20567 | K13: 110033 | L13: 82339 | M13: 3759 | N13: 13892 | O13: 85673 | P13: 20240 | Q13: 6744 | R13: 15172 | S13: 3950 | T13: 669 | U13: 1073 | V13: =SUM(C13:U13) -> 527231 | W13: =V13-B13 -> 0
... A21: 90+ | B21: =SUM(C21:U21) -> 12762 | C21: 2377 | D21: 152 | E21: 142 | F21: 684 | G21: 1151 | H21: 92 | I21: 235 | J21: 261 | K21: 1948 | L21: 3004 | M21: 95 | N21: 372 | O21: 1548 | P21: 337 | Q21: 84 | R21: 203 | S21: 38 | T21: 13 | U21: 26 | V21: =SUM(C21:U21) -> 12762 | W21: =V21-B21 -> 0
A22: Suma de los 19 grupos de edad | B22: =SUM(B3:B21) -> 7437543 | C22: =SUM(C3:C21) -> 986922 | D22: =SUM(D3:D21) -> 223584 | E22: =SUM(E3:E21) -> 84087 | F22: =SUM(F3:F21) -> 279415 | G22: =SUM(G3:G21) -> 349690 | H22: =SUM(H3:H21) -> 53489 | I22: =SUM(I3:I21) -> 234815 | ... U22: =SUM(U3:U21) -> 11261
A23: Diferencia con "Todas las edades" | B23: =B22-B2 -> 0 | C23: =C22-C2 -> 0 | D23: =D22-D2 -> 0 | E23: =E22-E2 -> 0 | F23: =F22-F2 -> 0 | G23: =G22-G2 -> 0 | H23: =H22-H2 -> 0 | I23: =I22-I2 -> 0 | ... U23: =U22-U2 -> 0
A25: Estadística Continua de Población (INE, tabla 59587), población residente a 1 de julio de 2026 (datos provisionales). Nacionalidad extranjera, ambos sexos. La columna España es la suma de las 19 CCAA (el INE da el total nacional de extranjeros: 7.437.543, que coincide).

Sheet Estructura_Edad
A1: territorio | B1: Población | C1: % 0–14 años | D1: % 15–64 años | E1: % 65 y más | F1: % 80 y más | G1: Índice de envejecimiento (65+ ÷ 0–14 × 100) | H1: Tasa de dependencia (0–14 + 65+) ÷ (15–64) × 100 | I1: Dependencia de mayores 65+ ÷ (15–64) × 100 | J1: % de 20 a 39 años | K1: 85+ como % de los 65+ | L1: % extranjeros | M1: % extranjeros entre 20 y 44 años | N1: Mujeres por 100 hombres (total) | O1: Mujeres por 100 hombres (65+) | P1: ranking % 65+ (1 = más envejecida) | Q1: ranking % extranjeros (1 = más)
A2: España | B2: =Edad_Total!B2 -> 49801559 | C2: =SUM(Edad_Total!B3:B5)/Edad_Total!B2*100 -> 12.389257 | D2: =SUM(Edad_Total!B6:B15)/Edad_Total!B2*100 -> 66.404263 | E2: =SUM(Edad_Total!B16:B21)/Edad_Total!B2*100 -> 21.206481 | F2: =SUM(Edad_Total!B19:B21)/Edad_Total!B2*100 -> 6.3486567 | G2: =SUM(Edad_Total!B16:B21)/SUM(Edad_Total!B3:B5)*100 -> 171.1683 | H2: =(SUM(Edad_Total!B3:B5)+SUM(Edad_Total!B16:B21))/SUM(Edad_Total!B6:B15)*100 -> 50.592742 | I2: =SUM(Edad_Total!B16:B21)/SUM(Edad_Total!B6:B15)*100 -> 31.935421 | J2: =SUM(Edad_Total!B7:B10)/Edad_Total!B2*100 -> 23.387131 | K2: =SUM(Edad_Total!B20:B21)/SUM(Edad_Total!B16:B21)*100 -> 15.451326 | L2: =Edad_Extranjeros!B2/Edad_Total!B2*100 -> 14.934358 | M2: =SUM(Edad_Extranjeros!B7:B11)/SUM(Edad_Total!B7:B11)*100 -> 24.068215 | N2: =Edad_Mujeres!B2/Edad_Hombres!B2*100 -> 103.58239 | O2: =SUM(Edad_Mujeres!B16:B21)/SUM(Edad_Hombres!B16:B21)*100 -> 128.29166
A3: Andalucía | B3: =Edad_Total!C2 -> 8778051 | C3: =SUM(Edad_Total!C3:C5)/Edad_Total!C2*100 -> 13.160154 | D3: =SUM(Edad_Total!C6:C15)/Edad_Total!C2*100 -> 67.101353 | E3: =SUM(Edad_Total!C16:C21)/Edad_Total!C2*100 -> 19.738493 | F3: =SUM(Edad_Total!C19:C21)/Edad_Total!C2*100 -> 5.3735049 | G3: =SUM(Edad_Total!C16:C21)/SUM(Edad_Total!C3:C5)*100 -> 149.9868 | H3: =(SUM(Edad_Total!C3:C5)+SUM(Edad_Total!C16:C21))/SUM(Edad_Total!C6:C15)*100 -> 49.028291 | I3: =SUM(Edad_Total!C16:C21)/SUM(Edad_Total!C6:C15)*100 -> 29.415939 | J3: =SUM(Edad_Total!C7:C10)/Edad_Total!C2*100 -> 23.40204 | K3: =SUM(Edad_Total!C20:C21)/SUM(Edad_Total!C16:C21)*100 -> 13.216768 | L3: =Edad_Extranjeros!C2/Edad_Total!C2*100 -> 11.243065 | M3: =SUM(Edad_Extranjeros!C7:C11)/SUM(Edad_Total!C7:C11)*100 -> 16.799649 | N3: =Edad_Mujeres!C2/Edad_Hombres!C2*100 -> 102.93519 | O3: =SUM(Edad_Mujeres!C16:C21)/SUM(Edad_Hombres!C16:C21)*100 -> 125.71339 | P3: =RANK(E3,E$3:E$21,0) -> 13 | Q3: =RANK(L3,L$3:L$21,0) -> 12
A4: Aragón | B4: =Edad_Total!D2 -> 1389298 | C4: =SUM(Edad_Total!D3:D5)/Edad_Total!D2*100 -> 12.265907 | D4: =SUM(Edad_Total!D6:D15)/Edad_Total!D2*100 -> 64.827488 | E4: =SUM(Edad_Total!D16:D21)/Edad_Total!D2*100 -> 22.906605 | F4: =SUM(Edad_Total!D19:D21)/Edad_Total!D2*100 -> 7.3162849 | G4: =SUM(Edad_Total!D16:D21)/SUM(Edad_Total!D3:D5)*100 -> 186.75019 | H4: =(SUM(Edad_Total!D3:D5)+SUM(Edad_Total!D16:D21))/SUM(Edad_Total!D6:D15)*100 -> 54.255552 | I4: =SUM(Edad_Total!D16:D21)/SUM(Edad_Total!D6:D15)*100 -> 35.334709 | J4: =SUM(Edad_Total!D7:D10)/Edad_Total!D2*100 -> 22.421899 | K4: =SUM(Edad_Total!D20:D21)/SUM(Edad_Total!D16:D21)*100 -> 17.105904 | L4: =Edad_Extranjeros!D2/Edad_Total!D2*100 -> 16.093308 | M4: =SUM(Edad_Extranjeros!D7:D11)/SUM(Edad_Total!D7:D11)*100 -> 27.207267 | N4: =Edad_Mujeres!D2/Edad_Hombres!D2*100 -> 100.76445 | O4: =SUM(Edad_Mujeres!D16:D21)/SUM(Edad_Hombres!D16:D21)*100 -> 126.08927 | P4: =RANK(E4,E$3:E$21,0) -> 8 | Q4: =RANK(L4,L$3:L$21,0) -> 6
A5: Asturias | B5: =Edad_Total!E2 -> 1026726 | C5: =SUM(Edad_Total!E3:E5)/Edad_Total!E2*100 -> 9.5020483 | D5: =SUM(Edad_Total!E6:E15)/Edad_Total!E2*100 -> 61.652379 | E5: =SUM(Edad_Total!E16:E21)/Edad_Total!E2*100 -> 28.845573 | F5: =SUM(Edad_Total!E19:E21)/Edad_Total!E2*100 -> 8.771571 | G5: =SUM(Edad_Total!E16:E21)/SUM(Edad_Total!E3:E5)*100 -> 303.57216 | H5: =(SUM(Edad_Total!E3:E5)+SUM(Edad_Total!E16:E21))/SUM(Edad_Total!E6:E15)*100 -> 62.199744 | I5: =SUM(Edad_Total!E16:E21)/SUM(Edad_Total!E6:E15)*100 -> 46.787446 | J5: =SUM(Edad_Total!E7:E10)/Edad_Total!E2*100 -> 18.191416 | K5: =SUM(Edad_Total!E20:E21)/SUM(Edad_Total!E16:E21)*100 -> 16.044097 | L5: =Edad_Extranjeros!E2/Edad_Total!E2*100 -> 8.1898189 | M5: =SUM(Edad_Extranjeros!E7:E11)/SUM(Edad_Total!E7:E11)*100 -> 16.72205 | N5: =Edad_Mujeres!E2/Edad_Hombres!E2*100 -> 109.17008 | O5: =SUM(Edad_Mujeres!E16:E21)/SUM(Edad_Hombres!E16:E21)*100 -> 134.74977 | P5: =RANK(E5,E$3:E$21,0) -> 1 | Q5: =RANK(L5,L$3:L$21,0) -> 16
A6: Baleares | B6: =Edad_Total!F2 -> 1266279 | C6: =SUM(Edad_Total!F3:F5)/Edad_Total!F2*100 -> 12.728238 | D6: =SUM(Edad_Total!F6:F15)/Edad_Total!F2*100 -> 69.957569 | E6: =SUM(Edad_Total!F16:F21)/Edad_Total!F2*100 -> 17.314194 | F6: =SUM(Edad_Total!F19:F21)/Edad_Total!F2*100 -> 4.7079672 | G6: =SUM(Edad_Total!F16:F21)/SUM(Edad_Total!F3:F5)*100 -> 136.02978 | H6: =(SUM(Edad_Total!F3:F5)+SUM(Edad_Total!F16:F21))/SUM(Edad_Total!F6:F15)*100 -> 42.94379 | I6: =SUM(Edad_Total!F16:F21)/SUM(Edad_Total!F6:F15)*100 -> 24.749565 | J6: =SUM(Edad_Total!F7:F10)/Edad_Total!F2*100 -> 26.580635 | K6: =SUM(Edad_Total!F20:F21)/SUM(Edad_Total!F16:F21)*100 -> 13.235361 | L6: =Edad_Extranjeros!F2/Edad_Total!F2*100 -> 22.065832 | M6: =SUM(Edad_Extranjeros!F7:F11)/SUM(Edad_Total!F7:F11)*100 -> 30.330622 | N6: =Edad_Mujeres!F2/Edad_Hombres!F2*100 -> 100.7408 | O6: =SUM(Edad_Mujeres!F16:F21)/SUM(Edad_Hombres!F16:F21)*100 -> 124.29947 | P6: =RANK(E6,E$3:E$21,0) -> 17 | Q6: =RANK(L6,L$3:L$21,0) -> 1
A7: Canarias | B7: =Edad_Total!G2 -> 2277705 | C7: =SUM(Edad_Total!G3:G5)/Edad_Total!G2*100 -> 10.677283 | D7: =SUM(Edad_Total!G6:G15)/Edad_Total!G2*100 -> 70.375092 | E7: =SUM(Edad_Total!G16:G21)/Edad_Total!G2*100 -> 18.947625 | F7: =SUM(Edad_Total!G19:G21)/Edad_Total!G2*100 -> 4.9010737 | G7: =SUM(Edad_Total!G16:G21)/SUM(Edad_Total!G3:G5)*100 -> 177.45737 | H7: =(SUM(Edad_Total!G3:G5)+SUM(Edad_Total!G16:G21))/SUM(Edad_Total!G6:G15)*100 -> 42.095728 | I7: =SUM(Edad_Total!G16:G21)/SUM(Edad_Total!G6:G15)*100 -> 26.923766 | J7: =SUM(Edad_Total!G7:G10)/Edad_Total!G2*100 -> 24.711058 | K7: =SUM(Edad_Total!G20:G21)/SUM(Edad_Total!G16:G21)*100 -> 12.296934 | L7: =Edad_Extranjeros!G2/Edad_Total!G2*100 -> 15.352734 | M7: =SUM(Edad_Extranjeros!G7:G11)/SUM(Edad_Total!G7:G11)*100 -> 19.475114 | N7: =Edad_Mujeres!G2/Edad_Hombres!G2*100 -> 102.77142 | O7: =SUM(Edad_Mujeres!G16:G21)/SUM(Edad_Hombres!G16:G21)*100 -> 121.93305 | P7: =RANK(E7,E$3:E$21,0) -> 15 | Q7: =RANK(L7,L$3:L$21,0) -> 8
A8: Cantabria | B8: =Edad_Total!H2 -> 599056 | C8: =SUM(Edad_Total!H3:H5)/Edad_Total!H2*100 -> 10.789809 | D8: =SUM(Edad_Total!H6:H15)/Edad_Total!H2*100 -> 63.989343 | E8: =SUM(Edad_Total!H16:H21)/Edad_Total!H2*100 -> 25.220847 | F8: =SUM(Edad_Total!H19:H21)/Edad_Total!H2*100 -> 7.319516 | G8: =SUM(Edad_Total!H16:H21)/SUM(Edad_Total!H3:H5)*100 -> 233.74693 | H8: =(SUM(Edad_Total!H3:H5)+SUM(Edad_Total!H16:H21))/SUM(Edad_Total!H6:H15)*100 -> 56.276022 | I8: =SUM(Edad_Total!H16:H21)/SUM(Edad_Total!H6:H15)*100 -> 39.414137 | J8: =SUM(Edad_Total!H7:H10)/Edad_Total!H2*100 -> 19.872433 | K8: =SUM(Edad_Total!H20:H21)/SUM(Edad_Total!H16:H21)*100 -> 15.499679 | L8: =Edad_Extranjeros!H2/Edad_Total!H2*100 -> 8.9288814 | M8: =SUM(Edad_Extranjeros!H7:H11)/SUM(Edad_Total!H7:H11)*100 -> 16.67913 | N8: =Edad_Mujeres!H2/Edad_Hombres!H2*100 -> 106.13389 | O8: =SUM(Edad_Mujeres!H16:H21)/SUM(Edad_Hombres!H16:H21)*100 -> 129.22881 | P8: =RANK(E8,E$3:E$21,0) -> 4 | Q8: =RANK(L8,L$3:L$21,0) -> 15
A9: Castilla y León | B9: =Edad_Total!I2 -> 2427156 | C9: =SUM(Edad_Total!I3:I5)/Edad_Total!I2*100 -> 10.572291 | D9: =SUM(Edad_Total!I6:I15)/Edad_Total!I2*100 -> 61.647459 | E9: =SUM(Edad_Total!I16:I21)/Edad_Total!I2*100 -> 27.78025 | F9: =SUM(Edad_Total!I19:I21)/Edad_Total!I2*100 -> 9.4153404 | G9: =SUM(Edad_Total!I16:I21)/SUM(Edad_Total!I3:I5)*100 -> 262.76471 | H9: =(SUM(Edad_Total!I3:I5)+SUM(Edad_Total!I16:I21))/SUM(Edad_Total!I6:I15)*100 -> 62.212687 | I9: =SUM(Edad_Total!I16:I21)/SUM(Edad_Total!I6:I15)*100 -> 45.06309 | J9: =SUM(Edad_Total!I7:I10)/Edad_Total!I2*100 -> 19.646203 | K9: =SUM(Edad_Total!I20:I21)/SUM(Edad_Total!I16:I21)*100 -> 19.077669 | L9: =Edad_Extranjeros!I2/Edad_Total!I2*100 -> 9.6744915 | M9: =SUM(Edad_Extranjeros!I7:I11)/SUM(Edad_Total!I7:I11)*100 -> 18.802105 | N9: =Edad_Mujeres!I2/Edad_Hombres!I2*100 -> 102.73402 | O9: =SUM(Edad_Mujeres!I16:I21)/SUM(Edad_Hombres!I16:I21)*100 -> 121.21501 | P9: =RANK(E9,E$3:E$21,0) -> 2 | Q9: =RANK(L9,L$3:L$21,0) -> 14
A10: Castilla-La Mancha | B10: =Edad_Total!J2 -> 2169241 | C10: =SUM(Edad_Total!J3:J5)/Edad_Total!J2*100 -> 13.194707 | D10: =SUM(Edad_Total!J6:J15)/Edad_Total!J2*100 -> 66.23017 | E10: =SUM(Edad_Total!J16:J21)/Edad_Total!J2*100 -> 20.575123 | F10: =SUM(Edad_Total!J19:J21)/Edad_Total!J2*100 -> 6.2948746 | G10: =SUM(Edad_Total!J16:J21)/SUM(Edad_Total!J3:J5)*100 -> 155.93467 | H10: =(SUM(Edad_Total!J3:J5)+SUM(Edad_Total!J16:J21))/SUM(Edad_Total!J6:J15)*100 -> 50.98859 | I10: =SUM(Edad_Total!J16:J21)/SUM(Edad_Total!J6:J15)*100 -> 31.066088 | J10: =SUM(Edad_Total!J7:J10)/Edad_Total!J2*100 -> 22.973104 | K10: =SUM(Edad_Total!J20:J21)/SUM(Edad_Total!J16:J21)*100 -> 16.890869 | L10: =Edad_Extranjeros!J2/Edad_Total!J2*100 -> 13.189729 | M10: =SUM(Edad_Extranjeros!J7:J11)/SUM(Edad_Total!J7:J11)*100 -> 21.557649 | N10: =Edad_Mujeres!J2/Edad_Hombres!J2*100 -> 98.697026 | O10: =SUM(Edad_Mujeres!J16:J21)/SUM(Edad_Hombres!J16:J21)*100 -> 119.97348 | P10: =RANK(E10,E$3:E$21,0) -> 11 | Q10: =RANK(L10,L$3:L$21,0) -> 10
A11: Cataluña | B11: =Edad_Total!K2 -> 8233788 | C11: =SUM(Edad_Total!K3:K5)/Edad_Total!K2*100 -> 12.680397 | D11: =SUM(Edad_Total!K6:K15)/Edad_Total!K2*100 -> 67.233793 | E11: =SUM(Edad_Total!K16:K21)/Edad_Total!K2*100 -> 20.08581 | F11: =SUM(Edad_Total!K19:K21)/Edad_Total!K2*100 -> 6.0884371 | G11: =SUM(Edad_Total!K16:K21)/SUM(Edad_Total!K3:K5)*100 -> 158.40048 | H11: =(SUM(Edad_Total!K3:K5)+SUM(Edad_Total!K16:K21))/SUM(Edad_Total!K6:K15)*100 -> 48.734729 | I11: =SUM(Edad_Total!K16:K21)/SUM(Edad_Total!K6:K15)*100 -> 29.874575 | J11: =SUM(Edad_Total!K7:K10)/Edad_Total!K2*100 -> 24.937465 | K11: =SUM(Edad_Total!K20:K21)/SUM(Edad_Total!K16:K21)*100 -> 15.57712 | L11: =Edad_Extranjeros!K2/Edad_Total!K2*100 -> 19.412693 | M11: =SUM(Edad_Extranjeros!K7:K11)/SUM(Edad_Total!K7:K11)*100 -> 32.259235 | N11: =Edad_Mujeres!K2/Edad_Hombres!K2*100 -> 102.03513 | O11: =SUM(Edad_Mujeres!K16:K21)/SUM(Edad_Hombres!K16:K21)*100 -> 131.31265 | P11: =RANK(E11,E$3:E$21,0) -> 12 | Q11: =RANK(L11,L$3:L$21,0) -> 3
A12: Comunitat Valenciana | B12: =Edad_Total!L2 -> 5574948 | C12: =SUM(Edad_Total!L3:L5)/Edad_Total!L2*100 -> 12.669966 | D12: =SUM(Edad_Total!L6:L15)/Edad_Total!L2*100 -> 66.623994 | E12: =SUM(Edad_Total!L16:L21)/Edad_Total!L2*100 -> 20.706041 | F12: =SUM(Edad_Total!L19:L21)/Edad_Total!L2*100 -> 5.8740458 | G12: =SUM(Edad_Total!L16:L21)/SUM(Edad_Total!L3:L5)*100 -> 163.42618 | H12: =(SUM(Edad_Total!L3:L5)+SUM(Edad_Total!L16:L21))/SUM(Edad_Total!L6:L15)*100 -> 50.096076 | I12: =SUM(Edad_Total!L16:L21)/SUM(Edad_Total!L6:L15)*100 -> 31.078955 | J12: =SUM(Edad_Total!L7:L10)/Edad_Total!L2*100 -> 23.504596 | K12: =SUM(Edad_Total!L20:L21)/SUM(Edad_Total!L16:L21)*100 -> 14.121355 | L12: =Edad_Extranjeros!L2/Edad_Total!L2*100 -> 21.055174 | M12: =SUM(Edad_Extranjeros!L7:L11)/SUM(Edad_Total!L7:L11)*100 -> 30.030537 | N12: =Edad_Mujeres!L2/Edad_Hombres!L2*100 -> 102.63946 | O12: =SUM(Edad_Mujeres!L16:L21)/SUM(Edad_Hombres!L16:L21)*100 -> 126.40859 | P12: =RANK(E12,E$3:E$21,0) -> 10 | Q12: =RANK(L12,L$3:L$21,0) -> 2
A13: Extremadura | B13: =Edad_Total!M2 -> 1055849 | C13: =SUM(Edad_Total!M3:M5)/Edad_Total!M2*100 -> 11.864859 | D13: =SUM(Edad_Total!M6:M15)/Edad_Total!M2*100 -> 64.337325 | E13: =SUM(Edad_Total!M16:M21)/Edad_Total!M2*100 -> 23.797816 | F13: =SUM(Edad_Total!M19:M21)/Edad_Total!M2*100 -> 7.3169554 | G13: =SUM(Edad_Total!M16:M21)/SUM(Edad_Total!M3:M5)*100 -> 200.57394 | H13: =(SUM(Edad_Total!M3:M5)+SUM(Edad_Total!M16:M21))/SUM(Edad_Total!M6:M15)*100 -> 55.430771 | I13: =SUM(Edad_Total!M16:M21)/SUM(Edad_Total!M6:M15)*100 -> 36.989129 | J13: =SUM(Edad_Total!M7:M10)/Edad_Total!M2*100 -> 21.515103 | K13: =SUM(Edad_Total!M20:M21)/SUM(Edad_Total!M16:M21)*100 -> 16.506612 | L13: =Edad_Extranjeros!M2/Edad_Total!M2*100 -> 5.1132312 | M13: =SUM(Edad_Extranjeros!M7:M11)/SUM(Edad_Total!M7:M11)*100 -> 8.8114878 | N13: =Edad_Mujeres!M2/Edad_Hombres!M2*100 -> 102.30984 | O13: =SUM(Edad_Mujeres!M16:M21)/SUM(Edad_Hombres!M16:M21)*100 -> 120.61654 | P13: =RANK(E13,E$3:E$21,0) -> 6 | Q13: =RANK(L13,L$3:L$21,0) -> 19
A14: Galicia | B14: =Edad_Total!N2 -> 2734494 | C14: =SUM(Edad_Total!N3:N5)/Edad_Total!N2*100 -> 10.299127 | D14: =SUM(Edad_Total!N6:N15)/Edad_Total!N2*100 -> 62.403428 | E14: =SUM(Edad_Total!N16:N21)/Edad_Total!N2*100 -> 27.297445 | F14: =SUM(Edad_Total!N19:N21)/Edad_Total!N2*100 -> 9.2789745 | G14: =SUM(Edad_Total!N16:N21)/SUM(Edad_Total!N3:N5)*100 -> 265.04621 | H14: =(SUM(Edad_Total!N3:N5)+SUM(Edad_Total!N16:N21))/SUM(Edad_Total!N6:N15)*100 -> 60.247606 | I14: =SUM(Edad_Total!N16:N21)/SUM(Edad_Total!N6:N15)*100 -> 43.743502 | J14: =SUM(Edad_Total!N7:N10)/Edad_Total!N2*100 -> 19.397227 | K14: =SUM(Edad_Total!N20:N21)/SUM(Edad_Total!N16:N21)*100 -> 18.212144 | L14: =Edad_Extranjeros!N2/Edad_Total!N2*100 -> 7.4323074 | M14: =SUM(Edad_Extranjeros!N7:N11)/SUM(Edad_Total!N7:N11)*100 -> 14.458254 | N14: =Edad_Mujeres!N2/Edad_Hombres!N2*100 -> 107.36144 | O14: =SUM(Edad_Mujeres!N16:N21)/SUM(Edad_Hombres!N16:N21)*100 -> 131.04235 | P14: =RANK(E14,E$3:E$21,0) -> 3 | Q14: =RANK(L14,L$3:L$21,0) -> 17
A15: Madrid | B15: =Edad_Total!O2 -> 7201554 | C15: =SUM(Edad_Total!O3:O5)/Edad_Total!O2*100 -> 12.705036 | D15: =SUM(Edad_Total!O6:O15)/Edad_Total!O2*100 -> 67.921687 | E15: =SUM(Edad_Total!O16:O21)/Edad_Total!O2*100 -> 19.373277 | F15: =SUM(Edad_Total!O19:O21)/Edad_Total!O2*100 -> 5.9867912 | G15: =SUM(Edad_Total!O16:O21)/SUM(Edad_Total!O3:O5)*100 -> 152.48503 | H15: =(SUM(Edad_Total!O3:O5)+SUM(Edad_Total!O16:O21))/SUM(Edad_Total!O6:O15)*100 -> 47.22838 | I15: =SUM(Edad_Total!O16:O21)/SUM(Edad_Total!O6:O15)*100 -> 28.522962 | J15: =SUM(Edad_Total!O7:O10)/Edad_Total!O2*100 -> 25.417431 | K15: =SUM(Edad_Total!O20:O21)/SUM(Edad_Total!O16:O21)*100 -> 16.095377 | L15: =Edad_Extranjeros!O2/Edad_Total!O2*100 -> 17.07251 | M15: =SUM(Edad_Extranjeros!O7:O11)/SUM(Edad_Total!O7:O11)*100 -> 27.799789 | N15: =Edad_Mujeres!O2/Edad_Hombres!O2*100 -> 108.70343 | O15: =SUM(Edad_Mujeres!O16:O21)/SUM(Edad_Hombres!O16:O21)*100 -> 138.87318 | P15: =RANK(E15,E$3:E$21,0) -> 14 | Q15: =RANK(L15,L$3:L$21,0) -> 4
A16: Murcia | B16: =Edad_Total!P2 -> 1616189 | C16: =SUM(Edad_Total!P3:P5)/Edad_Total!P2*100 -> 14.759846 | D16: =SUM(Edad_Total!P6:P15)/Edad_Total!P2*100 -> 67.672222 | E16: =SUM(Edad_Total!P16:P21)/Edad_Total!P2*100 -> 17.567933 | F16: =SUM(Edad_Total!P19:P21)/Edad_Total!P2*100 -> 4.8363774 | G16: =SUM(Edad_Total!P16:P21)/SUM(Edad_Total!P3:P5)*100 -> 119.02518 | H16: =(SUM(Edad_Total!P3:P5)+SUM(Edad_Total!P16:P21))/SUM(Edad_Total!P6:P15)*100 -> 47.771121 | I16: =SUM(Edad_Total!P16:P21)/SUM(Edad_Total!P6:P15)*100 -> 25.960331 | J16: =SUM(Edad_Total!P7:P10)/Edad_Total!P2*100 -> 24.461805 | K16: =SUM(Edad_Total!P20:P21)/SUM(Edad_Total!P16:P21)*100 -> 13.971 | L16: =Edad_Extranjeros!P2/Edad_Total!P2*100 -> 16.791353 | M16: =SUM(Edad_Extranjeros!P7:P11)/SUM(Edad_Total!P7:P11)*100 -> 23.837577 | N16: =Edad_Mujeres!P2/Edad_Hombres!P2*100 -> 99.693699 | O16: =SUM(Edad_Mujeres!P16:P21)/SUM(Edad_Hombres!P16:P21)*100 -> 124.12715 | P16: =RANK(E16,E$3:E$21,0) -> 16 | Q16: =RANK(L16,L$3:L$21,0) -> 5
A17: Navarra | B17: =Edad_Total!Q2 -> 692026 | C17: =SUM(Edad_Total!Q3:Q5)/Edad_Total!Q2*100 -> 13.31135 | D17: =SUM(Edad_Total!Q6:Q15)/Edad_Total!Q2*100 -> 65.205643 | E17: =SUM(Edad_Total!Q16:Q21)/Edad_Total!Q2*100 -> 21.483008 | F17: =SUM(Edad_Total!Q19:Q21)/Edad_Total!Q2*100 -> 6.6579868 | G17: =SUM(Edad_Total!Q16:Q21)/SUM(Edad_Total!Q3:Q5)*100 -> 161.38865 | H17: =(SUM(Edad_Total!Q3:Q5)+SUM(Edad_Total!Q16:Q21))/SUM(Edad_Total!Q6:Q15)*100 -> 53.360961 | I17: =SUM(Edad_Total!Q16:Q21)/SUM(Edad_Total!Q6:Q15)*100 -> 32.946547 | J17: =SUM(Edad_Total!Q7:Q10)/Edad_Total!Q2*100 -> 22.799577 | K17: =SUM(Edad_Total!Q20:Q21)/SUM(Edad_Total!Q16:Q21)*100 -> 15.95905 | L17: =Edad_Extranjeros!Q2/Edad_Total!Q2*100 -> 13.857427 | M17: =SUM(Edad_Extranjeros!Q7:Q11)/SUM(Edad_Total!Q7:Q11)*100 -> 23.507487 | N17: =Edad_Mujeres!Q2/Edad_Hombres!Q2*100 -> 101.50013 | O17: =SUM(Edad_Mujeres!Q16:Q21)/SUM(Edad_Hombres!Q16:Q21)*100 -> 123.20512 | P17: =RANK(E17,E$3:E$21,0) -> 9 | Q17: =RANK(L17,L$3:L$21,0) -> 9
A18: País Vasco | B18: =Edad_Total!R2 -> 2257392 | C18: =SUM(Edad_Total!R3:R5)/Edad_Total!R2*100 -> 11.577608 | D18: =SUM(Edad_Total!R6:R15)/Edad_Total!R2*100 -> 63.720524 | E18: =SUM(Edad_Total!R16:R21)/Edad_Total!R2*100 -> 24.701868 | F18: =SUM(Edad_Total!R19:R21)/Edad_Total!R2*100 -> 7.707124 | G18: =SUM(Edad_Total!R16:R21)/SUM(Edad_Total!R3:R5)*100 -> 213.35899 | H18: =(SUM(Edad_Total!R3:R5)+SUM(Edad_Total!R16:R21))/SUM(Edad_Total!R6:R15)*100 -> 56.935308 | I18: =SUM(Edad_Total!R16:R21)/SUM(Edad_Total!R6:R15)*100 -> 38.765953 | J18: =SUM(Edad_Total!R7:R10)/Edad_Total!R2*100 -> 21.212488 | K18: =SUM(Edad_Total!R20:R21)/SUM(Edad_Total!R16:R21)*100 -> 16.188681 | L18: =Edad_Extranjeros!R2/Edad_Total!R2*100 -> 10.818856 | M18: =SUM(Edad_Extranjeros!R7:R11)/SUM(Edad_Total!R7:R11)*100 -> 21.786177 | N18: =Edad_Mujeres!R2/Edad_Hombres!R2*100 -> 105.03851 | O18: =SUM(Edad_Mujeres!R16:R21)/SUM(Edad_Hombres!R16:R21)*100 -> 131.1897 | P18: =RANK(E18,E$3:E$21,0) -> 5 | Q18: =RANK(L18,L$3:L$21,0) -> 13
A19: La Rioja | B19: =Edad_Total!S2 -> 330756 | C19: =SUM(Edad_Total!S3:S5)/Edad_Total!S2*100 -> 12.496523 | D19: =SUM(Edad_Total!S6:S15)/Edad_Total!S2*100 -> 64.451741 | E19: =SUM(Edad_Total!S16:S21)/Edad_Total!S2*100 -> 23.051736 | F19: =SUM(Edad_Total!S19:S21)/Edad_Total!S2*100 -> 7.2083348 | G19: =SUM(Edad_Total!S16:S21)/SUM(Edad_Total!S3:S5)*100 -> 184.4652 | H19: =(SUM(Edad_Total!S3:S5)+SUM(Edad_Total!S16:S21))/SUM(Edad_Total!S6:S15)*100 -> 55.154847 | I19: =SUM(Edad_Total!S16:S21)/SUM(Edad_Total!S6:S15)*100 -> 35.765886 | J19: =SUM(Edad_Total!S7:S10)/Edad_Total!S2*100 -> 21.478673 | K19: =SUM(Edad_Total!S20:S21)/SUM(Edad_Total!S16:S21)*100 -> 16.528297 | L19: =Edad_Extranjeros!S2/Edad_Total!S2*100 -> 15.626927 | M19: =SUM(Edad_Extranjeros!S7:S11)/SUM(Edad_Total!S7:S11)*100 -> 25.722366 | N19: =Edad_Mujeres!S2/Edad_Hombres!S2*100 -> 102.52145 | O19: =SUM(Edad_Mujeres!S16:S21)/SUM(Edad_Hombres!S16:S21)*100 -> 122.17204 | P19: =RANK(E19,E$3:E$21,0) -> 7 | Q19: =RANK(L19,L$3:L$21,0) -> 7
A20: Ceuta | B20: =Edad_Total!T2 -> 84435 | C20: =SUM(Edad_Total!T3:T5)/Edad_Total!T2*100 -> 15.788476 | D20: =SUM(Edad_Total!T6:T15)/Edad_Total!T2*100 -> 69.750696 | E20: =SUM(Edad_Total!T16:T21)/Edad_Total!T2*100 -> 14.460828 | F20: =SUM(Edad_Total!T19:T21)/Edad_Total!T2*100 -> 3.2012791 | G20: =SUM(Edad_Total!T16:T21)/SUM(Edad_Total!T3:T5)*100 -> 91.591028 | H20: =(SUM(Edad_Total!T3:T5)+SUM(Edad_Total!T16:T21))/SUM(Edad_Total!T6:T15)*100 -> 43.367745 | I20: =SUM(Edad_Total!T16:T21)/SUM(Edad_Total!T6:T15)*100 -> 20.732163 | J20: =SUM(Edad_Total!T7:T10)/Edad_Total!T2*100 -> 26.939066 | K20: =SUM(Edad_Total!T20:T21)/SUM(Edad_Total!T16:T21)*100 -> 10.565111 | L20: =Edad_Extranjeros!T2/Edad_Total!T2*100 -> 7.1652751 | M20: =SUM(Edad_Extranjeros!T7:T11)/SUM(Edad_Total!T7:T11)*100 -> 8.8605833 | N20: =Edad_Mujeres!T2/Edad_Hombres!T2*100 -> 98.427806 | O20: =SUM(Edad_Mujeres!T16:T21)/SUM(Edad_Hombres!T16:T21)*100 -> 119.05274 | P20: =RANK(E20,E$3:E$21,0) -> 18 | Q20: =RANK(L20,L$3:L$21,0) -> 18
A21: Melilla | B21: =Edad_Total!U2 -> 86616 | C21: =SUM(Edad_Total!U3:U5)/Edad_Total!U2*100 -> 18.543918 | D21: =SUM(Edad_Total!U6:U15)/Edad_Total!U2*100 -> 67.763462 | E21: =SUM(Edad_Total!U16:U21)/Edad_Total!U2*100 -> 13.69262 | F21: =SUM(Edad_Total!U19:U21)/Edad_Total!U2*100 -> 2.8678304 | G21: =SUM(Edad_Total!U16:U21)/SUM(Edad_Total!U3:U5)*100 -> 73.838874 | H21: =(SUM(Edad_Total!U3:U5)+SUM(Edad_Total!U16:U21))/SUM(Edad_Total!U6:U15)*100 -> 47.572154 | I21: =SUM(Edad_Total!U16:U21)/SUM(Edad_Total!U6:U15)*100 -> 20.206495 | J21: =SUM(Edad_Total!U7:U10)/Edad_Total!U2*100 -> 27.133555 | K21: =SUM(Edad_Total!U20:U21)/SUM(Edad_Total!U16:U21)*100 -> 10.033727 | L21: =Edad_Extranjeros!U2/Edad_Total!U2*100 -> 13.001062 | M21: =SUM(Edad_Extranjeros!U7:U11)/SUM(Edad_Total!U7:U11)*100 -> 14.77535 | N21: =Edad_Mujeres!U2/Edad_Hombres!U2*100 -> 100.78817 | O21: =SUM(Edad_Mujeres!U16:U21)/SUM(Edad_Hombres!U16:U21)*100 -> 113.57825 | P21: =RANK(E21,E$3:E$21,0) -> 19 | Q21: =RANK(L21,L$3:L$21,0) -> 11
A23: Cálculos propios con la población a 1-jul-2026 por grupos quinquenales (hojas Edad_*). Con grupos de 5 años no se puede separar a los menores de 16: el índice de envejecimiento aquí usa 0–14 años (el índice oficial del INE usa menores de 16 y está en Indicadores_Demograficos), por lo que no coincide exactamente. La tasa de dependencia usa 15–64 años como población en edad de trabajar.

Sheet Piramide_Mad_vs_Esp
A1: grupo de edad | B1: España: hombres (% de la población) | C1: España: mujeres (% de la población) | D1: Madrid: hombres (% de la población) | E1: Madrid: mujeres (% de la población) | F1: España: total (%) | G1: Madrid: total (%) | H1: Madrid − España (puntos) | I1: Madrid como % de España (personas) | J1: % extranjeros España | K1: % extranjeros Madrid | L1: Mujeres por 100 hombres España | M1: Mujeres por 100 hombres Madrid
A2: 0-4 | B2: =Edad_Hombres!B3/Edad_Total!B$2*100 -> 1.732265 | C2: =Edad_Mujeres!B3/Edad_Total!B$2*100 -> 1.6374487 | D2: =Edad_Hombres!O3/Edad_Total!O$2*100 -> 1.8406722 | E2: =Edad_Mujeres!O3/Edad_Total!O$2*100 -> 1.7359309 | F2: =B2+C2 -> 3.3697138 | G2: =D2+E2 -> 3.576603 | H2: =G2-F2 -> 0.20688926 | I2: =Edad_Total!O3/Edad_Total!B3*100 -> 15.348326 | J2: =Edad_Extranjeros!B3/Edad_Total!B3*100 -> 14.490904 | K2: =Edad_Extranjeros!O3/Edad_Total!O3*100 -> 14.561422 | L2: =Edad_Mujeres!B3/Edad_Hombres!B3*100 -> 94.526455 | M2: =Edad_Mujeres!O3/Edad_Hombres!O3*100 -> 94.309618
